ERROR - 2020-10-28 16:13:32,813 - D:\csv\Se_Project\Testcases\loginPageTest\test_publciLoginPage.py - test_publciLoginPage.py[:35] - -------------------------------------------------
ERROR - 2020-10-28 16:13:34,092 - D:\csv\Se_Project\Testcases\loginPageTest\test_publciLoginPage.py - test_publciLoginPage.py[:35] - -------------------------------------------------
ERROR - 2020-10-28 16:13:35,175 - D:\csv\Se_Project\Testcases\loginPageTest\test_publciLoginPage.py - test_publciLoginPage.py[:35] - -------------------------------------------------
ERROR - 2020-10-28 16:13:36,200 - D:\csv\Se_Project\Testcases\loginPageTest\test_publciLoginPage.py - test_publciLoginPage.py[:35] - -------------------------------------------------
ERROR - 2020-10-28 16:13:36,998 - D:\csv\Se_Project\Testcases\loginPageTest\test_publciLoginPage.py - test_publciLoginPage.py[:35] - -------------------------------------------------
ERROR - 2020-10-28 16:14:52,391 - D:\csv\Se_Project\Testcases\loginPageTest\test_publciLoginPage.py - test_publciLoginPage.py[:35] - -------------------------------------------------
ERROR - 2020-10-28 16:14:53,650 - D:\csv\Se_Project\Testcases\loginPageTest\test_publciLoginPage.py - test_publciLoginPage.py[:35] - -------------------------------------------------
ERROR - 2020-10-28 16:14:54,760 - D:\csv\Se_Project\Testcases\loginPageTest\test_publciLoginPage.py - test_publciLoginPage.py[:35] - -------------------------------------------------
ERROR - 2020-10-28 16:14:55,812 - D:\csv\Se_Project\Testcases\loginPageTest\test_publciLoginPage.py - test_publciLoginPage.py[:35] - -------------------------------------------------
ERROR - 2020-10-28 16:14:57,139 - D:\csv\Se_Project\Testcases\loginPageTest\test_publciLoginPage.py - test_publciLoginPage.py[:35] - -------------------------------------------------
ERROR - 2020-10-28 16:19:45,130 - D:\csv\Se_Project\Testcases\loginPageTest\test_publciLoginPage.py - test_publciLoginPage.py[:36] - -------------------------------------------------
ERROR - 2020-10-28 16:19:46,344 - D:\csv\Se_Project\Testcases\loginPageTest\test_publciLoginPage.py - test_publciLoginPage.py[:36] - -------------------------------------------------
ERROR - 2020-10-28 16:19:47,438 - D:\csv\Se_Project\Testcases\loginPageTest\test_publciLoginPage.py - test_publciLoginPage.py[:36] - -------------------------------------------------
ERROR - 2020-10-28 16:19:48,432 - D:\csv\Se_Project\Testcases\loginPageTest\test_publciLoginPage.py - test_publciLoginPage.py[:36] - -------------------------------------------------
ERROR - 2020-10-28 16:19:49,278 - D:\csv\Se_Project\Testcases\loginPageTest\test_publciLoginPage.py - test_publciLoginPage.py[:36] - -------------------------------------------------
ERROR - 2020-10-28 18:18:03,870 - D:\csv\Se_Project\Testcases\loginPageTest\test_publciLoginPage.py - test_publciLoginPage.py[:36] - -------------------------------------------------
ERROR - 2020-10-28 18:18:05,092 - D:\csv\Se_Project\Testcases\loginPageTest\test_publciLoginPage.py - test_publciLoginPage.py[:36] - -------------------------------------------------
ERROR - 2020-10-28 18:18:06,180 - D:\csv\Se_Project\Testcases\loginPageTest\test_publciLoginPage.py - test_publciLoginPage.py[:36] - -------------------------------------------------
ERROR - 2020-10-28 18:18:07,170 - D:\csv\Se_Project\Testcases\loginPageTest\test_publciLoginPage.py - test_publciLoginPage.py[:36] - -------------------------------------------------
ERROR - 2020-10-28 18:18:09,319 - D:\csv\Se_Project\Testcases\loginPageTest\test_publciLoginPage.py - test_publciLoginPage.py[:36] - -------------------------------------------------
ERROR - 2020-10-28 18:19:00,439 - D:\csv\Se_Project\Testcases\loginPageTest\test_publciLoginPage.py - test_publciLoginPage.py[:36] - -------------------------------------------------
ERROR - 2020-10-28 18:19:01,245 - D:\csv\Se_Project\Testcases\loginPageTest\test_publciLoginPage.py - test_publciLoginPage.py[:36] - -------------------------------------------------
ERROR - 2020-10-28 18:19:02,404 - D:\csv\Se_Project\Testcases\loginPageTest\test_publciLoginPage.py - test_publciLoginPage.py[:36] - -------------------------------------------------
ERROR - 2020-10-28 18:19:03,411 - D:\csv\Se_Project\Testcases\loginPageTest\test_publciLoginPage.py - test_publciLoginPage.py[:36] - -------------------------------------------------
ERROR - 2020-10-28 18:19:04,273 - D:\csv\Se_Project\Testcases\loginPageTest\test_publciLoginPage.py - test_publciLoginPage.py[:36] - -------------------------------------------------
ERROR - 2020-10-28 23:16:24,377 - D:\Pycharm\AutoProject\SeleniumAutoProject\Testcases\loginPageTest\test_publciLoginPage.py - test_publciLoginPage.py[:36] - -------------------------------------------------
ERROR - 2020-10-28 23:16:25,479 - D:\Pycharm\AutoProject\SeleniumAutoProject\Testcases\loginPageTest\test_publciLoginPage.py - test_publciLoginPage.py[:36] - -------------------------------------------------
ERROR - 2020-10-28 23:16:26,329 - D:\Pycharm\AutoProject\SeleniumAutoProject\Testcases\loginPageTest\test_publciLoginPage.py - test_publciLoginPage.py[:36] - -------------------------------------------------
ERROR - 2020-10-28 23:16:28,802 - D:\Pycharm\AutoProject\SeleniumAutoProject\Testcases\loginPageTest\test_publciLoginPage.py - test_publciLoginPage.py[:36] - -------------------------------------------------
ERROR - 2020-10-28 23:16:30,555 - D:\Pycharm\AutoProject\SeleniumAutoProject\Testcases\loginPageTest\test_publciLoginPage.py - test_publciLoginPage.py[:36] - -------------------------------------------------
ERROR - 2020-10-28 23:24:30,104 - D:\Pycharm\AutoProject\SeleniumAutoProject\Testcases\loginPageTest\test_publciLoginPage.py - test_publciLoginPage.py[:36] - -------------------------------------------------
ERROR - 2020-10-28 23:24:30,825 - D:\Pycharm\AutoProject\SeleniumAutoProject\Testcases\loginPageTest\test_publciLoginPage.py - test_publciLoginPage.py[:36] - -------------------------------------------------
ERROR - 2020-10-28 23:24:31,911 - D:\Pycharm\AutoProject\SeleniumAutoProject\Testcases\loginPageTest\test_publciLoginPage.py - test_publciLoginPage.py[:36] - -------------------------------------------------
ERROR - 2020-10-28 23:24:32,966 - D:\Pycharm\AutoProject\SeleniumAutoProject\Testcases\loginPageTest\test_publciLoginPage.py - test_publciLoginPage.py[:36] - -------------------------------------------------
ERROR - 2020-10-28 23:24:33,885 - D:\Pycharm\AutoProject\SeleniumAutoProject\Testcases\loginPageTest\test_publciLoginPage.py - test_publciLoginPage.py[:36] - -------------------------------------------------
ERROR - 2020-10-28 23:25:13,115 - D:\Pycharm\AutoProject\SeleniumAutoProject\Testcases\loginPageTest\test_publciLoginPage.py - test_publciLoginPage.py[:36] - -------------------------------------------------
ERROR - 2020-10-28 23:25:15,486 - D:\Pycharm\AutoProject\SeleniumAutoProject\Testcases\loginPageTest\test_publciLoginPage.py - test_publciLoginPage.py[:36] - -------------------------------------------------
ERROR - 2020-10-28 23:25:16,676 - D:\Pycharm\AutoProject\SeleniumAutoProject\Testcases\loginPageTest\test_publciLoginPage.py - test_publciLoginPage.py[:36] - -------------------------------------------------
ERROR - 2020-10-28 23:25:17,917 - D:\Pycharm\AutoProject\SeleniumAutoProject\Testcases\loginPageTest\test_publciLoginPage.py - test_publciLoginPage.py[:36] - -------------------------------------------------
ERROR - 2020-10-28 23:25:20,064 - D:\Pycharm\AutoProject\SeleniumAutoProject\Testcases\loginPageTest\test_publciLoginPage.py - test_publciLoginPage.py[:36] - -------------------------------------------------
ERROR - 2020-10-28 23:26:45,347 - D:\Pycharm\AutoProject\SeleniumAutoProject\Testcases\loginPageTest\test_publciLoginPage.py - test_publciLoginPage.py[:36] - -------------------------------------------------
ERROR - 2020-10-28 23:26:47,711 - D:\Pycharm\AutoProject\SeleniumAutoProject\Testcases\loginPageTest\test_publciLoginPage.py - test_publciLoginPage.py[:36] - -------------------------------------------------
ERROR - 2020-10-28 23:26:48,938 - D:\Pycharm\AutoProject\SeleniumAutoProject\Testcases\loginPageTest\test_publciLoginPage.py - test_publciLoginPage.py[:36] - -------------------------------------------------
ERROR - 2020-10-28 23:26:50,045 - D:\Pycharm\AutoProject\SeleniumAutoProject\Testcases\loginPageTest\test_publciLoginPage.py - test_publciLoginPage.py[:36] - -------------------------------------------------
ERROR - 2020-10-28 23:26:52,221 - D:\Pycharm\AutoProject\SeleniumAutoProject\Testcases\loginPageTest\test_publciLoginPage.py - test_publciLoginPage.py[:36] - -------------------------------------------------
ERROR - 2020-10-28 23:27:47,853 - D:\Pycharm\AutoProject\SeleniumAutoProject\Testcases\loginPageTest\test_publciLoginPage.py - test_publciLoginPage.py[:36] - -------------------------------------------------
ERROR - 2020-10-28 23:27:50,190 - D:\Pycharm\AutoProject\SeleniumAutoProject\Testcases\loginPageTest\test_publciLoginPage.py - test_publciLoginPage.py[:36] - -------------------------------------------------
ERROR - 2020-10-28 23:27:51,238 - D:\Pycharm\AutoProject\SeleniumAutoProject\Testcases\loginPageTest\test_publciLoginPage.py - test_publciLoginPage.py[:36] - -------------------------------------------------
ERROR - 2020-10-28 23:27:52,396 - D:\Pycharm\AutoProject\SeleniumAutoProject\Testcases\loginPageTest\test_publciLoginPage.py - test_publciLoginPage.py[:36] - -------------------------------------------------
ERROR - 2020-10-28 23:27:54,548 - D:\Pycharm\AutoProject\SeleniumAutoProject\Testcases\loginPageTest\test_publciLoginPage.py - test_publciLoginPage.py[:36] - -------------------------------------------------
ERROR - 2020-10-28 23:29:09,456 - D:\Pycharm\AutoProject\SeleniumAutoProject\Testcases\loginPageTest\test_publciLoginPage.py - test_publciLoginPage.py[:36] - -------------------------------------------------
ERROR - 2020-10-28 23:29:13,252 - D:\Pycharm\AutoProject\SeleniumAutoProject\Testcases\loginPageTest\test_publciLoginPage.py - test_publciLoginPage.py[:36] - -------------------------------------------------
ERROR - 2020-10-28 23:29:16,160 - D:\Pycharm\AutoProject\SeleniumAutoProject\Testcases\loginPageTest\test_publciLoginPage.py - test_publciLoginPage.py[:36] - -------------------------------------------------
ERROR - 2020-10-28 23:29:17,384 - D:\Pycharm\AutoProject\SeleniumAutoProject\Testcases\loginPageTest\test_publciLoginPage.py - test_publciLoginPage.py[:36] - -------------------------------------------------
ERROR - 2020-10-28 23:29:19,588 - D:\Pycharm\AutoProject\SeleniumAutoProject\Testcases\loginPageTest\test_publciLoginPage.py - test_publciLoginPage.py[:36] - -------------------------------------------------
ERROR - 2020-10-28 23:31:12,142 - D:\Pycharm\AutoProject\SeleniumAutoProject\Testcases\loginPageTest\test_publciLoginPage.py - test_publciLoginPage.py[:36] - -------------------------------------------------
ERROR - 2020-10-28 23:31:13,931 - D:\Pycharm\AutoProject\SeleniumAutoProject\Testcases\loginPageTest\test_publciLoginPage.py - test_publciLoginPage.py[:36] - -------------------------------------------------
ERROR - 2020-10-28 23:31:14,730 - D:\Pycharm\AutoProject\SeleniumAutoProject\Testcases\loginPageTest\test_publciLoginPage.py - test_publciLoginPage.py[:36] - -------------------------------------------------
ERROR - 2020-10-28 23:31:15,820 - D:\Pycharm\AutoProject\SeleniumAutoProject\Testcases\loginPageTest\test_publciLoginPage.py - test_publciLoginPage.py[:36] - -------------------------------------------------
ERROR - 2020-10-28 23:31:17,580 - D:\Pycharm\AutoProject\SeleniumAutoProject\Testcases\loginPageTest\test_publciLoginPage.py - test_publciLoginPage.py[:36] - -------------------------------------------------
ERROR - 2020-10-28 23:32:20,564 - D:\Pycharm\AutoProject\SeleniumAutoProject\Testcases\loginPageTest\test_publciLoginPage.py - test_publciLoginPage.py[:36] - -------------------------------------------------
ERROR - 2020-10-28 23:32:22,350 - D:\Pycharm\AutoProject\SeleniumAutoProject\Testcases\loginPageTest\test_publciLoginPage.py - test_publciLoginPage.py[:36] - -------------------------------------------------
ERROR - 2020-10-28 23:32:23,870 - D:\Pycharm\AutoProject\SeleniumAutoProject\Testcases\loginPageTest\test_publciLoginPage.py - test_publciLoginPage.py[:36] - -------------------------------------------------
ERROR - 2020-10-28 23:32:25,766 - D:\Pycharm\AutoProject\SeleniumAutoProject\Testcases\loginPageTest\test_publciLoginPage.py - test_publciLoginPage.py[:36] - -------------------------------------------------
ERROR - 2020-10-28 23:32:27,449 - D:\Pycharm\AutoProject\SeleniumAutoProject\Testcases\loginPageTest\test_publciLoginPage.py - test_publciLoginPage.py[:36] - -------------------------------------------------
ERROR - 2020-10-28 23:36:35,067 - D:\Pycharm\AutoProject\SeleniumAutoProject\Testcases\loginPageTest\test_publciLoginPage.py - test_publciLoginPage.py[:36] - -------------------------------------------------
ERROR - 2020-10-28 23:36:36,019 - D:\Pycharm\AutoProject\SeleniumAutoProject\Testcases\loginPageTest\test_publciLoginPage.py - test_publciLoginPage.py[:36] - -------------------------------------------------
ERROR - 2020-10-28 23:36:36,747 - D:\Pycharm\AutoProject\SeleniumAutoProject\Testcases\loginPageTest\test_publciLoginPage.py - test_publciLoginPage.py[:36] - -------------------------------------------------
ERROR - 2020-10-28 23:36:37,553 - D:\Pycharm\AutoProject\SeleniumAutoProject\Testcases\loginPageTest\test_publciLoginPage.py - test_publciLoginPage.py[:36] - -------------------------------------------------
ERROR - 2020-10-28 23:36:39,208 - D:\Pycharm\AutoProject\SeleniumAutoProject\Testcases\loginPageTest\test_publciLoginPage.py - test_publciLoginPage.py[:36] - -------------------------------------------------
ERROR - 2020-10-29 01:09:04,813 - D:\Pycharm\AutoProject\SeleniumAutoProject\Testcases\loginPageTest\test_publciLoginPage.py - test_publciLoginPage.py[:74] - <class 'selenium.common.exceptions.TimeoutException'>
ERROR - 2020-10-29 01:09:08,611 - D:\Pycharm\AutoProject\SeleniumAutoProject\Testcases\loginPageTest\test_publciLoginPage.py - test_publciLoginPage.py[:74] - <class 'selenium.common.exceptions.TimeoutException'>
ERROR - 2020-10-29 01:27:31,635 - D:\Pycharm\AutoProject\SeleniumAutoProject\Testcases\loginPageTest\test_publciLoginPage.py - test_publciLoginPage.py[:74] - <class 'selenium.common.exceptions.TimeoutException'>
ERROR - 2020-10-29 01:27:37,080 - D:\Pycharm\AutoProject\SeleniumAutoProject\Testcases\loginPageTest\test_publciLoginPage.py - test_publciLoginPage.py[:74] - <class 'selenium.common.exceptions.TimeoutException'>
ERROR - 2020-10-29 12:44:00,264 - D:\csv\Se_Project\Testcases\loginPageTest\test_publciLoginPage.py - test_publciLoginPage.py[:75] - 出现异常
ERROR - 2020-10-29 12:44:00,264 - D:\csv\Se_Project\Testcases\loginPageTest\test_publciLoginPage.py - test_publciLoginPage.py[:76] - <class 'selenium.common.exceptions.TimeoutException'>
ERROR - 2020-10-29 12:44:05,970 - D:\csv\Se_Project\Testcases\loginPageTest\test_publciLoginPage.py - test_publciLoginPage.py[:75] - 出现异常
ERROR - 2020-10-29 12:44:05,970 - D:\csv\Se_Project\Testcases\loginPageTest\test_publciLoginPage.py - test_publciLoginPage.py[:76] - <class 'selenium.common.exceptions.TimeoutException'>
ERROR - 2020-10-29 12:44:08,474 - D:\csv\Se_Project\Testcases\loginPageTest\test_publciLoginPage.py - test_publciLoginPage.py[:75] - 出现异常
ERROR - 2020-10-29 12:44:08,474 - D:\csv\Se_Project\Testcases\loginPageTest\test_publciLoginPage.py - test_publciLoginPage.py[:76] - <class 'selenium.common.exceptions.TimeoutException'>
ERROR - 2020-11-16 11:18:12,872 - D:\csv\Se_Project\Testcases\loginPageTest\test_publciLoginPage.py - test_publciLoginPage.py[:76] - 出现异常
ERROR - 2020-11-16 11:18:12,875 - D:\csv\Se_Project\Testcases\loginPageTest\test_publciLoginPage.py - test_publciLoginPage.py[:77] - <class 'selenium.common.exceptions.TimeoutException'>
ERROR - 2021-01-06 13:33:11,650 - D:\se\Se_Project\Testcases\loginPageTest\test_publciLoginPage.py - test_publciLoginPage.py[:80] - 出现异常
ERROR - 2021-01-06 13:33:11,650 - D:\se\Se_Project\Testcases\loginPageTest\test_publciLoginPage.py - test_publciLoginPage.py[:81] - <class 'selenium.common.exceptions.TimeoutException'>
ERROR - 2021-01-06 14:17:48,620 - D:\se\Se_Project\Testcases\loginPageTest\test_publciLoginPage.py - test_publciLoginPage.py[:79] - 出现异常
ERROR - 2021-01-06 14:17:48,620 - D:\se\Se_Project\Testcases\loginPageTest\test_publciLoginPage.py - test_publciLoginPage.py[:80] - <class 'selenium.common.exceptions.TimeoutException'>
ERROR - 2021-01-06 20:18:57,629 - D:\se\Se_Project\Testcases\loginPageTest\test_publciLoginPage.py - test_publciLoginPage.py[:79] - 出现异常
ERROR - 2021-01-06 20:18:57,629 - D:\se\Se_Project\Testcases\loginPageTest\test_publciLoginPage.py - test_publciLoginPage.py[:80] - <class 'selenium.common.exceptions.TimeoutException'>
ERROR - 2021-01-06 20:18:59,909 - D:\se\Se_Project\Testcases\loginPageTest\test_publciLoginPage.py - test_publciLoginPage.py[:79] - 出现异常
ERROR - 2021-01-06 20:18:59,909 - D:\se\Se_Project\Testcases\loginPageTest\test_publciLoginPage.py - test_publciLoginPage.py[:80] - <class 'selenium.common.exceptions.TimeoutException'>
ERROR - 2021-01-07 09:17:02,923 - D:\se\Se_Project\Testcases\loginPageTest\test_publciLoginPage.py - test_publciLoginPage.py[:79] - 出现异常
ERROR - 2021-01-07 09:17:02,924 - D:\se\Se_Project\Testcases\loginPageTest\test_publciLoginPage.py - test_publciLoginPage.py[:80] - <class 'AttributeError'>
ERROR - 2021-01-07 09:17:04,055 - D:\se\Se_Project\Testcases\loginPageTest\test_publciLoginPage.py - test_publciLoginPage.py[:79] - 出现异常
ERROR - 2021-01-07 09:17:04,056 - D:\se\Se_Project\Testcases\loginPageTest\test_publciLoginPage.py - test_publciLoginPage.py[:80] - <class 'AttributeError'>
ERROR - 2021-01-07 09:17:05,041 - D:\se\Se_Project\Testcases\loginPageTest\test_publciLoginPage.py - test_publciLoginPage.py[:79] - 出现异常
ERROR - 2021-01-07 09:17:05,041 - D:\se\Se_Project\Testcases\loginPageTest\test_publciLoginPage.py - test_publciLoginPage.py[:80] - <class 'AttributeError'>
ERROR - 2021-01-07 09:17:06,101 - D:\se\Se_Project\Testcases\loginPageTest\test_publciLoginPage.py - test_publciLoginPage.py[:79] - 出现异常
ERROR - 2021-01-07 09:17:06,101 - D:\se\Se_Project\Testcases\loginPageTest\test_publciLoginPage.py - test_publciLoginPage.py[:80] - <class 'AttributeError'>
ERROR - 2021-01-07 09:17:07,120 - D:\se\Se_Project\Testcases\loginPageTest\test_publciLoginPage.py - test_publciLoginPage.py[:79] - 出现异常
ERROR - 2021-01-07 09:17:07,120 - D:\se\Se_Project\Testcases\loginPageTest\test_publciLoginPage.py - test_publciLoginPage.py[:80] - <class 'AttributeError'>
ERROR - 2021-01-07 09:20:12,063 - D:\se\Se_Project\Testcases\loginPageTest\test_publciLoginPage.py - test_publciLoginPage.py[:79] - 出现异常
ERROR - 2021-01-07 09:20:12,064 - D:\se\Se_Project\Testcases\loginPageTest\test_publciLoginPage.py - test_publciLoginPage.py[:80] - <class 'AssertionError'>
ERROR - 2021-01-07 09:20:15,736 - D:\se\Se_Project\Testcases\loginPageTest\test_publciLoginPage.py - test_publciLoginPage.py[:79] - 出现异常
ERROR - 2021-01-07 09:20:15,736 - D:\se\Se_Project\Testcases\loginPageTest\test_publciLoginPage.py - test_publciLoginPage.py[:80] - <class 'selenium.common.exceptions.TimeoutException'>
ERROR - 2021-01-07 09:20:17,608 - D:\se\Se_Project\Testcases\loginPageTest\test_publciLoginPage.py - test_publciLoginPage.py[:79] - 出现异常
ERROR - 2021-01-07 09:20:17,609 - D:\se\Se_Project\Testcases\loginPageTest\test_publciLoginPage.py - test_publciLoginPage.py[:80] - <class 'AssertionError'>
ERROR - 2021-01-07 09:20:20,103 - D:\se\Se_Project\Testcases\loginPageTest\test_publciLoginPage.py - test_publciLoginPage.py[:79] - 出现异常
ERROR - 2021-01-07 09:20:20,103 - D:\se\Se_Project\Testcases\loginPageTest\test_publciLoginPage.py - test_publciLoginPage.py[:80] - <class 'selenium.common.exceptions.TimeoutException'>
ERROR - 2021-01-07 09:34:32,803 - D:/se/Se_Project/Util/log.py - log.py[:44] - 测试error
CRITICAL - 2021-01-07 09:34:32,803 - D:/se/Se_Project/Util/log.py - log.py[:47] - 测试critical
ERROR - 2021-01-07 09:36:40,131 - D:/se/Se_Project/Util/log.py - log.py[:45] - 测试error
CRITICAL - 2021-01-07 09:36:40,131 - D:/se/Se_Project/Util/log.py - log.py[:48] - 测试critical
ERROR - 2021-01-07 10:06:43,762 - D:\se\Se_Project\Testcases\loginPageTest\test_publciLoginPage.py - test_publciLoginPage.py[:83] - 出现异常
ERROR - 2021-01-07 10:06:43,763 - D:\se\Se_Project\Testcases\loginPageTest\test_publciLoginPage.py - test_publciLoginPage.py[:84] - <class 'AssertionError'>
ERROR - 2021-01-07 10:06:49,560 - D:\se\Se_Project\Testcases\loginPageTest\test_publciLoginPage.py - test_publciLoginPage.py[:83] - 出现异常
ERROR - 2021-01-07 10:06:49,560 - D:\se\Se_Project\Testcases\loginPageTest\test_publciLoginPage.py - test_publciLoginPage.py[:84] - <class 'selenium.common.exceptions.TimeoutException'>
ERROR - 2021-01-07 10:06:52,170 - D:\se\Se_Project\Testcases\loginPageTest\test_publciLoginPage.py - test_publciLoginPage.py[:83] - 出现异常
ERROR - 2021-01-07 10:06:52,170 - D:\se\Se_Project\Testcases\loginPageTest\test_publciLoginPage.py - test_publciLoginPage.py[:84] - <class 'selenium.common.exceptions.TimeoutException'>
ERROR - 2021-01-07 10:21:33,209 - D:\se\Se_Project\Util\log.py - log.py[:46] - 出现异常
ERROR - 2021-01-07 10:21:33,209 - D:\se\Se_Project\Util\log.py - log.py[:46] - <class 'selenium.common.exceptions.TimeoutException'>
ERROR - 2021-01-07 10:21:39,421 - D:\se\Se_Project\Util\log.py - log.py[:46] - 出现异常
ERROR - 2021-01-07 10:21:39,421 - D:\se\Se_Project\Util\log.py - log.py[:46] - <class 'selenium.common.exceptions.TimeoutException'>
ERROR - 2021-01-07 10:21:42,297 - D:\se\Se_Project\Util\log.py - log.py[:46] - 出现异常
ERROR - 2021-01-07 10:21:42,298 - D:\se\Se_Project\Util\log.py - log.py[:46] - <class 'selenium.common.exceptions.TimeoutException'>
ERROR - 2021-01-07 10:25:51,024 - D:\se\Se_Project\Util\log.py - log.py[:46] - 出现异常
ERROR - 2021-01-07 10:25:51,024 - D:\se\Se_Project\Util\log.py - log.py[:46] - <class 'selenium.common.exceptions.TimeoutException'>
ERROR - 2021-01-19 15:05:29,570 - D:\se\Se_Project\Util\log.py - log.py[:46] - Exception: Don't find Boe, please check config
ERROR - 2021-01-19 15:07:20,198 - D:\se\Se_Project\Util\log.py - log.py[:46] - Exception: Don't find Boe, please check config
ERROR - 2021-01-19 15:22:37,643 - D:\se\Se_Project\Util\log.py - log.py[:46] - Exception: Don't find Boe, please check config
ERROR - 2021-01-19 15:23:30,747 - D:\se\Se_Project\Util\log.py - log.py[:46] - Exception: Don't find Boe, please check config
ERROR - 2021-01-19 17:42:41,544 - D:\se\Se_Project\Util\log.py - log.py[:46] - 没有找到对应配置项，请检查配置
ERROR - 2021-01-19 17:43:40,309 - D:\se\Se_Project\Util\log.py - log.py[:46] - 没有找到对应配置项，请检查配置
ERROR - 2021-01-19 20:46:13,141 - D:\se\Se_Project\Util\log.py - log.py[:46] - 没有找到对应配置项，请检查配置
ERROR - 2021-01-19 20:47:05,598 - D:\se\Se_Project\Util\log.py - log.py[:46] - 没有找到对应配置项，请检查配置
ERROR - 2021-01-19 21:00:53,801 - D:\se\Se_Project\Util\log.py - log.py[:46] - 没有找到对应配置项，请检查配置
ERROR - 2021-01-20 16:52:40,732 - D:\se\Se_Project\Util\log.py - log.py[:46] - Exception: Don't find Boe, please check config
ERROR - 2021-01-21 14:04:15,678 - D:\se\Se_Project\Util\log.py - log.py[:46] - 出现异常，异常信息为：<class 'selenium.common.exceptions.NoSuchElementException'>
ERROR - 2021-01-21 14:18:59,864 - D:\se\Se_Project\Util\log.py - log.py[:46] - 出现异常，异常信息为：<class 'selenium.common.exceptions.ElementClickInterceptedException'>
ERROR - 2021-01-21 14:41:03,395 - D:\se\Se_Project\Util\log.py - log.py[:46] - 出现异常，异常信息为：<class 'selenium.common.exceptions.NoSuchElementException'>
ERROR - 2021-01-21 18:56:25,844 - D:\se\Se_Project\Util\log.py - log.py[:46] - Exception: Don't find Boe, please check config
ERROR - 2021-01-21 20:04:09,421 - D:\se\Se_Project\Util\log.py - log.py[:46] - Exception: Don't find Boe, please check config
ERROR - 2021-01-21 20:45:50,247 - D:\se\Se_Project\Util\log.py - log.py[:46] - 出现异常，异常信息为：<class 'ValueError'>
ERROR - 2021-01-21 20:47:43,322 - D:\se\Se_Project\Util\log.py - log.py[:46] - 出现异常，异常信息为：<class 'ValueError'>
ERROR - 2021-01-21 20:50:47,814 - D:\se\Se_Project\Util\log.py - log.py[:46] - 出现异常，异常信息为：<class 'ValueError'>
ERROR - 2021-01-22 10:19:20,069 - D:\se\Se_Project\Util\log.py - log.py[:46] - Exception: Don't find Boe, please check config
ERROR - 2021-01-22 13:43:32,582 - D:\se\Se_Project\Util\log.py - log.py[:46] - 业务审批出现异常，异常信息为：<class 'Exception'>
ERROR - 2021-01-22 13:46:40,363 - D:\se\Se_Project\Util\log.py - log.py[:46] - Exception: Don't find Boe, please check config
ERROR - 2021-01-22 13:46:40,364 - D:\se\Se_Project\Util\log.py - log.py[:46] - 出现异常，异常信息为：<class 'Exception'>
ERROR - 2021-01-22 13:47:13,303 - D:\se\Se_Project\Util\log.py - log.py[:46] - 出现异常，异常信息为：<class 'selenium.common.exceptions.NoSuchElementException'>
ERROR - 2021-01-22 13:49:03,699 - D:\se\Se_Project\Util\log.py - log.py[:46] - 出现异常，异常信息为：<class 'selenium.common.exceptions.NoSuchElementException'>
ERROR - 2021-01-22 13:52:55,787 - D:\se\Se_Project\Util\log.py - log.py[:46] - 业务审批出现异常，异常信息为：<class 'Exception'>
ERROR - 2021-01-22 13:55:08,483 - D:\se\Se_Project\Util\log.py - log.py[:46] - boeNum do not exist
ERROR - 2021-01-22 13:55:08,483 - D:\se\Se_Project\Util\log.py - log.py[:46] - 业务审批出现异常，异常信息为：<class 'Exception'>
ERROR - 2021-01-22 13:58:11,956 - D:\se\Se_Project\Util\log.py - log.py[:46] - 出现异常，异常信息为：<class 'AssertionError'>
ERROR - 2021-01-22 14:02:38,714 - D:\se\Se_Project\Util\log.py - log.py[:46] - 业务审批出现异常，异常信息为：<class 'selenium.common.exceptions.TimeoutException'>
ERROR - 2021-01-22 14:06:54,950 - D:\se\Se_Project\Util\log.py - log.py[:46] - 业务审批出现异常，异常信息为：<class 'selenium.common.exceptions.TimeoutException'>
ERROR - 2021-01-22 14:08:17,649 - D:\se\Se_Project\Util\log.py - log.py[:46] - Exception: Don't find Boe, please check config
ERROR - 2021-01-22 14:08:17,650 - D:\se\Se_Project\Util\log.py - log.py[:46] - 出现异常，异常信息为：<class 'Exception'>
ERROR - 2021-01-22 14:09:04,861 - D:\se\Se_Project\Util\log.py - log.py[:46] - Exception: Don't find Boe, please check config
ERROR - 2021-01-22 14:09:04,864 - D:\se\Se_Project\Util\log.py - log.py[:46] - 出现异常，异常信息为：<class 'Exception'>
ERROR - 2021-01-22 14:14:51,391 - D:\se\Se_Project\Util\log.py - log.py[:46] - 业务审批出现异常，异常信息为：<class 'selenium.common.exceptions.TimeoutException'>
ERROR - 2021-01-22 14:19:01,271 - D:\se\Se_Project\Util\log.py - log.py[:46] - 业务审批出现异常，异常信息为：<class 'selenium.common.exceptions.TimeoutException'>
ERROR - 2021-01-22 14:20:26,089 - D:\se\Se_Project\Util\log.py - log.py[:46] - 业务审批出现异常，异常信息为：<class 'selenium.common.exceptions.NoSuchElementException'>
ERROR - 2021-01-22 14:28:51,568 - D:\se\Se_Project\Util\log.py - log.py[:46] - Exception: Don't find Boe, please check config
ERROR - 2021-01-22 14:28:51,568 - D:\se\Se_Project\Util\log.py - log.py[:46] - 出现异常，异常信息为：<class 'Exception'>
ERROR - 2021-01-22 14:34:08,607 - D:\se\Se_Project\Util\log.py - log.py[:46] - 出现异常，异常信息为：<class 'selenium.common.exceptions.NoSuchElementException'>
ERROR - 2021-01-22 14:35:13,239 - D:\se\Se_Project\Util\log.py - log.py[:46] - 出现异常，异常信息为：<class 'selenium.common.exceptions.TimeoutException'>
ERROR - 2021-01-22 14:41:11,865 - D:\se\Se_Project\Util\log.py - log.py[:46] - 出现异常，异常信息为：<class 'selenium.common.exceptions.TimeoutException'>
ERROR - 2021-01-22 14:41:43,906 - D:\se\Se_Project\Util\log.py - log.py[:46] - Exception: Don't find Boe, please check config
ERROR - 2021-01-22 14:41:43,907 - D:\se\Se_Project\Util\log.py - log.py[:46] - 出现异常，异常信息为：<class 'Exception'>
ERROR - 2021-01-22 14:42:06,312 - D:\se\Se_Project\Util\log.py - log.py[:46] - Exception: Don't find Boe, please check config
ERROR - 2021-01-22 14:42:06,313 - D:\se\Se_Project\Util\log.py - log.py[:46] - 出现异常，异常信息为：<class 'Exception'>
ERROR - 2021-01-22 15:14:56,350 - D:\se\Se_Project\Util\log.py - log.py[:46] - Exception: Don't find Boe, please check config
ERROR - 2021-01-22 15:14:56,350 - D:\se\Se_Project\Util\log.py - log.py[:46] - 出现异常，异常信息为：<class 'Exception'>
ERROR - 2021-01-22 15:17:06,980 - D:\se\Se_Project\Util\log.py - log.py[:46] - Exception: Don't find Boe, please check config
ERROR - 2021-01-22 15:17:06,982 - D:\se\Se_Project\Util\log.py - log.py[:46] - 出现异常，异常信息为：<class 'Exception'>
ERROR - 2021-01-22 15:18:14,379 - D:\se\Se_Project\Util\log.py - log.py[:46] - 出现异常，异常信息为：<class 'selenium.common.exceptions.TimeoutException'>
ERROR - 2021-01-22 15:19:50,411 - D:\se\Se_Project\Util\log.py - log.py[:46] - Exception: Don't find Boe, please check config
ERROR - 2021-01-22 15:19:50,411 - D:\se\Se_Project\Util\log.py - log.py[:46] - 出现异常，异常信息为：<class 'Exception'>
ERROR - 2021-01-22 15:20:17,083 - D:\se\Se_Project\Util\log.py - log.py[:46] - Exception: Don't find Boe, please check config
ERROR - 2021-01-22 15:20:17,084 - D:\se\Se_Project\Util\log.py - log.py[:46] - 出现异常，异常信息为：<class 'Exception'>
ERROR - 2021-01-22 15:26:04,407 - D:\se\Se_Project\Util\log.py - log.py[:46] - 出现异常，异常信息为：<class 'selenium.common.exceptions.TimeoutException'>
ERROR - 2021-01-22 15:27:04,459 - D:\se\Se_Project\Util\log.py - log.py[:46] - 出现异常，异常信息为：<class 'selenium.common.exceptions.TimeoutException'>
ERROR - 2021-01-22 15:29:06,380 - D:\se\Se_Project\Util\log.py - log.py[:46] - 出现异常，异常信息为：<class 'selenium.common.exceptions.TimeoutException'>
ERROR - 2021-01-22 16:05:26,141 - D:\se\Se_Project\Util\log.py - log.py[:46] - Exception: Don't find Boe, please check config
ERROR - 2021-01-22 16:05:26,143 - D:\se\Se_Project\Util\log.py - log.py[:46] - 出现异常，异常信息为：<class 'Exception'>
ERROR - 2021-01-22 16:09:22,613 - D:\se\Se_Project\Util\log.py - log.py[:46] - 出现异常，异常信息为：<class 'selenium.common.exceptions.TimeoutException'>
ERROR - 2021-01-22 16:15:29,696 - D:\se\Se_Project\Util\log.py - log.py[:46] - 出现异常，异常信息为：<class 'selenium.common.exceptions.TimeoutException'>
ERROR - 2021-01-22 16:15:57,794 - D:\se\Se_Project\Util\log.py - log.py[:46] - Exception: Don't find Boe, please check config
ERROR - 2021-01-22 16:30:35,670 - D:\se\Se_Project\Util\log.py - log.py[:46] - Exception: Don't find Boe, please check config
ERROR - 2021-01-22 16:33:27,793 - D:\se\Se_Project\Util\log.py - log.py[:46] - Exception: Don't find Boe, please check config
ERROR - 2021-01-22 16:33:41,728 - D:\se\Se_Project\Util\log.py - log.py[:46] - 出现异常，异常信息为：<class 'selenium.common.exceptions.TimeoutException'>
ERROR - 2021-01-22 16:34:21,751 - D:\se\Se_Project\Util\log.py - log.py[:46] - 出现异常，异常信息为：<class 'AttributeError'>
ERROR - 2021-01-22 16:47:02,001 - D:\se\Se_Project\Util\log.py - log.py[:46] - Exception: Don't find Boe, please check config
ERROR - 2021-01-22 16:47:02,463 - D:\se\Se_Project\Util\log.py - log.py[:46] - Exception: Don't find Boe, please check config
ERROR - 2021-01-22 16:47:02,465 - D:\se\Se_Project\Util\log.py - log.py[:46] - 出现异常，异常信息为：<class 'Exception'>
ERROR - 2021-01-22 16:48:37,494 - D:\se\Se_Project\Util\log.py - log.py[:46] - Exception: Don't find Boe, please check config
ERROR - 2021-01-22 16:48:37,496 - D:\se\Se_Project\Util\log.py - log.py[:46] - 出现异常，异常信息为：<class 'Exception'>
ERROR - 2021-01-22 16:50:14,483 - D:\se\Se_Project\Util\log.py - log.py[:46] - 出现异常，异常信息为：<class 'selenium.common.exceptions.TimeoutException'>
ERROR - 2021-01-22 20:35:31,231 - D:\se\Se_Project\Util\log.py - log.py[:46] - 出现异常，异常信息为：<class 'selenium.common.exceptions.TimeoutException'>
ERROR - 2021-01-22 20:36:59,751 - D:\se\Se_Project\Util\log.py - log.py[:46] - 出现异常，异常信息为：<class 'selenium.common.exceptions.TimeoutException'>
ERROR - 2021-01-22 20:38:41,466 - D:\se\Se_Project\Util\log.py - log.py[:46] - 出现异常，异常信息为：<class 'selenium.common.exceptions.TimeoutException'>
ERROR - 2021-01-22 20:40:14,829 - D:\se\Se_Project\Util\log.py - log.py[:46] - 出现异常，异常信息为：<class 'selenium.common.exceptions.TimeoutException'>
ERROR - 2021-01-22 20:41:02,247 - D:\se\Se_Project\Util\log.py - log.py[:46] - 出现异常，异常信息为：<class 'selenium.common.exceptions.TimeoutException'>
ERROR - 2021-01-22 20:42:18,299 - D:\se\Se_Project\Util\log.py - log.py[:46] - 出现异常，异常信息为：<class 'selenium.common.exceptions.TimeoutException'>
ERROR - 2021-01-22 20:43:50,640 - D:\se\Se_Project\Util\log.py - log.py[:46] - 出现异常，异常信息为：<class 'selenium.common.exceptions.TimeoutException'>
ERROR - 2021-01-22 20:44:39,169 - D:\se\Se_Project\Util\log.py - log.py[:46] - 出现异常，异常信息为：<class 'selenium.common.exceptions.TimeoutException'>
ERROR - 2021-01-22 20:54:03,389 - D:\se\Se_Project\Util\log.py - log.py[:46] - 出现异常，异常信息为：<class 'selenium.common.exceptions.TimeoutException'>
ERROR - 2021-01-22 21:07:03,588 - D:\se\Se_Project\Util\log.py - log.py[:46] - 出现异常，异常信息为：<class 'AttributeError'>
ERROR - 2021-01-22 21:08:03,790 - D:\se\Se_Project\Util\log.py - log.py[:46] - 出现异常，异常信息为：<class 'AttributeError'>
ERROR - 2021-01-22 21:09:32,598 - D:\se\Se_Project\Util\log.py - log.py[:46] - 出现异常，异常信息为：<class 'selenium.common.exceptions.TimeoutException'>
ERROR - 2021-01-22 21:27:01,002 - D:\se\Se_Project\Util\log.py - log.py[:46] - 出现异常，异常信息为：<class 'selenium.common.exceptions.TimeoutException'>
ERROR - 2021-01-22 21:27:47,617 - D:\se\Se_Project\Util\log.py - log.py[:46] - 出现异常，异常信息为：<class 'selenium.common.exceptions.TimeoutException'>
ERROR - 2021-01-22 21:30:34,398 - D:\se\Se_Project\Util\log.py - log.py[:46] - 出现异常，异常信息为：<class 'selenium.common.exceptions.TimeoutException'>
ERROR - 2021-01-22 21:30:59,690 - D:\se\Se_Project\Util\log.py - log.py[:46] - Exception: Don't find Boe, please check config
ERROR - 2021-01-22 21:30:59,690 - D:\se\Se_Project\Util\log.py - log.py[:46] - 出现异常，异常信息为：<class 'Exception'>
ERROR - 2021-01-22 23:14:50,479 - D:\se\Se_Project\Util\log.py - log.py[:46] - 出现异常，异常信息为：<class 'AttributeError'>
ERROR - 2021-01-22 23:15:25,226 - D:\se\Se_Project\Util\log.py - log.py[:46] - 出现异常，异常信息为：<class 'AttributeError'>
ERROR - 2021-01-22 23:21:36,438 - D:\se\Se_Project\Util\log.py - log.py[:46] - Exception: Don't find Boe, please check config
ERROR - 2021-01-22 23:21:36,438 - D:\se\Se_Project\Util\log.py - log.py[:46] - 出现异常，异常信息为：<class 'Exception'>
ERROR - 2021-01-22 23:32:51,415 - D:\se\Se_Project\Util\log.py - log.py[:46] - 出现异常，异常信息为：<class 'selenium.common.exceptions.NoSuchElementException'>
ERROR - 2021-01-22 23:34:06,267 - D:\se\Se_Project\Util\log.py - log.py[:46] - 出现异常，异常信息为：<class 'selenium.common.exceptions.NoSuchElementException'>
ERROR - 2021-01-22 23:35:55,257 - D:\se\Se_Project\Util\log.py - log.py[:46] - 出现异常，异常信息为：<class 'selenium.common.exceptions.StaleElementReferenceException'>
ERROR - 2021-01-22 23:36:46,455 - D:\se\Se_Project\Util\log.py - log.py[:46] - 出现异常，异常信息为：<class 'selenium.common.exceptions.StaleElementReferenceException'>
ERROR - 2021-01-22 23:39:00,513 - D:\se\Se_Project\Util\log.py - log.py[:46] - 出现异常，异常信息为：<class 'selenium.common.exceptions.TimeoutException'>
ERROR - 2021-01-22 23:48:38,604 - D:\se\Se_Project\Util\log.py - log.py[:46] - 出现异常，异常信息为：<class 'selenium.common.exceptions.TimeoutException'>
ERROR - 2021-01-22 23:51:57,115 - D:\se\Se_Project\Util\log.py - log.py[:46] - 出现异常，异常信息为：<class 'selenium.common.exceptions.ElementClickInterceptedException'>
ERROR - 2021-01-22 23:52:32,775 - D:\se\Se_Project\Util\log.py - log.py[:46] - 出现异常，异常信息为：<class 'selenium.common.exceptions.ElementClickInterceptedException'>
ERROR - 2021-01-23 00:07:42,630 - D:\se\Se_Project\Util\log.py - log.py[:46] - Exception: Don't find Boe, please check config
ERROR - 2021-01-23 00:07:42,631 - D:\se\Se_Project\Util\log.py - log.py[:46] - 出现异常，异常信息为：<class 'Exception'>
ERROR - 2021-01-23 00:29:33,387 - D:\se\Se_Project\Util\log.py - log.py[:46] - Exception: Don't find Boe, please check config
ERROR - 2021-01-23 00:29:33,388 - D:\se\Se_Project\Util\log.py - log.py[:46] - 出现异常，异常信息为：<class 'Exception'>
ERROR - 2021-01-23 00:30:09,453 - D:\se\Se_Project\Util\log.py - log.py[:46] - Exception: Don't find Boe, please check config
ERROR - 2021-01-23 00:30:09,454 - D:\se\Se_Project\Util\log.py - log.py[:46] - 出现异常，异常信息为：<class 'Exception'>
ERROR - 2021-01-23 00:30:40,164 - D:\se\Se_Project\Util\log.py - log.py[:46] - Exception: Don't find Boe, please check config
ERROR - 2021-01-23 00:30:40,165 - D:\se\Se_Project\Util\log.py - log.py[:46] - 出现异常，异常信息为：<class 'Exception'>
ERROR - 2021-01-23 00:32:07,045 - D:\se\Se_Project\Util\log.py - log.py[:46] - 出现异常，异常信息为：<class 'selenium.common.exceptions.NoSuchElementException'>
ERROR - 2021-01-23 00:32:40,805 - D:\se\Se_Project\Util\log.py - log.py[:46] - Exception: Don't find Boe, please check config
ERROR - 2021-01-23 00:32:40,805 - D:\se\Se_Project\Util\log.py - log.py[:46] - 出现异常，异常信息为：<class 'Exception'>
ERROR - 2021-01-23 00:36:33,216 - D:\se\Se_Project\Util\log.py - log.py[:46] - 出现异常，异常信息为：<class 'selenium.common.exceptions.TimeoutException'>
ERROR - 2021-01-23 01:07:24,167 - D:\se\Se_Project\Util\log.py - log.py[:46] - Exception: Don't find Boe, please check config
ERROR - 2021-01-23 01:07:24,168 - D:\se\Se_Project\Util\log.py - log.py[:46] - 出现异常，异常信息为：<class 'Exception'>
ERROR - 2021-01-23 01:08:41,120 - D:\se\Se_Project\Util\log.py - log.py[:46] - Exception: Don't find Boe, please check config
ERROR - 2021-01-23 01:08:41,121 - D:\se\Se_Project\Util\log.py - log.py[:46] - 出现异常，异常信息为：<class 'Exception'>
ERROR - 2021-01-23 01:09:37,484 - D:\se\Se_Project\Util\log.py - log.py[:46] - Exception: Don't find Boe, please check config
ERROR - 2021-01-23 01:09:37,486 - D:\se\Se_Project\Util\log.py - log.py[:46] - 出现异常，异常信息为：<class 'Exception'>
ERROR - 2021-01-23 17:01:57,675 - D:\se\Se_Project\Util\log.py - log.py[:46] - Exception: Don't find Boe, please check config
ERROR - 2021-01-23 17:01:57,681 - D:\se\Se_Project\Util\log.py - log.py[:46] - 出现异常，异常信息为：<class 'Exception'>
ERROR - 2021-01-24 15:57:26,307 - D:\se\Se_Project\Util\log.py - log.py[:46] - 业务审批出现异常，异常信息为：<class 'selenium.common.exceptions.TimeoutException'>
ERROR - 2021-01-24 16:11:10,808 - D:\se\Se_Project\Util\log.py - log.py[:46] - Exception: Don't find Boe, please check config
ERROR - 2021-01-24 16:11:10,813 - D:\se\Se_Project\Util\log.py - log.py[:46] - 出现异常，异常信息为：<class 'Exception'>
ERROR - 2021-01-24 17:12:07,970 - D:\se\Se_Project\Util\log.py - log.py[:46] - Exception: Don't find Boe, please check config
ERROR - 2021-01-24 17:12:07,971 - D:\se\Se_Project\Util\log.py - log.py[:46] -  Don't find Boe, Try agent
ERROR - 2021-01-24 18:49:04,988 - D:\se\Se_Project\Util\log.py - log.py[:46] - 没有找到查询结果，--- try again ---
ERROR - 2021-01-24 18:53:28,332 - D:\se\Se_Project\Util\log.py - log.py[:46] - 没有找到查询结果，--- try again ---
ERROR - 2021-01-24 19:30:45,292 - D:\se\Se_Project\Util\log.py - log.py[:46] - Exception: Don't find Boe, please check config
ERROR - 2021-01-24 19:30:45,292 - D:\se\Se_Project\Util\log.py - log.py[:46] -  Don't find Boe, Try again
ERROR - 2021-01-24 19:32:29,126 - D:\se\Se_Project\Util\log.py - log.py[:46] - Exception: Don't find Boe, please check config
ERROR - 2021-01-24 19:32:29,126 - D:\se\Se_Project\Util\log.py - log.py[:46] -  Don't find Boe, Try again
ERROR - 2021-01-24 19:34:21,452 - D:\se\Se_Project\Util\log.py - log.py[:46] - 没有找到查询结果，--- try again ---
ERROR - 2021-01-24 19:45:58,381 - D:\se\Se_Project\Util\log.py - log.py[:46] - 没有找到查询结果，--- try again ---
ERROR - 2021-01-24 19:46:00,664 - D:\se\Se_Project\Util\log.py - log.py[:46] - 没有找到查询结果，--- try again ---
ERROR - 2021-01-24 19:48:40,616 - D:\se\Se_Project\Util\log.py - log.py[:46] - Exception: Don't find Boe, please check config
ERROR - 2021-01-24 19:48:40,616 - D:\se\Se_Project\Util\log.py - log.py[:46] -  Don't find Boe, Try again
ERROR - 2021-01-24 19:49:34,413 - D:\se\Se_Project\Util\log.py - log.py[:46] - 没有找到查询结果，--- try again ---
ERROR - 2021-01-24 19:54:33,778 - D:\se\Se_Project\Util\log.py - log.py[:46] - Exception: Don't find Boe, please check config
ERROR - 2021-01-24 19:54:33,778 - D:\se\Se_Project\Util\log.py - log.py[:46] -  Don't find Boe, Try again
ERROR - 2021-01-24 19:57:27,680 - D:\se\Se_Project\Util\log.py - log.py[:46] - 没有找到查询结果，--- try again ---
ERROR - 2021-01-24 19:58:33,439 - D:\se\Se_Project\Util\log.py - log.py[:46] - 没有找到查询结果，--- try again ---
ERROR - 2021-01-24 20:17:27,277 - D:\se\Se_Project\Util\log.py - log.py[:46] - Exception: Don't find Boe, please check config
ERROR - 2021-01-24 20:17:27,277 - D:\se\Se_Project\Util\log.py - log.py[:46] -  Don't find Boe, Try again
ERROR - 2021-01-24 20:17:27,279 - D:\se\Se_Project\Util\log.py - log.py[:46] - 出现异常，异常信息为：<class 'AttributeError'>
ERROR - 2021-01-24 20:18:27,146 - D:\se\Se_Project\Util\log.py - log.py[:46] - 出现异常，异常信息为：<class 'KeyError'>
ERROR - 2021-01-24 20:23:04,700 - D:\se\Se_Project\Util\log.py - log.py[:46] - 出现异常，异常信息为：<class 'KeyError'>
ERROR - 2021-01-24 20:23:55,295 - D:\se\Se_Project\Util\log.py - log.py[:46] - 出现异常，异常信息为：<class 'KeyError'>
ERROR - 2021-01-24 20:24:48,155 - D:\se\Se_Project\Util\log.py - log.py[:46] - 出现异常，异常信息为：<class 'KeyError'>
ERROR - 2021-01-24 20:29:40,753 - D:\se\Se_Project\Util\log.py - log.py[:46] - 出现异常，异常信息为：<class 'selenium.common.exceptions.TimeoutException'>
ERROR - 2021-01-24 20:33:19,326 - D:\se\Se_Project\Util\log.py - log.py[:46] - 没有找到查询结果，--- try again ---
ERROR - 2021-01-24 20:34:07,118 - D:\se\Se_Project\Util\log.py - log.py[:46] - 没有找到查询结果，--- try again ---
ERROR - 2021-01-24 20:53:45,412 - D:\se\Se_Project\Util\log.py - log.py[:46] - 出现异常，异常信息为：<class 'KeyError'>
ERROR - 2021-01-24 20:54:50,594 - D:\se\Se_Project\Util\log.py - log.py[:46] - 出现异常，异常信息为：<class 'KeyError'>
ERROR - 2021-01-24 20:57:52,501 - D:\se\Se_Project\Util\log.py - log.py[:46] - 出现异常，异常信息为：<class 'selenium.common.exceptions.NoSuchElementException'>
ERROR - 2021-01-24 21:00:17,145 - D:\se\Se_Project\Util\log.py - log.py[:46] - Exception: Don't find Boe, please check config
ERROR - 2021-01-24 21:00:18,145 - D:\se\Se_Project\Util\log.py - log.py[:46] -  Don't find Boe, Try again
ERROR - 2021-01-24 21:01:20,283 - D:\se\Se_Project\Util\log.py - log.py[:46] - 没有找到查询结果，--- try again ---
ERROR - 2021-01-24 21:02:11,591 - D:\se\Se_Project\Util\log.py - log.py[:46] - 没有找到查询结果，--- try again ---
ERROR - 2021-01-24 21:35:44,976 - D:\se\Se_Project\Util\log.py - log.py[:46] - Exception: Don't find Boe, please check config
ERROR - 2021-01-24 21:35:45,976 - D:\se\Se_Project\Util\log.py - log.py[:46] -  Don't find Boe, Try again
ERROR - 2021-01-24 21:40:07,158 - D:\se\Se_Project\Util\log.py - log.py[:46] - 没有找到查询结果，--- try again ---
ERROR - 2021-01-24 21:41:06,446 - D:\se\Se_Project\Util\log.py - log.py[:46] - 没有找到查询结果，--- try again ---
ERROR - 2021-01-24 22:02:40,713 - D:\se\Se_Project\Util\log.py - log.py[:46] - Exception: Don't find Boe, please check config
ERROR - 2021-01-24 22:02:41,714 - D:\se\Se_Project\Util\log.py - log.py[:46] -  Don't find Boe, Try again
ERROR - 2021-01-24 22:02:58,649 - D:\se\Se_Project\Util\log.py - log.py[:46] - 出现异常，异常信息为：<class 'selenium.common.exceptions.TimeoutException'>
ERROR - 2021-01-24 22:15:15,768 - D:\se\Se_Project\Util\log.py - log.py[:46] - 没有找到查询结果，--- try again ---
ERROR - 2021-01-24 22:16:11,452 - D:\se\Se_Project\Util\log.py - log.py[:46] - 没有找到查询结果，--- try again ---
ERROR - 2021-01-24 22:35:12,740 - D:\se\Se_Project\Util\log.py - log.py[:46] - 出现异常，异常信息为：<class 'selenium.common.exceptions.NoSuchElementException'>
ERROR - 2021-01-24 22:40:24,606 - D:\se\Se_Project\Util\log.py - log.py[:46] - 没有找到查询结果，--- try again ---
ERROR - 2021-01-24 22:41:11,026 - D:\se\Se_Project\Util\log.py - log.py[:46] - 没有找到查询结果，--- try again ---
ERROR - 2021-01-24 23:18:19,789 - D:\se\Se_Project\Util\log.py - log.py[:46] - 没有找到查询结果，--- try again ---
ERROR - 2021-01-24 23:19:08,618 - D:\se\Se_Project\Util\log.py - log.py[:46] - 没有找到查询结果，--- try again ---
ERROR - 2021-01-24 23:39:24,417 - D:\se\Se_Project\Util\log.py - log.py[:46] - Exception: Don't find Boe, please check config
ERROR - 2021-01-24 23:39:25,420 - D:\se\Se_Project\Util\log.py - log.py[:46] -  Don't find Boe, Try again
ERROR - 2021-01-24 23:39:25,500 - D:\se\Se_Project\Util\log.py - log.py[:46] - Exception: Don't find Boe, please check config
ERROR - 2021-01-24 23:39:25,504 - D:\se\Se_Project\Util\log.py - log.py[:46] - 出现异常，异常信息为：<class 'Exception'>
ERROR - 2021-01-24 23:40:05,713 - D:\se\Se_Project\Util\log.py - log.py[:46] - Exception: Don't find Boe, please check config
ERROR - 2021-01-24 23:40:07,714 - D:\se\Se_Project\Util\log.py - log.py[:46] -  Don't find Boe, Try again
ERROR - 2021-01-24 23:40:07,810 - D:\se\Se_Project\Util\log.py - log.py[:46] - Exception: Don't find Boe, please check config
ERROR - 2021-01-24 23:40:07,811 - D:\se\Se_Project\Util\log.py - log.py[:46] - 出现异常，异常信息为：<class 'Exception'>
ERROR - 2021-01-24 23:41:05,060 - D:\se\Se_Project\Util\log.py - log.py[:46] - Exception: Don't find Boe, please check config
ERROR - 2021-01-24 23:41:06,061 - D:\se\Se_Project\Util\log.py - log.py[:46] -  Don't find Boe, Try again
ERROR - 2021-01-24 23:41:06,132 - D:\se\Se_Project\Util\log.py - log.py[:46] - Exception: Don't find Boe, please check config
ERROR - 2021-01-24 23:41:06,135 - D:\se\Se_Project\Util\log.py - log.py[:46] - 出现异常，异常信息为：<class 'Exception'>
ERROR - 2021-01-24 23:43:26,511 - D:\se\Se_Project\Util\log.py - log.py[:46] - Exception: Don't find Boe, please check config
ERROR - 2021-01-24 23:43:27,511 - D:\se\Se_Project\Util\log.py - log.py[:46] -  Don't find Boe, Try again
ERROR - 2021-01-24 23:43:27,610 - D:\se\Se_Project\Util\log.py - log.py[:46] - Exception: Don't find Boe, please check config
ERROR - 2021-01-24 23:43:27,612 - D:\se\Se_Project\Util\log.py - log.py[:46] - 出现异常，异常信息为：<class 'Exception'>
ERROR - 2021-01-24 23:45:31,117 - D:\se\Se_Project\Util\log.py - log.py[:46] - Exception: Don't find Boe, please check config
ERROR - 2021-01-24 23:45:32,117 - D:\se\Se_Project\Util\log.py - log.py[:46] -  Don't find Boe, Try again
ERROR - 2021-01-24 23:45:32,189 - D:\se\Se_Project\Util\log.py - log.py[:46] - Exception: Don't find Boe, please check config
ERROR - 2021-01-24 23:45:32,190 - D:\se\Se_Project\Util\log.py - log.py[:46] - 出现异常，异常信息为：<class 'Exception'>
ERROR - 2021-01-24 23:46:20,868 - D:\se\Se_Project\Util\log.py - log.py[:46] - Exception: Don't find Boe, please check config
ERROR - 2021-01-24 23:50:49,827 - D:\se\Se_Project\Util\log.py - log.py[:46] - Exception: Don't find Boe, please check config
ERROR - 2021-01-24 23:50:50,829 - D:\se\Se_Project\Util\log.py - log.py[:46] -  Don't find Boe, Try again
ERROR - 2021-01-24 23:50:50,894 - D:\se\Se_Project\Util\log.py - log.py[:46] - Exception: Don't find Boe, please check config
ERROR - 2021-01-24 23:50:50,895 - D:\se\Se_Project\Util\log.py - log.py[:46] - 出现异常，异常信息为：<class 'Exception'>
ERROR - 2021-01-24 23:52:04,785 - D:\se\Se_Project\Util\log.py - log.py[:46] - Exception: Don't find Boe, please check config
ERROR - 2021-01-24 23:52:05,786 - D:\se\Se_Project\Util\log.py - log.py[:46] -  Don't find Boe, Try again
ERROR - 2021-01-24 23:52:05,861 - D:\se\Se_Project\Util\log.py - log.py[:46] - Exception: Don't find Boe, please check config
ERROR - 2021-01-24 23:52:05,862 - D:\se\Se_Project\Util\log.py - log.py[:46] - 出现异常，异常信息为：<class 'Exception'>
ERROR - 2021-01-24 23:52:59,595 - D:\se\Se_Project\Util\log.py - log.py[:46] - 出现异常，异常信息为：<class 'selenium.common.exceptions.WebDriverException'>
ERROR - 2021-01-24 23:54:02,076 - D:\se\Se_Project\Util\log.py - log.py[:46] - 出现异常，异常信息为：<class 'selenium.common.exceptions.NoSuchElementException'>
ERROR - 2021-01-24 23:56:32,004 - D:\se\Se_Project\Util\log.py - log.py[:46] - 出现异常，异常信息为：<class 'selenium.common.exceptions.ElementNotInteractableException'>
ERROR - 2021-01-24 23:58:08,666 - D:\se\Se_Project\Util\log.py - log.py[:46] - 出现异常，异常信息为：<class 'TypeError'>
ERROR - 2021-01-25 00:00:59,363 - D:\se\Se_Project\Util\log.py - log.py[:46] - 出现异常，异常信息为：<class 'selenium.common.exceptions.TimeoutException'>
ERROR - 2021-01-25 00:01:54,631 - D:\se\Se_Project\Util\log.py - log.py[:46] - Exception: Don't find Boe, please check config
ERROR - 2021-01-25 00:01:55,632 - D:\se\Se_Project\Util\log.py - log.py[:46] -  Don't find Boe, Try again
ERROR - 2021-01-25 00:03:00,050 - D:\se\Se_Project\Util\log.py - log.py[:46] - 没有找到查询结果，--- try again ---
ERROR - 2021-01-25 00:04:02,161 - D:\se\Se_Project\Util\log.py - log.py[:46] - 没有找到查询结果，--- try again ---
ERROR - 2021-01-25 00:05:24,477 - D:\se\Se_Project\Util\log.py - log.py[:46] - Exception: Don't find Boe, please check config
ERROR - 2021-01-25 00:05:25,478 - D:\se\Se_Project\Util\log.py - log.py[:46] -  Don't find Boe, Try again
ERROR - 2021-01-25 00:05:31,262 - D:\se\Se_Project\Util\log.py - log.py[:46] - 出现异常，异常信息为：<class 'selenium.common.exceptions.NoSuchElementException'>
ERROR - 2021-01-25 00:05:41,532 - D:\se\Se_Project\Util\log.py - log.py[:46] - 出现异常，异常信息为：<class 'selenium.common.exceptions.ElementClickInterceptedException'>
ERROR - 2021-01-25 00:06:53,538 - D:\se\Se_Project\Util\log.py - log.py[:46] - Exception: Don't find Boe, please check config
ERROR - 2021-01-25 00:06:54,539 - D:\se\Se_Project\Util\log.py - log.py[:46] -  Don't find Boe, Try again
ERROR - 2021-01-25 00:06:59,989 - D:\se\Se_Project\Util\log.py - log.py[:46] - 出现异常，异常信息为：<class 'selenium.common.exceptions.NoSuchElementException'>
ERROR - 2021-01-25 00:07:11,337 - D:\se\Se_Project\Util\log.py - log.py[:46] - 出现异常，异常信息为：<class 'selenium.common.exceptions.ElementClickInterceptedException'>
ERROR - 2021-01-25 00:08:10,600 - D:\se\Se_Project\Util\log.py - log.py[:46] - 出现异常，异常信息为：<class 'selenium.common.exceptions.NoSuchElementException'>
ERROR - 2021-01-25 00:08:22,190 - D:\se\Se_Project\Util\log.py - log.py[:46] - 出现异常，异常信息为：<class 'selenium.common.exceptions.ElementClickInterceptedException'>
ERROR - 2021-01-25 00:09:14,512 - D:\se\Se_Project\Util\log.py - log.py[:46] - 出现异常，异常信息为：<class 'selenium.common.exceptions.NoSuchElementException'>
ERROR - 2021-01-25 00:09:38,692 - D:\se\Se_Project\Util\log.py - log.py[:46] - 出现异常，异常信息为：<class 'selenium.common.exceptions.TimeoutException'>
ERROR - 2021-01-25 00:14:22,046 - D:\se\Se_Project\Util\log.py - log.py[:46] - 出现异常，异常信息为：<class 'selenium.common.exceptions.NoSuchElementException'>
ERROR - 2021-01-25 00:15:25,911 - D:\se\Se_Project\Util\log.py - log.py[:46] - 没有找到查询结果，--- try again ---
ERROR - 2021-01-25 00:16:26,062 - D:\se\Se_Project\Util\log.py - log.py[:46] - 没有找到查询结果，--- try again ---
ERROR - 2021-01-25 00:26:42,433 - D:\se\Se_Project\Util\log.py - log.py[:46] - Exception: Don't find Boe, please check config
ERROR - 2021-01-25 00:29:29,801 - D:\se\Se_Project\Util\log.py - log.py[:46] - Exception: Don't find Boe, please check config
ERROR - 2021-01-25 00:31:36,732 - D:\se\Se_Project\Util\log.py - log.py[:46] - 出现异常，异常信息为：<class 'selenium.common.exceptions.NoSuchElementException'>
ERROR - 2021-01-25 00:31:52,479 - D:\se\Se_Project\Util\log.py - log.py[:46] - 出现异常，异常信息为：<class 'selenium.common.exceptions.ElementClickInterceptedException'>
ERROR - 2021-01-25 00:33:02,291 - D:\se\Se_Project\Util\log.py - log.py[:46] - 出现异常，异常信息为：<class 'selenium.common.exceptions.NoSuchElementException'>
ERROR - 2021-01-25 00:33:18,271 - D:\se\Se_Project\Util\log.py - log.py[:46] - 出现异常，异常信息为：<class 'selenium.common.exceptions.ElementClickInterceptedException'>
ERROR - 2021-01-25 00:34:15,049 - D:\se\Se_Project\Util\log.py - log.py[:46] - 出现异常，异常信息为：<class 'selenium.common.exceptions.NoSuchElementException'>
ERROR - 2021-01-25 00:34:30,847 - D:\se\Se_Project\Util\log.py - log.py[:46] - 出现异常，异常信息为：<class 'selenium.common.exceptions.ElementClickInterceptedException'>
ERROR - 2021-01-25 00:35:50,706 - D:\se\Se_Project\Util\log.py - log.py[:46] - 出现异常，异常信息为：<class 'selenium.common.exceptions.NoSuchElementException'>
ERROR - 2021-01-25 00:36:07,658 - D:\se\Se_Project\Util\log.py - log.py[:46] - 出现异常，异常信息为：<class 'selenium.common.exceptions.NoSuchElementException'>
ERROR - 2021-01-25 00:36:22,918 - D:\se\Se_Project\Util\log.py - log.py[:46] - 出现异常，异常信息为：<class 'selenium.common.exceptions.ElementClickInterceptedException'>
ERROR - 2021-01-25 00:38:22,847 - D:\se\Se_Project\Util\log.py - log.py[:46] - 出现异常，异常信息为：<class 'selenium.common.exceptions.NoSuchElementException'>
ERROR - 2021-01-25 00:38:40,265 - D:\se\Se_Project\Util\log.py - log.py[:46] - 出现异常，异常信息为：<class 'selenium.common.exceptions.NoSuchElementException'>
ERROR - 2021-01-25 00:46:03,808 - D:\se\Se_Project\Util\log.py - log.py[:46] - 没有找到查询结果，--- try again ---
ERROR - 2021-01-25 00:47:07,143 - D:\se\Se_Project\Util\log.py - log.py[:46] - 没有找到查询结果，--- try again ---
ERROR - 2021-01-25 00:48:53,607 - D:\se\Se_Project\Util\log.py - log.py[:46] - 没有找到查询结果，--- try again ---
ERROR - 2021-01-25 00:49:52,510 - D:\se\Se_Project\Util\log.py - log.py[:46] - 没有找到查询结果，--- try again ---
ERROR - 2021-01-25 00:51:39,945 - D:\se\Se_Project\Util\log.py - log.py[:46] - 没有找到查询结果，--- try again ---
ERROR - 2021-01-25 00:52:47,085 - D:\se\Se_Project\Util\log.py - log.py[:46] - 没有找到查询结果，--- try again ---
ERROR - 2021-01-25 00:54:30,727 - D:\se\Se_Project\Util\log.py - log.py[:46] - 没有找到查询结果，--- try again ---
ERROR - 2021-01-25 00:55:31,722 - D:\se\Se_Project\Util\log.py - log.py[:46] - 没有找到查询结果，--- try again ---
ERROR - 2021-01-25 00:56:09,990 - D:\se\Se_Project\Util\log.py - log.py[:46] - 出现异常，异常信息为：<class 'selenium.common.exceptions.NoSuchElementException'>
ERROR - 2021-01-25 00:57:31,638 - D:\se\Se_Project\Util\log.py - log.py[:46] - 没有找到查询结果，--- try again ---
ERROR - 2021-01-25 00:58:33,541 - D:\se\Se_Project\Util\log.py - log.py[:46] - 没有找到查询结果，--- try again ---
ERROR - 2021-01-25 00:59:17,143 - D:\se\Se_Project\Util\log.py - log.py[:46] - 出现异常，异常信息为：<class 'selenium.common.exceptions.NoSuchElementException'>
ERROR - 2021-01-25 00:59:33,971 - D:\se\Se_Project\Util\log.py - log.py[:46] - 出现异常，异常信息为：<class 'selenium.common.exceptions.NoSuchElementException'>
ERROR - 2021-01-25 01:00:51,453 - D:\se\Se_Project\Util\log.py - log.py[:46] - 没有找到查询结果，--- try again ---
ERROR - 2021-01-25 01:01:55,445 - D:\se\Se_Project\Util\log.py - log.py[:46] - 没有找到查询结果，--- try again ---
ERROR - 2021-01-25 01:02:29,606 - D:\se\Se_Project\Util\log.py - log.py[:46] - Exception: Don't find Boe, please check config
ERROR - 2021-01-25 01:02:30,606 - D:\se\Se_Project\Util\log.py - log.py[:46] -  Don't find Boe, Try again
ERROR - 2021-01-25 01:03:41,186 - D:\se\Se_Project\Util\log.py - log.py[:46] - 没有找到查询结果，--- try again ---
ERROR - 2021-01-25 01:04:50,391 - D:\se\Se_Project\Util\log.py - log.py[:46] - 没有找到查询结果，--- try again ---
ERROR - 2021-01-25 01:05:21,613 - D:\se\Se_Project\Util\log.py - log.py[:46] - Exception: Don't find Boe, please check config
ERROR - 2021-01-25 01:05:22,614 - D:\se\Se_Project\Util\log.py - log.py[:46] -  Don't find Boe, Try again
ERROR - 2021-01-25 01:06:34,880 - D:\se\Se_Project\Util\log.py - log.py[:46] - 没有找到查询结果，--- try again ---
ERROR - 2021-01-25 01:07:34,756 - D:\se\Se_Project\Util\log.py - log.py[:46] - 没有找到查询结果，--- try again ---
ERROR - 2021-01-25 08:53:03,288 - D:\se\Se_Project\Util\log.py - log.py[:46] - Exception: Don't find Boe, please check config
ERROR - 2021-01-25 08:53:04,292 - D:\se\Se_Project\Util\log.py - log.py[:46] -  Don't find Boe, Try again
ERROR - 2021-01-25 08:53:04,378 - D:\se\Se_Project\Util\log.py - log.py[:46] - Exception: Don't find Boe, please check config
ERROR - 2021-01-25 08:53:04,388 - D:\se\Se_Project\Util\log.py - log.py[:46] - 出现异常，异常信息为：<class 'Exception'>
ERROR - 2021-01-25 08:55:10,454 - D:\se\Se_Project\Util\log.py - log.py[:46] - Exception: Don't find Boe, please check config
ERROR - 2021-01-25 08:55:11,455 - D:\se\Se_Project\Util\log.py - log.py[:46] -  Don't find Boe, Try again
ERROR - 2021-01-25 08:55:11,528 - D:\se\Se_Project\Util\log.py - log.py[:46] - Exception: Don't find Boe, please check config
ERROR - 2021-01-25 08:55:11,529 - D:\se\Se_Project\Util\log.py - log.py[:46] - 出现异常，异常信息为：<class 'Exception'>
ERROR - 2021-01-25 09:00:27,136 - D:\se\Se_Project\Util\log.py - log.py[:46] - 没有找到查询结果，--- try again ---
ERROR - 2021-01-25 09:01:01,713 - D:\se\Se_Project\Util\log.py - log.py[:46] - 没有找到查询结果，--- try again ---
ERROR - 2021-01-25 09:11:32,953 - D:\se\Se_Project\Util\log.py - log.py[:46] - 没有找到查询结果，--- try again ---
ERROR - 2021-01-25 09:11:48,926 - D:\se\Se_Project\Util\log.py - log.py[:46] - 没有找到查询结果，--- try again ---
ERROR - 2021-01-25 11:00:14,082 - D:\se\Se_Project\Util\log.py - log.py[:46] - Exception: Don't find Boe, please check config
ERROR - 2021-01-25 11:00:15,083 - D:\se\Se_Project\Util\log.py - log.py[:46] -  Don't find Boe, Try again
ERROR - 2021-01-25 11:00:15,197 - D:\se\Se_Project\Util\log.py - log.py[:46] - Exception: Don't find Boe, please check config
ERROR - 2021-01-25 11:00:15,198 - D:\se\Se_Project\Util\log.py - log.py[:46] - 出现异常，异常信息为：<class 'Exception'>
ERROR - 2021-01-25 11:02:20,158 - D:\se\Se_Project\Util\log.py - log.py[:46] - Exception: Don't find Boe, please check config
ERROR - 2021-01-25 11:02:21,159 - D:\se\Se_Project\Util\log.py - log.py[:46] -  Don't find Boe, Try again
ERROR - 2021-01-25 11:02:21,243 - D:\se\Se_Project\Util\log.py - log.py[:46] - Exception: Don't find Boe, please check config
ERROR - 2021-01-25 11:02:21,244 - D:\se\Se_Project\Util\log.py - log.py[:46] - 出现异常，异常信息为：<class 'Exception'>
ERROR - 2021-01-25 11:03:33,337 - D:\se\Se_Project\Util\log.py - log.py[:46] - Exception: Don't find Boe, please check config
ERROR - 2021-01-25 11:03:34,338 - D:\se\Se_Project\Util\log.py - log.py[:46] -  Don't find Boe, Try again
ERROR - 2021-01-25 11:03:34,429 - D:\se\Se_Project\Util\log.py - log.py[:46] - Exception: Don't find Boe, please check config
ERROR - 2021-01-25 11:03:34,430 - D:\se\Se_Project\Util\log.py - log.py[:46] - 出现异常，异常信息为：<class 'Exception'>
ERROR - 2021-01-25 11:05:06,558 - D:\se\Se_Project\Util\log.py - log.py[:46] - Exception: Don't find Boe, please check config
ERROR - 2021-01-25 11:05:07,559 - D:\se\Se_Project\Util\log.py - log.py[:46] -  Don't find Boe, Try again
ERROR - 2021-01-25 11:05:07,715 - D:\se\Se_Project\Util\log.py - log.py[:46] - Exception: Don't find Boe, please check config
ERROR - 2021-01-25 11:05:07,716 - D:\se\Se_Project\Util\log.py - log.py[:46] - 出现异常，异常信息为：<class 'Exception'>
ERROR - 2021-01-25 11:05:18,481 - D:\se\Se_Project\Util\log.py - log.py[:46] - 出现异常，异常信息为：<class 'urllib3.exceptions.MaxRetryError'>
ERROR - 2021-01-25 11:08:21,787 - D:\se\Se_Project\Util\log.py - log.py[:46] - Exception: Don't find Boe, please check config
ERROR - 2021-01-25 11:08:22,788 - D:\se\Se_Project\Util\log.py - log.py[:46] -  Don't find Boe, Try again
ERROR - 2021-01-25 11:08:22,959 - D:\se\Se_Project\Util\log.py - log.py[:46] - Exception: Don't find Boe, please check config
ERROR - 2021-01-25 11:08:22,961 - D:\se\Se_Project\Util\log.py - log.py[:46] - 出现异常，异常信息为：<class 'Exception'>
ERROR - 2021-01-25 11:08:24,656 - D:\se\Se_Project\Util\log.py - log.py[:46] - 出现异常，异常信息为：<class 'selenium.common.exceptions.ElementClickInterceptedException'>
ERROR - 2021-01-25 11:10:33,101 - D:\se\Se_Project\Util\log.py - log.py[:46] - Exception: Don't find Boe, please check config
ERROR - 2021-01-25 11:10:34,101 - D:\se\Se_Project\Util\log.py - log.py[:46] -  Don't find Boe, Try again
ERROR - 2021-01-25 11:10:34,267 - D:\se\Se_Project\Util\log.py - log.py[:46] - Exception: Don't find Boe, please check config
ERROR - 2021-01-25 11:10:34,268 - D:\se\Se_Project\Util\log.py - log.py[:46] - 出现异常，异常信息为：<class 'Exception'>
ERROR - 2021-01-25 11:12:04,526 - D:\se\Se_Project\Util\log.py - log.py[:46] - 没有找到查询结果，--- try again ---
ERROR - 2021-01-25 11:12:19,166 - D:\se\Se_Project\Util\log.py - log.py[:46] - 没有找到查询结果，--- try again ---
ERROR - 2021-01-25 11:17:06,449 - D:\se\Se_Project\Util\log.py - log.py[:46] - 没有找到查询结果，--- try again ---
ERROR - 2021-01-25 11:23:46,808 - D:\se\Se_Project\Util\log.py - log.py[:46] - 出现异常，异常信息为：<class 'selenium.common.exceptions.ElementClickInterceptedException'>
ERROR - 2021-01-25 11:26:14,200 - D:\se\Se_Project\Util\log.py - log.py[:46] - 没有找到查询结果，--- try again ---
ERROR - 2021-01-25 11:26:16,934 - D:\se\Se_Project\Util\log.py - log.py[:46] - 没有找到查询结果，--- try again ---
ERROR - 2021-01-25 11:26:34,300 - D:\se\Se_Project\Util\log.py - log.py[:46] - 没有找到查询结果，--- try again ---
ERROR - 2021-01-25 11:26:37,691 - D:\se\Se_Project\Util\log.py - log.py[:46] - 没有找到查询结果，--- try again ---
ERROR - 2021-01-25 11:36:58,032 - D:\se\Se_Project\Util\log.py - log.py[:46] - 没有找到查询结果，--- try again ---
ERROR - 2021-01-25 11:40:41,624 - D:\se\Se_Project\Util\log.py - log.py[:46] - 没有找到查询结果，--- try again ---
ERROR - 2021-01-25 11:40:49,359 - D:\se\Se_Project\Util\log.py - log.py[:46] - 没有找到查询结果，--- try again ---
ERROR - 2021-01-25 11:40:51,808 - D:\se\Se_Project\Util\log.py - log.py[:46] - 没有找到查询结果，--- try again ---
ERROR - 2021-01-25 11:41:53,314 - D:\se\Se_Project\Util\log.py - log.py[:46] - 没有找到查询结果，--- try again ---
ERROR - 2021-01-25 11:46:23,582 - D:\se\Se_Project\Util\log.py - log.py[:46] - 出现异常，异常信息为：<class 'selenium.common.exceptions.NoSuchElementException'>
ERROR - 2021-01-25 11:47:49,782 - D:\se\Se_Project\Util\log.py - log.py[:46] - 没有找到查询结果，--- try again ---
ERROR - 2021-01-25 11:48:51,064 - D:\se\Se_Project\Util\log.py - log.py[:46] - 没有找到查询结果，--- try again ---
ERROR - 2021-01-27 14:44:35,895 - D:\se\Se_Project\Util\log.py - log.py[:47] - 出现异常，异常信息为：<class 'selenium.common.exceptions.TimeoutException'>
ERROR - 2021-01-27 14:46:27,740 - D:\se\Se_Project\Util\log.py - log.py[:47] - 出现异常，异常信息为：<class 'selenium.common.exceptions.TimeoutException'>
ERROR - 2021-01-27 14:51:22,588 - D:\se\Se_Project\Util\log.py - log.py[:47] - Exception: Don't find Boe, please check config
ERROR - 2021-01-27 14:51:23,590 - D:\se\Se_Project\Util\log.py - log.py[:47] -  Don't find Boe, Try again
ERROR - 2021-01-27 14:52:08,268 - D:\se\Se_Project\Util\log.py - log.py[:47] - 没有找到查询结果，--- try again ---
ERROR - 2021-01-27 14:52:23,107 - D:\se\Se_Project\Util\log.py - log.py[:47] - 没有找到查询结果，--- try again ---
ERROR - 2021-01-27 14:52:30,522 - D:\se\Se_Project\Util\log.py - log.py[:47] - 出现异常，异常信息为：<class 'selenium.common.exceptions.TimeoutException'>
ERROR - 2021-01-27 14:53:51,586 - D:\se\Se_Project\Util\log.py - log.py[:47] - 没有找到查询结果，--- try again ---
ERROR - 2021-01-27 14:54:23,758 - D:\se\Se_Project\Util\log.py - log.py[:47] - 出现异常，异常信息为：<class 'selenium.common.exceptions.TimeoutException'>
ERROR - 2021-01-27 14:55:45,499 - D:\se\Se_Project\Util\log.py - log.py[:47] - 没有找到查询结果，--- try again ---
ERROR - 2021-01-27 14:56:46,227 - D:\se\Se_Project\Util\log.py - log.py[:47] - 没有找到查询结果，--- try again ---
ERROR - 2021-01-27 14:57:02,566 - D:\se\Se_Project\Util\log.py - log.py[:47] - 出现异常，异常信息为：<class 'selenium.common.exceptions.TimeoutException'>
ERROR - 2021-01-28 11:11:10,361 - D:\se\Se_Project\Util\log.py - log.py[:54] - Exception: Don't find Boe, please check config
ERROR - 2021-01-28 11:11:11,363 - D:\se\Se_Project\Util\log.py - log.py[:54] -  Don't find Boe, Try again
ERROR - 2021-01-28 11:11:26,151 - D:\se\Se_Project\Util\log.py - log.py[:54] - 出现异常，异常信息为：<class 'selenium.common.exceptions.TimeoutException'>
ERROR - 2021-01-28 11:13:18,895 - D:\se\Se_Project\Util\log.py - log.py[:54] - 没有找到查询结果，--- try again ---
ERROR - 2021-01-28 11:13:28,675 - D:\se\Se_Project\Util\log.py - log.py[:54] - 没有找到查询结果，--- try again ---
ERROR - 2021-01-28 11:14:05,930 - D:\se\Se_Project\Util\log.py - log.py[:54] - Exception: Don't find Boe, please check config
ERROR - 2021-01-28 11:14:06,931 - D:\se\Se_Project\Util\log.py - log.py[:54] -  Don't find Boe, Try again
ERROR - 2021-01-28 11:14:54,534 - D:\se\Se_Project\Util\log.py - log.py[:54] - 没有找到查询结果，--- try again ---
ERROR - 2021-01-28 11:15:08,361 - D:\se\Se_Project\Util\log.py - log.py[:54] - 没有找到查询结果，--- try again ---
ERROR - 2021-01-28 17:00:54,563 - D:\se\Se_Project\Util\log.py - log.py[:54] - 没有找到查询结果，--- try again ---
ERROR - 2021-01-28 17:00:57,555 - D:\se\Se_Project\Util\log.py - log.py[:54] - 没有找到查询结果，--- try again ---
ERROR - 2021-01-28 17:01:57,771 - D:\se\Se_Project\Util\log.py - log.py[:54] - 没有找到查询结果，--- try again ---
ERROR - 2021-01-29 14:30:17,889 - D:\se\Se_Project\Util\log.py - log.py[:54] - 没有找到查询结果，--- try again ---
ERROR - 2021-01-29 14:32:23,133 - D:\se\Se_Project\Util\log.py - log.py[:54] - 没有找到查询结果，--- try again ---
ERROR - 2021-01-29 14:47:01,968 - D:\se\Se_Project\Util\log.py - log.py[:54] - 没有找到查询结果，--- try again ---
ERROR - 2021-01-29 14:49:28,651 - D:\se\Se_Project\Util\log.py - log.py[:54] - 没有找到查询结果，--- try again ---
ERROR - 2021-01-29 14:49:44,085 - D:\se\Se_Project\Util\log.py - log.py[:54] - 没有找到查询结果，--- try again ---
ERROR - 2021-01-29 14:50:19,875 - D:\se\Se_Project\Util\log.py - log.py[:54] - 没有找到查询结果，--- try again ---
ERROR - 2021-01-29 14:50:36,575 - D:\se\Se_Project\Util\log.py - log.py[:54] - 没有找到查询结果，--- try again ---
ERROR - 2021-01-29 14:57:09,327 - D:\se\Se_Project\Util\log.py - log.py[:54] - 没有找到查询结果，--- try again ---
ERROR - 2021-01-29 15:08:52,106 - D:\se\Se_Project\Util\log.py - log.py[:54] - 没有找到查询结果，--- try again ---
ERROR - 2021-01-29 15:39:36,143 - D:\se\Se_Project\Util\log.py - log.py[:54] - 没有找到查询结果，--- try again ---
ERROR - 2021-01-29 15:40:32,693 - D:\se\Se_Project\Util\log.py - log.py[:54] - 没有找到查询结果，--- try again ---
ERROR - 2021-01-29 15:43:40,057 - D:\se\Se_Project\Util\log.py - log.py[:54] - 没有找到查询结果，--- try again ---
ERROR - 2021-01-29 15:58:32,847 - D:\se\Se_Project\Util\log.py - log.py[:54] - 没有找到查询结果，--- try again ---
ERROR - 2021-01-29 16:01:00,030 - D:\se\Se_Project\Util\log.py - log.py[:54] - 没有找到查询结果，--- try again ---
ERROR - 2021-01-29 16:06:32,952 - D:\se\Se_Project\Util\log.py - log.py[:54] - 没有找到查询结果，--- try again ---
ERROR - 2021-01-29 16:18:20,680 - D:\se\Se_Project\Util\log.py - log.py[:54] - 没有找到查询结果，--- try again ---
ERROR - 2021-01-29 16:22:23,656 - D:\se\Se_Project\Util\log.py - log.py[:54] - 没有找到查询结果，--- try again ---
ERROR - 2021-01-29 16:22:30,792 - D:\se\Se_Project\Util\log.py - log.py[:54] - 没有找到查询结果，--- try again ---
ERROR - 2021-01-29 16:23:21,787 - D:\se\Se_Project\Util\log.py - log.py[:54] - 没有找到查询结果，--- try again ---
ERROR - 2021-01-29 16:30:32,559 - D:\se\Se_Project\Util\log.py - log.py[:54] - 没有找到查询结果，--- try again ---
ERROR - 2021-01-29 16:31:19,021 - D:\se\Se_Project\Util\log.py - log.py[:54] - 没有找到查询结果，--- try again ---
ERROR - 2021-01-29 16:40:23,783 - D:\se\Se_Project\Util\log.py - log.py[:54] - 没有找到查询结果，--- try again ---
ERROR - 2021-01-29 16:42:20,828 - D:\se\Se_Project\Util\log.py - log.py[:54] - 没有找到查询结果，--- try again ---
ERROR - 2021-01-29 16:47:41,665 - D:\se\Se_Project\Util\log.py - log.py[:54] - 没有找到查询结果，--- try again ---
ERROR - 2021-01-29 16:49:13,083 - D:\se\Se_Project\Util\log.py - log.py[:54] - 没有找到查询结果，--- try again ---
ERROR - 2021-01-29 16:50:00,456 - D:\se\Se_Project\Util\log.py - log.py[:54] - 没有找到查询结果，--- try again ---
ERROR - 2021-01-29 16:50:40,046 - D:\se\Se_Project\Util\log.py - log.py[:54] - 没有找到查询结果，--- try again ---
ERROR - 2021-01-29 16:59:07,700 - D:\se\Se_Project\Util\log.py - log.py[:54] - 没有找到查询结果，--- try again ---
ERROR - 2021-01-29 17:00:08,260 - D:\se\Se_Project\Util\log.py - log.py[:54] - 没有找到查询结果，--- try again ---
ERROR - 2021-01-29 17:07:34,248 - D:\se\Se_Project\Util\log.py - log.py[:54] - 没有找到查询结果，--- try again ---
ERROR - 2021-01-29 17:08:36,149 - D:\se\Se_Project\Util\log.py - log.py[:54] - 没有找到查询结果，--- try again ---
ERROR - 2021-02-03 09:18:37,961 - D:\se\Se_Project\Util\log.py - log.py[:54] - 没有找到查询结果，--- try again ---
ERROR - 2021-02-03 09:21:45,203 - D:\se\Se_Project\Util\log.py - log.py[:54] - 没有找到查询结果，--- try again ---
ERROR - 2021-02-03 11:33:19,568 - D:\se\Se_Project\Util\log.py - log.py[:54] - 没有找到查询结果，--- try again ---
ERROR - 2021-02-03 11:33:26,980 - D:\se\Se_Project\Util\log.py - log.py[:54] - 没有找到查询结果，--- try again ---
ERROR - 2021-02-03 11:34:27,538 - D:\se\Se_Project\Util\log.py - log.py[:54] - 没有找到查询结果，--- try again ---
ERROR - 2021-02-03 11:47:48,063 - D:\se\Se_Project\Util\log.py - log.py[:54] - 没有找到查询结果，--- try again ---
ERROR - 2021-02-03 11:49:14,996 - D:\se\Se_Project\Util\log.py - log.py[:54] - 没有找到查询结果，--- try again ---
ERROR - 2021-02-03 11:50:17,380 - D:\se\Se_Project\Util\log.py - log.py[:54] - 没有找到查询结果，--- try again ---
ERROR - 2021-02-03 11:52:22,413 - D:\se\Se_Project\Util\log.py - log.py[:54] - 没有找到查询结果，--- try again ---
ERROR - 2021-02-03 11:53:21,616 - D:\se\Se_Project\Util\log.py - log.py[:54] - 没有找到查询结果，--- try again ---
ERROR - 2021-02-03 14:43:18,987 - D:\se\Se_Project\Util\log.py - log.py[:54] - 没有找到查询结果，--- try again ---
ERROR - 2021-02-03 14:44:08,019 - D:\se\Se_Project\Util\log.py - log.py[:54] - 没有找到查询结果，--- try again ---
