ERROR - 2020-10-28 16:13:32,813 - D:\csv\Se_Project\Testcases\loginPageTest\test_publciLoginPage.py - test_publciLoginPage.py[:35] - -------------------------------------------------
ERROR - 2020-10-28 16:13:34,092 - D:\csv\Se_Project\Testcases\loginPageTest\test_publciLoginPage.py - test_publciLoginPage.py[:35] - -------------------------------------------------
ERROR - 2020-10-28 16:13:35,175 - D:\csv\Se_Project\Testcases\loginPageTest\test_publciLoginPage.py - test_publciLoginPage.py[:35] - -------------------------------------------------
ERROR - 2020-10-28 16:13:36,200 - D:\csv\Se_Project\Testcases\loginPageTest\test_publciLoginPage.py - test_publciLoginPage.py[:35] - -------------------------------------------------
ERROR - 2020-10-28 16:13:36,998 - D:\csv\Se_Project\Testcases\loginPageTest\test_publciLoginPage.py - test_publciLoginPage.py[:35] - -------------------------------------------------
ERROR - 2020-10-28 16:14:52,391 - D:\csv\Se_Project\Testcases\loginPageTest\test_publciLoginPage.py - test_publciLoginPage.py[:35] - -------------------------------------------------
ERROR - 2020-10-28 16:14:53,650 - D:\csv\Se_Project\Testcases\loginPageTest\test_publciLoginPage.py - test_publciLoginPage.py[:35] - -------------------------------------------------
ERROR - 2020-10-28 16:14:54,760 - D:\csv\Se_Project\Testcases\loginPageTest\test_publciLoginPage.py - test_publciLoginPage.py[:35] - -------------------------------------------------
ERROR - 2020-10-28 16:14:55,812 - D:\csv\Se_Project\Testcases\loginPageTest\test_publciLoginPage.py - test_publciLoginPage.py[:35] - -------------------------------------------------
ERROR - 2020-10-28 16:14:57,139 - D:\csv\Se_Project\Testcases\loginPageTest\test_publciLoginPage.py - test_publciLoginPage.py[:35] - -------------------------------------------------
ERROR - 2020-10-28 16:19:45,130 - D:\csv\Se_Project\Testcases\loginPageTest\test_publciLoginPage.py - test_publciLoginPage.py[:36] - -------------------------------------------------
ERROR - 2020-10-28 16:19:46,344 - D:\csv\Se_Project\Testcases\loginPageTest\test_publciLoginPage.py - test_publciLoginPage.py[:36] - -------------------------------------------------
ERROR - 2020-10-28 16:19:47,438 - D:\csv\Se_Project\Testcases\loginPageTest\test_publciLoginPage.py - test_publciLoginPage.py[:36] - -------------------------------------------------
ERROR - 2020-10-28 16:19:48,432 - D:\csv\Se_Project\Testcases\loginPageTest\test_publciLoginPage.py - test_publciLoginPage.py[:36] - -------------------------------------------------
ERROR - 2020-10-28 16:19:49,278 - D:\csv\Se_Project\Testcases\loginPageTest\test_publciLoginPage.py - test_publciLoginPage.py[:36] - -------------------------------------------------
ERROR - 2020-10-28 18:18:03,870 - D:\csv\Se_Project\Testcases\loginPageTest\test_publciLoginPage.py - test_publciLoginPage.py[:36] - -------------------------------------------------
ERROR - 2020-10-28 18:18:05,092 - D:\csv\Se_Project\Testcases\loginPageTest\test_publciLoginPage.py - test_publciLoginPage.py[:36] - -------------------------------------------------
ERROR - 2020-10-28 18:18:06,180 - D:\csv\Se_Project\Testcases\loginPageTest\test_publciLoginPage.py - test_publciLoginPage.py[:36] - -------------------------------------------------
ERROR - 2020-10-28 18:18:07,170 - D:\csv\Se_Project\Testcases\loginPageTest\test_publciLoginPage.py - test_publciLoginPage.py[:36] - -------------------------------------------------
ERROR - 2020-10-28 18:18:09,319 - D:\csv\Se_Project\Testcases\loginPageTest\test_publciLoginPage.py - test_publciLoginPage.py[:36] - -------------------------------------------------
ERROR - 2020-10-28 18:19:00,439 - D:\csv\Se_Project\Testcases\loginPageTest\test_publciLoginPage.py - test_publciLoginPage.py[:36] - -------------------------------------------------
ERROR - 2020-10-28 18:19:01,245 - D:\csv\Se_Project\Testcases\loginPageTest\test_publciLoginPage.py - test_publciLoginPage.py[:36] - -------------------------------------------------
ERROR - 2020-10-28 18:19:02,404 - D:\csv\Se_Project\Testcases\loginPageTest\test_publciLoginPage.py - test_publciLoginPage.py[:36] - -------------------------------------------------
ERROR - 2020-10-28 18:19:03,411 - D:\csv\Se_Project\Testcases\loginPageTest\test_publciLoginPage.py - test_publciLoginPage.py[:36] - -------------------------------------------------
ERROR - 2020-10-28 18:19:04,273 - D:\csv\Se_Project\Testcases\loginPageTest\test_publciLoginPage.py - test_publciLoginPage.py[:36] - -------------------------------------------------
ERROR - 2020-10-28 23:16:24,377 - D:\Pycharm\AutoProject\SeleniumAutoProject\Testcases\loginPageTest\test_publciLoginPage.py - test_publciLoginPage.py[:36] - -------------------------------------------------
ERROR - 2020-10-28 23:16:25,479 - D:\Pycharm\AutoProject\SeleniumAutoProject\Testcases\loginPageTest\test_publciLoginPage.py - test_publciLoginPage.py[:36] - -------------------------------------------------
ERROR - 2020-10-28 23:16:26,329 - D:\Pycharm\AutoProject\SeleniumAutoProject\Testcases\loginPageTest\test_publciLoginPage.py - test_publciLoginPage.py[:36] - -------------------------------------------------
ERROR - 2020-10-28 23:16:28,802 - D:\Pycharm\AutoProject\SeleniumAutoProject\Testcases\loginPageTest\test_publciLoginPage.py - test_publciLoginPage.py[:36] - -------------------------------------------------
ERROR - 2020-10-28 23:16:30,555 - D:\Pycharm\AutoProject\SeleniumAutoProject\Testcases\loginPageTest\test_publciLoginPage.py - test_publciLoginPage.py[:36] - -------------------------------------------------
ERROR - 2020-10-28 23:24:30,104 - D:\Pycharm\AutoProject\SeleniumAutoProject\Testcases\loginPageTest\test_publciLoginPage.py - test_publciLoginPage.py[:36] - -------------------------------------------------
ERROR - 2020-10-28 23:24:30,825 - D:\Pycharm\AutoProject\SeleniumAutoProject\Testcases\loginPageTest\test_publciLoginPage.py - test_publciLoginPage.py[:36] - -------------------------------------------------
ERROR - 2020-10-28 23:24:31,911 - D:\Pycharm\AutoProject\SeleniumAutoProject\Testcases\loginPageTest\test_publciLoginPage.py - test_publciLoginPage.py[:36] - -------------------------------------------------
ERROR - 2020-10-28 23:24:32,966 - D:\Pycharm\AutoProject\SeleniumAutoProject\Testcases\loginPageTest\test_publciLoginPage.py - test_publciLoginPage.py[:36] - -------------------------------------------------
ERROR - 2020-10-28 23:24:33,885 - D:\Pycharm\AutoProject\SeleniumAutoProject\Testcases\loginPageTest\test_publciLoginPage.py - test_publciLoginPage.py[:36] - -------------------------------------------------
ERROR - 2020-10-28 23:25:13,115 - D:\Pycharm\AutoProject\SeleniumAutoProject\Testcases\loginPageTest\test_publciLoginPage.py - test_publciLoginPage.py[:36] - -------------------------------------------------
ERROR - 2020-10-28 23:25:15,486 - D:\Pycharm\AutoProject\SeleniumAutoProject\Testcases\loginPageTest\test_publciLoginPage.py - test_publciLoginPage.py[:36] - -------------------------------------------------
ERROR - 2020-10-28 23:25:16,676 - D:\Pycharm\AutoProject\SeleniumAutoProject\Testcases\loginPageTest\test_publciLoginPage.py - test_publciLoginPage.py[:36] - -------------------------------------------------
ERROR - 2020-10-28 23:25:17,917 - D:\Pycharm\AutoProject\SeleniumAutoProject\Testcases\loginPageTest\test_publciLoginPage.py - test_publciLoginPage.py[:36] - -------------------------------------------------
ERROR - 2020-10-28 23:25:20,064 - D:\Pycharm\AutoProject\SeleniumAutoProject\Testcases\loginPageTest\test_publciLoginPage.py - test_publciLoginPage.py[:36] - -------------------------------------------------
ERROR - 2020-10-28 23:26:45,347 - D:\Pycharm\AutoProject\SeleniumAutoProject\Testcases\loginPageTest\test_publciLoginPage.py - test_publciLoginPage.py[:36] - -------------------------------------------------
ERROR - 2020-10-28 23:26:47,711 - D:\Pycharm\AutoProject\SeleniumAutoProject\Testcases\loginPageTest\test_publciLoginPage.py - test_publciLoginPage.py[:36] - -------------------------------------------------
ERROR - 2020-10-28 23:26:48,938 - D:\Pycharm\AutoProject\SeleniumAutoProject\Testcases\loginPageTest\test_publciLoginPage.py - test_publciLoginPage.py[:36] - -------------------------------------------------
ERROR - 2020-10-28 23:26:50,045 - D:\Pycharm\AutoProject\SeleniumAutoProject\Testcases\loginPageTest\test_publciLoginPage.py - test_publciLoginPage.py[:36] - -------------------------------------------------
ERROR - 2020-10-28 23:26:52,221 - D:\Pycharm\AutoProject\SeleniumAutoProject\Testcases\loginPageTest\test_publciLoginPage.py - test_publciLoginPage.py[:36] - -------------------------------------------------
ERROR - 2020-10-28 23:27:47,853 - D:\Pycharm\AutoProject\SeleniumAutoProject\Testcases\loginPageTest\test_publciLoginPage.py - test_publciLoginPage.py[:36] - -------------------------------------------------
ERROR - 2020-10-28 23:27:50,190 - D:\Pycharm\AutoProject\SeleniumAutoProject\Testcases\loginPageTest\test_publciLoginPage.py - test_publciLoginPage.py[:36] - -------------------------------------------------
ERROR - 2020-10-28 23:27:51,238 - D:\Pycharm\AutoProject\SeleniumAutoProject\Testcases\loginPageTest\test_publciLoginPage.py - test_publciLoginPage.py[:36] - -------------------------------------------------
ERROR - 2020-10-28 23:27:52,396 - D:\Pycharm\AutoProject\SeleniumAutoProject\Testcases\loginPageTest\test_publciLoginPage.py - test_publciLoginPage.py[:36] - -------------------------------------------------
ERROR - 2020-10-28 23:27:54,548 - D:\Pycharm\AutoProject\SeleniumAutoProject\Testcases\loginPageTest\test_publciLoginPage.py - test_publciLoginPage.py[:36] - -------------------------------------------------
ERROR - 2020-10-28 23:29:09,456 - D:\Pycharm\AutoProject\SeleniumAutoProject\Testcases\loginPageTest\test_publciLoginPage.py - test_publciLoginPage.py[:36] - -------------------------------------------------
ERROR - 2020-10-28 23:29:13,252 - D:\Pycharm\AutoProject\SeleniumAutoProject\Testcases\loginPageTest\test_publciLoginPage.py - test_publciLoginPage.py[:36] - -------------------------------------------------
ERROR - 2020-10-28 23:29:16,160 - D:\Pycharm\AutoProject\SeleniumAutoProject\Testcases\loginPageTest\test_publciLoginPage.py - test_publciLoginPage.py[:36] - -------------------------------------------------
ERROR - 2020-10-28 23:29:17,384 - D:\Pycharm\AutoProject\SeleniumAutoProject\Testcases\loginPageTest\test_publciLoginPage.py - test_publciLoginPage.py[:36] - -------------------------------------------------
ERROR - 2020-10-28 23:29:19,588 - D:\Pycharm\AutoProject\SeleniumAutoProject\Testcases\loginPageTest\test_publciLoginPage.py - test_publciLoginPage.py[:36] - -------------------------------------------------
ERROR - 2020-10-28 23:31:12,142 - D:\Pycharm\AutoProject\SeleniumAutoProject\Testcases\loginPageTest\test_publciLoginPage.py - test_publciLoginPage.py[:36] - -------------------------------------------------
ERROR - 2020-10-28 23:31:13,931 - D:\Pycharm\AutoProject\SeleniumAutoProject\Testcases\loginPageTest\test_publciLoginPage.py - test_publciLoginPage.py[:36] - -------------------------------------------------
ERROR - 2020-10-28 23:31:14,730 - D:\Pycharm\AutoProject\SeleniumAutoProject\Testcases\loginPageTest\test_publciLoginPage.py - test_publciLoginPage.py[:36] - -------------------------------------------------
ERROR - 2020-10-28 23:31:15,820 - D:\Pycharm\AutoProject\SeleniumAutoProject\Testcases\loginPageTest\test_publciLoginPage.py - test_publciLoginPage.py[:36] - -------------------------------------------------
ERROR - 2020-10-28 23:31:17,580 - D:\Pycharm\AutoProject\SeleniumAutoProject\Testcases\loginPageTest\test_publciLoginPage.py - test_publciLoginPage.py[:36] - -------------------------------------------------
ERROR - 2020-10-28 23:32:20,564 - D:\Pycharm\AutoProject\SeleniumAutoProject\Testcases\loginPageTest\test_publciLoginPage.py - test_publciLoginPage.py[:36] - -------------------------------------------------
ERROR - 2020-10-28 23:32:22,350 - D:\Pycharm\AutoProject\SeleniumAutoProject\Testcases\loginPageTest\test_publciLoginPage.py - test_publciLoginPage.py[:36] - -------------------------------------------------
ERROR - 2020-10-28 23:32:23,870 - D:\Pycharm\AutoProject\SeleniumAutoProject\Testcases\loginPageTest\test_publciLoginPage.py - test_publciLoginPage.py[:36] - -------------------------------------------------
ERROR - 2020-10-28 23:32:25,766 - D:\Pycharm\AutoProject\SeleniumAutoProject\Testcases\loginPageTest\test_publciLoginPage.py - test_publciLoginPage.py[:36] - -------------------------------------------------
ERROR - 2020-10-28 23:32:27,449 - D:\Pycharm\AutoProject\SeleniumAutoProject\Testcases\loginPageTest\test_publciLoginPage.py - test_publciLoginPage.py[:36] - -------------------------------------------------
ERROR - 2020-10-28 23:36:35,067 - D:\Pycharm\AutoProject\SeleniumAutoProject\Testcases\loginPageTest\test_publciLoginPage.py - test_publciLoginPage.py[:36] - -------------------------------------------------
ERROR - 2020-10-28 23:36:36,019 - D:\Pycharm\AutoProject\SeleniumAutoProject\Testcases\loginPageTest\test_publciLoginPage.py - test_publciLoginPage.py[:36] - -------------------------------------------------
ERROR - 2020-10-28 23:36:36,747 - D:\Pycharm\AutoProject\SeleniumAutoProject\Testcases\loginPageTest\test_publciLoginPage.py - test_publciLoginPage.py[:36] - -------------------------------------------------
ERROR - 2020-10-28 23:36:37,553 - D:\Pycharm\AutoProject\SeleniumAutoProject\Testcases\loginPageTest\test_publciLoginPage.py - test_publciLoginPage.py[:36] - -------------------------------------------------
ERROR - 2020-10-28 23:36:39,208 - D:\Pycharm\AutoProject\SeleniumAutoProject\Testcases\loginPageTest\test_publciLoginPage.py - test_publciLoginPage.py[:36] - -------------------------------------------------
ERROR - 2020-10-29 01:09:04,813 - D:\Pycharm\AutoProject\SeleniumAutoProject\Testcases\loginPageTest\test_publciLoginPage.py - test_publciLoginPage.py[:74] - <class 'selenium.common.exceptions.TimeoutException'>
ERROR - 2020-10-29 01:09:08,611 - D:\Pycharm\AutoProject\SeleniumAutoProject\Testcases\loginPageTest\test_publciLoginPage.py - test_publciLoginPage.py[:74] - <class 'selenium.common.exceptions.TimeoutException'>
ERROR - 2020-10-29 01:27:31,635 - D:\Pycharm\AutoProject\SeleniumAutoProject\Testcases\loginPageTest\test_publciLoginPage.py - test_publciLoginPage.py[:74] - <class 'selenium.common.exceptions.TimeoutException'>
ERROR - 2020-10-29 01:27:37,080 - D:\Pycharm\AutoProject\SeleniumAutoProject\Testcases\loginPageTest\test_publciLoginPage.py - test_publciLoginPage.py[:74] - <class 'selenium.common.exceptions.TimeoutException'>
ERROR - 2020-10-29 12:44:00,264 - D:\csv\Se_Project\Testcases\loginPageTest\test_publciLoginPage.py - test_publciLoginPage.py[:75] - 出现异常
ERROR - 2020-10-29 12:44:00,264 - D:\csv\Se_Project\Testcases\loginPageTest\test_publciLoginPage.py - test_publciLoginPage.py[:76] - <class 'selenium.common.exceptions.TimeoutException'>
ERROR - 2020-10-29 12:44:05,970 - D:\csv\Se_Project\Testcases\loginPageTest\test_publciLoginPage.py - test_publciLoginPage.py[:75] - 出现异常
ERROR - 2020-10-29 12:44:05,970 - D:\csv\Se_Project\Testcases\loginPageTest\test_publciLoginPage.py - test_publciLoginPage.py[:76] - <class 'selenium.common.exceptions.TimeoutException'>
ERROR - 2020-10-29 12:44:08,474 - D:\csv\Se_Project\Testcases\loginPageTest\test_publciLoginPage.py - test_publciLoginPage.py[:75] - 出现异常
ERROR - 2020-10-29 12:44:08,474 - D:\csv\Se_Project\Testcases\loginPageTest\test_publciLoginPage.py - test_publciLoginPage.py[:76] - <class 'selenium.common.exceptions.TimeoutException'>
ERROR - 2020-11-16 11:18:12,872 - D:\csv\Se_Project\Testcases\loginPageTest\test_publciLoginPage.py - test_publciLoginPage.py[:76] - 出现异常
ERROR - 2020-11-16 11:18:12,875 - D:\csv\Se_Project\Testcases\loginPageTest\test_publciLoginPage.py - test_publciLoginPage.py[:77] - <class 'selenium.common.exceptions.TimeoutException'>
ERROR - 2021-01-06 13:33:11,650 - D:\se\Se_Project\Testcases\loginPageTest\test_publciLoginPage.py - test_publciLoginPage.py[:80] - 出现异常
ERROR - 2021-01-06 13:33:11,650 - D:\se\Se_Project\Testcases\loginPageTest\test_publciLoginPage.py - test_publciLoginPage.py[:81] - <class 'selenium.common.exceptions.TimeoutException'>
ERROR - 2021-01-06 14:17:48,620 - D:\se\Se_Project\Testcases\loginPageTest\test_publciLoginPage.py - test_publciLoginPage.py[:79] - 出现异常
ERROR - 2021-01-06 14:17:48,620 - D:\se\Se_Project\Testcases\loginPageTest\test_publciLoginPage.py - test_publciLoginPage.py[:80] - <class 'selenium.common.exceptions.TimeoutException'>
ERROR - 2021-01-06 20:18:57,629 - D:\se\Se_Project\Testcases\loginPageTest\test_publciLoginPage.py - test_publciLoginPage.py[:79] - 出现异常
ERROR - 2021-01-06 20:18:57,629 - D:\se\Se_Project\Testcases\loginPageTest\test_publciLoginPage.py - test_publciLoginPage.py[:80] - <class 'selenium.common.exceptions.TimeoutException'>
ERROR - 2021-01-06 20:18:59,909 - D:\se\Se_Project\Testcases\loginPageTest\test_publciLoginPage.py - test_publciLoginPage.py[:79] - 出现异常
ERROR - 2021-01-06 20:18:59,909 - D:\se\Se_Project\Testcases\loginPageTest\test_publciLoginPage.py - test_publciLoginPage.py[:80] - <class 'selenium.common.exceptions.TimeoutException'>
ERROR - 2021-01-07 09:17:02,923 - D:\se\Se_Project\Testcases\loginPageTest\test_publciLoginPage.py - test_publciLoginPage.py[:79] - 出现异常
ERROR - 2021-01-07 09:17:02,924 - D:\se\Se_Project\Testcases\loginPageTest\test_publciLoginPage.py - test_publciLoginPage.py[:80] - <class 'AttributeError'>
ERROR - 2021-01-07 09:17:04,055 - D:\se\Se_Project\Testcases\loginPageTest\test_publciLoginPage.py - test_publciLoginPage.py[:79] - 出现异常
ERROR - 2021-01-07 09:17:04,056 - D:\se\Se_Project\Testcases\loginPageTest\test_publciLoginPage.py - test_publciLoginPage.py[:80] - <class 'AttributeError'>
ERROR - 2021-01-07 09:17:05,041 - D:\se\Se_Project\Testcases\loginPageTest\test_publciLoginPage.py - test_publciLoginPage.py[:79] - 出现异常
ERROR - 2021-01-07 09:17:05,041 - D:\se\Se_Project\Testcases\loginPageTest\test_publciLoginPage.py - test_publciLoginPage.py[:80] - <class 'AttributeError'>
ERROR - 2021-01-07 09:17:06,101 - D:\se\Se_Project\Testcases\loginPageTest\test_publciLoginPage.py - test_publciLoginPage.py[:79] - 出现异常
ERROR - 2021-01-07 09:17:06,101 - D:\se\Se_Project\Testcases\loginPageTest\test_publciLoginPage.py - test_publciLoginPage.py[:80] - <class 'AttributeError'>
ERROR - 2021-01-07 09:17:07,120 - D:\se\Se_Project\Testcases\loginPageTest\test_publciLoginPage.py - test_publciLoginPage.py[:79] - 出现异常
ERROR - 2021-01-07 09:17:07,120 - D:\se\Se_Project\Testcases\loginPageTest\test_publciLoginPage.py - test_publciLoginPage.py[:80] - <class 'AttributeError'>
ERROR - 2021-01-07 09:20:12,063 - D:\se\Se_Project\Testcases\loginPageTest\test_publciLoginPage.py - test_publciLoginPage.py[:79] - 出现异常
ERROR - 2021-01-07 09:20:12,064 - D:\se\Se_Project\Testcases\loginPageTest\test_publciLoginPage.py - test_publciLoginPage.py[:80] - <class 'AssertionError'>
ERROR - 2021-01-07 09:20:15,736 - D:\se\Se_Project\Testcases\loginPageTest\test_publciLoginPage.py - test_publciLoginPage.py[:79] - 出现异常
ERROR - 2021-01-07 09:20:15,736 - D:\se\Se_Project\Testcases\loginPageTest\test_publciLoginPage.py - test_publciLoginPage.py[:80] - <class 'selenium.common.exceptions.TimeoutException'>
ERROR - 2021-01-07 09:20:17,608 - D:\se\Se_Project\Testcases\loginPageTest\test_publciLoginPage.py - test_publciLoginPage.py[:79] - 出现异常
ERROR - 2021-01-07 09:20:17,609 - D:\se\Se_Project\Testcases\loginPageTest\test_publciLoginPage.py - test_publciLoginPage.py[:80] - <class 'AssertionError'>
ERROR - 2021-01-07 09:20:20,103 - D:\se\Se_Project\Testcases\loginPageTest\test_publciLoginPage.py - test_publciLoginPage.py[:79] - 出现异常
ERROR - 2021-01-07 09:20:20,103 - D:\se\Se_Project\Testcases\loginPageTest\test_publciLoginPage.py - test_publciLoginPage.py[:80] - <class 'selenium.common.exceptions.TimeoutException'>
ERROR - 2021-01-07 09:34:32,803 - D:/se/Se_Project/Util/log.py - log.py[:44] - 测试error
CRITICAL - 2021-01-07 09:34:32,803 - D:/se/Se_Project/Util/log.py - log.py[:47] - 测试critical
ERROR - 2021-01-07 09:36:40,131 - D:/se/Se_Project/Util/log.py - log.py[:45] - 测试error
CRITICAL - 2021-01-07 09:36:40,131 - D:/se/Se_Project/Util/log.py - log.py[:48] - 测试critical
ERROR - 2021-01-07 10:06:43,762 - D:\se\Se_Project\Testcases\loginPageTest\test_publciLoginPage.py - test_publciLoginPage.py[:83] - 出现异常
ERROR - 2021-01-07 10:06:43,763 - D:\se\Se_Project\Testcases\loginPageTest\test_publciLoginPage.py - test_publciLoginPage.py[:84] - <class 'AssertionError'>
ERROR - 2021-01-07 10:06:49,560 - D:\se\Se_Project\Testcases\loginPageTest\test_publciLoginPage.py - test_publciLoginPage.py[:83] - 出现异常
ERROR - 2021-01-07 10:06:49,560 - D:\se\Se_Project\Testcases\loginPageTest\test_publciLoginPage.py - test_publciLoginPage.py[:84] - <class 'selenium.common.exceptions.TimeoutException'>
ERROR - 2021-01-07 10:06:52,170 - D:\se\Se_Project\Testcases\loginPageTest\test_publciLoginPage.py - test_publciLoginPage.py[:83] - 出现异常
ERROR - 2021-01-07 10:06:52,170 - D:\se\Se_Project\Testcases\loginPageTest\test_publciLoginPage.py - test_publciLoginPage.py[:84] - <class 'selenium.common.exceptions.TimeoutException'>
ERROR - 2021-01-07 10:21:33,209 - D:\se\Se_Project\Util\log.py - log.py[:46] - 出现异常
ERROR - 2021-01-07 10:21:33,209 - D:\se\Se_Project\Util\log.py - log.py[:46] - <class 'selenium.common.exceptions.TimeoutException'>
ERROR - 2021-01-07 10:21:39,421 - D:\se\Se_Project\Util\log.py - log.py[:46] - 出现异常
ERROR - 2021-01-07 10:21:39,421 - D:\se\Se_Project\Util\log.py - log.py[:46] - <class 'selenium.common.exceptions.TimeoutException'>
ERROR - 2021-01-07 10:21:42,297 - D:\se\Se_Project\Util\log.py - log.py[:46] - 出现异常
ERROR - 2021-01-07 10:21:42,298 - D:\se\Se_Project\Util\log.py - log.py[:46] - <class 'selenium.common.exceptions.TimeoutException'>
ERROR - 2021-01-07 10:25:51,024 - D:\se\Se_Project\Util\log.py - log.py[:46] - 出现异常
ERROR - 2021-01-07 10:25:51,024 - D:\se\Se_Project\Util\log.py - log.py[:46] - <class 'selenium.common.exceptions.TimeoutException'>
ERROR - 2021-01-19 15:05:29,570 - D:\se\Se_Project\Util\log.py - log.py[:46] - Exception: Don't find Boe, please check config
ERROR - 2021-01-19 15:07:20,198 - D:\se\Se_Project\Util\log.py - log.py[:46] - Exception: Don't find Boe, please check config
ERROR - 2021-01-19 15:22:37,643 - D:\se\Se_Project\Util\log.py - log.py[:46] - Exception: Don't find Boe, please check config
ERROR - 2021-01-19 15:23:30,747 - D:\se\Se_Project\Util\log.py - log.py[:46] - Exception: Don't find Boe, please check config
ERROR - 2021-01-19 17:42:41,544 - D:\se\Se_Project\Util\log.py - log.py[:46] - 没有找到对应配置项，请检查配置
ERROR - 2021-01-19 17:43:40,309 - D:\se\Se_Project\Util\log.py - log.py[:46] - 没有找到对应配置项，请检查配置
ERROR - 2021-01-19 20:46:13,141 - D:\se\Se_Project\Util\log.py - log.py[:46] - 没有找到对应配置项，请检查配置
ERROR - 2021-01-19 20:47:05,598 - D:\se\Se_Project\Util\log.py - log.py[:46] - 没有找到对应配置项，请检查配置
ERROR - 2021-01-19 21:00:53,801 - D:\se\Se_Project\Util\log.py - log.py[:46] - 没有找到对应配置项，请检查配置
ERROR - 2021-01-20 16:52:40,732 - D:\se\Se_Project\Util\log.py - log.py[:46] - Exception: Don't find Boe, please check config
ERROR - 2021-01-21 14:04:15,678 - D:\se\Se_Project\Util\log.py - log.py[:46] - 出现异常，异常信息为：<class 'selenium.common.exceptions.NoSuchElementException'>
ERROR - 2021-01-21 14:18:59,864 - D:\se\Se_Project\Util\log.py - log.py[:46] - 出现异常，异常信息为：<class 'selenium.common.exceptions.ElementClickInterceptedException'>
ERROR - 2021-01-21 14:41:03,395 - D:\se\Se_Project\Util\log.py - log.py[:46] - 出现异常，异常信息为：<class 'selenium.common.exceptions.NoSuchElementException'>
ERROR - 2021-01-21 18:56:25,844 - D:\se\Se_Project\Util\log.py - log.py[:46] - Exception: Don't find Boe, please check config
ERROR - 2021-01-21 20:04:09,421 - D:\se\Se_Project\Util\log.py - log.py[:46] - Exception: Don't find Boe, please check config
ERROR - 2021-01-21 20:45:50,247 - D:\se\Se_Project\Util\log.py - log.py[:46] - 出现异常，异常信息为：<class 'ValueError'>
ERROR - 2021-01-21 20:47:43,322 - D:\se\Se_Project\Util\log.py - log.py[:46] - 出现异常，异常信息为：<class 'ValueError'>
ERROR - 2021-01-21 20:50:47,814 - D:\se\Se_Project\Util\log.py - log.py[:46] - 出现异常，异常信息为：<class 'ValueError'>
ERROR - 2021-01-22 10:19:20,069 - D:\se\Se_Project\Util\log.py - log.py[:46] - Exception: Don't find Boe, please check config
ERROR - 2021-01-22 13:43:32,582 - D:\se\Se_Project\Util\log.py - log.py[:46] - 业务审批出现异常，异常信息为：<class 'Exception'>
ERROR - 2021-01-22 13:46:40,363 - D:\se\Se_Project\Util\log.py - log.py[:46] - Exception: Don't find Boe, please check config
ERROR - 2021-01-22 13:46:40,364 - D:\se\Se_Project\Util\log.py - log.py[:46] - 出现异常，异常信息为：<class 'Exception'>
ERROR - 2021-01-22 13:47:13,303 - D:\se\Se_Project\Util\log.py - log.py[:46] - 出现异常，异常信息为：<class 'selenium.common.exceptions.NoSuchElementException'>
ERROR - 2021-01-22 13:49:03,699 - D:\se\Se_Project\Util\log.py - log.py[:46] - 出现异常，异常信息为：<class 'selenium.common.exceptions.NoSuchElementException'>
ERROR - 2021-01-22 13:52:55,787 - D:\se\Se_Project\Util\log.py - log.py[:46] - 业务审批出现异常，异常信息为：<class 'Exception'>
ERROR - 2021-01-22 13:55:08,483 - D:\se\Se_Project\Util\log.py - log.py[:46] - boeNum do not exist
ERROR - 2021-01-22 13:55:08,483 - D:\se\Se_Project\Util\log.py - log.py[:46] - 业务审批出现异常，异常信息为：<class 'Exception'>
ERROR - 2021-01-22 13:58:11,956 - D:\se\Se_Project\Util\log.py - log.py[:46] - 出现异常，异常信息为：<class 'AssertionError'>
ERROR - 2021-01-22 14:02:38,714 - D:\se\Se_Project\Util\log.py - log.py[:46] - 业务审批出现异常，异常信息为：<class 'selenium.common.exceptions.TimeoutException'>
ERROR - 2021-01-22 14:06:54,950 - D:\se\Se_Project\Util\log.py - log.py[:46] - 业务审批出现异常，异常信息为：<class 'selenium.common.exceptions.TimeoutException'>
ERROR - 2021-01-22 14:08:17,649 - D:\se\Se_Project\Util\log.py - log.py[:46] - Exception: Don't find Boe, please check config
ERROR - 2021-01-22 14:08:17,650 - D:\se\Se_Project\Util\log.py - log.py[:46] - 出现异常，异常信息为：<class 'Exception'>
ERROR - 2021-01-22 14:09:04,861 - D:\se\Se_Project\Util\log.py - log.py[:46] - Exception: Don't find Boe, please check config
ERROR - 2021-01-22 14:09:04,864 - D:\se\Se_Project\Util\log.py - log.py[:46] - 出现异常，异常信息为：<class 'Exception'>
ERROR - 2021-01-22 14:14:51,391 - D:\se\Se_Project\Util\log.py - log.py[:46] - 业务审批出现异常，异常信息为：<class 'selenium.common.exceptions.TimeoutException'>
ERROR - 2021-01-22 14:19:01,271 - D:\se\Se_Project\Util\log.py - log.py[:46] - 业务审批出现异常，异常信息为：<class 'selenium.common.exceptions.TimeoutException'>
ERROR - 2021-01-22 14:20:26,089 - D:\se\Se_Project\Util\log.py - log.py[:46] - 业务审批出现异常，异常信息为：<class 'selenium.common.exceptions.NoSuchElementException'>
ERROR - 2021-01-22 14:28:51,568 - D:\se\Se_Project\Util\log.py - log.py[:46] - Exception: Don't find Boe, please check config
ERROR - 2021-01-22 14:28:51,568 - D:\se\Se_Project\Util\log.py - log.py[:46] - 出现异常，异常信息为：<class 'Exception'>
ERROR - 2021-01-22 14:34:08,607 - D:\se\Se_Project\Util\log.py - log.py[:46] - 出现异常，异常信息为：<class 'selenium.common.exceptions.NoSuchElementException'>
ERROR - 2021-01-22 14:35:13,239 - D:\se\Se_Project\Util\log.py - log.py[:46] - 出现异常，异常信息为：<class 'selenium.common.exceptions.TimeoutException'>
ERROR - 2021-01-22 14:41:11,865 - D:\se\Se_Project\Util\log.py - log.py[:46] - 出现异常，异常信息为：<class 'selenium.common.exceptions.TimeoutException'>
ERROR - 2021-01-22 14:41:43,906 - D:\se\Se_Project\Util\log.py - log.py[:46] - Exception: Don't find Boe, please check config
ERROR - 2021-01-22 14:41:43,907 - D:\se\Se_Project\Util\log.py - log.py[:46] - 出现异常，异常信息为：<class 'Exception'>
ERROR - 2021-01-22 14:42:06,312 - D:\se\Se_Project\Util\log.py - log.py[:46] - Exception: Don't find Boe, please check config
ERROR - 2021-01-22 14:42:06,313 - D:\se\Se_Project\Util\log.py - log.py[:46] - 出现异常，异常信息为：<class 'Exception'>
ERROR - 2021-01-22 15:14:56,350 - D:\se\Se_Project\Util\log.py - log.py[:46] - Exception: Don't find Boe, please check config
ERROR - 2021-01-22 15:14:56,350 - D:\se\Se_Project\Util\log.py - log.py[:46] - 出现异常，异常信息为：<class 'Exception'>
ERROR - 2021-01-22 15:17:06,980 - D:\se\Se_Project\Util\log.py - log.py[:46] - Exception: Don't find Boe, please check config
ERROR - 2021-01-22 15:17:06,982 - D:\se\Se_Project\Util\log.py - log.py[:46] - 出现异常，异常信息为：<class 'Exception'>
ERROR - 2021-01-22 15:18:14,379 - D:\se\Se_Project\Util\log.py - log.py[:46] - 出现异常，异常信息为：<class 'selenium.common.exceptions.TimeoutException'>
ERROR - 2021-01-22 15:19:50,411 - D:\se\Se_Project\Util\log.py - log.py[:46] - Exception: Don't find Boe, please check config
ERROR - 2021-01-22 15:19:50,411 - D:\se\Se_Project\Util\log.py - log.py[:46] - 出现异常，异常信息为：<class 'Exception'>
ERROR - 2021-01-22 15:20:17,083 - D:\se\Se_Project\Util\log.py - log.py[:46] - Exception: Don't find Boe, please check config
ERROR - 2021-01-22 15:20:17,084 - D:\se\Se_Project\Util\log.py - log.py[:46] - 出现异常，异常信息为：<class 'Exception'>
ERROR - 2021-01-22 15:26:04,407 - D:\se\Se_Project\Util\log.py - log.py[:46] - 出现异常，异常信息为：<class 'selenium.common.exceptions.TimeoutException'>
ERROR - 2021-01-22 15:27:04,459 - D:\se\Se_Project\Util\log.py - log.py[:46] - 出现异常，异常信息为：<class 'selenium.common.exceptions.TimeoutException'>
ERROR - 2021-01-22 15:29:06,380 - D:\se\Se_Project\Util\log.py - log.py[:46] - 出现异常，异常信息为：<class 'selenium.common.exceptions.TimeoutException'>
ERROR - 2021-01-22 16:05:26,141 - D:\se\Se_Project\Util\log.py - log.py[:46] - Exception: Don't find Boe, please check config
ERROR - 2021-01-22 16:05:26,143 - D:\se\Se_Project\Util\log.py - log.py[:46] - 出现异常，异常信息为：<class 'Exception'>
ERROR - 2021-01-22 16:09:22,613 - D:\se\Se_Project\Util\log.py - log.py[:46] - 出现异常，异常信息为：<class 'selenium.common.exceptions.TimeoutException'>
ERROR - 2021-01-22 16:15:29,696 - D:\se\Se_Project\Util\log.py - log.py[:46] - 出现异常，异常信息为：<class 'selenium.common.exceptions.TimeoutException'>
ERROR - 2021-01-22 16:15:57,794 - D:\se\Se_Project\Util\log.py - log.py[:46] - Exception: Don't find Boe, please check config
ERROR - 2021-01-22 16:30:35,670 - D:\se\Se_Project\Util\log.py - log.py[:46] - Exception: Don't find Boe, please check config
ERROR - 2021-01-22 16:33:27,793 - D:\se\Se_Project\Util\log.py - log.py[:46] - Exception: Don't find Boe, please check config
ERROR - 2021-01-22 16:33:41,728 - D:\se\Se_Project\Util\log.py - log.py[:46] - 出现异常，异常信息为：<class 'selenium.common.exceptions.TimeoutException'>
ERROR - 2021-01-22 16:34:21,751 - D:\se\Se_Project\Util\log.py - log.py[:46] - 出现异常，异常信息为：<class 'AttributeError'>
ERROR - 2021-01-22 16:47:02,001 - D:\se\Se_Project\Util\log.py - log.py[:46] - Exception: Don't find Boe, please check config
ERROR - 2021-01-22 16:47:02,463 - D:\se\Se_Project\Util\log.py - log.py[:46] - Exception: Don't find Boe, please check config
ERROR - 2021-01-22 16:47:02,465 - D:\se\Se_Project\Util\log.py - log.py[:46] - 出现异常，异常信息为：<class 'Exception'>
ERROR - 2021-01-22 16:48:37,494 - D:\se\Se_Project\Util\log.py - log.py[:46] - Exception: Don't find Boe, please check config
ERROR - 2021-01-22 16:48:37,496 - D:\se\Se_Project\Util\log.py - log.py[:46] - 出现异常，异常信息为：<class 'Exception'>
ERROR - 2021-01-22 16:50:14,483 - D:\se\Se_Project\Util\log.py - log.py[:46] - 出现异常，异常信息为：<class 'selenium.common.exceptions.TimeoutException'>
ERROR - 2021-01-22 20:35:31,231 - D:\se\Se_Project\Util\log.py - log.py[:46] - 出现异常，异常信息为：<class 'selenium.common.exceptions.TimeoutException'>
ERROR - 2021-01-22 20:36:59,751 - D:\se\Se_Project\Util\log.py - log.py[:46] - 出现异常，异常信息为：<class 'selenium.common.exceptions.TimeoutException'>
ERROR - 2021-01-22 20:38:41,466 - D:\se\Se_Project\Util\log.py - log.py[:46] - 出现异常，异常信息为：<class 'selenium.common.exceptions.TimeoutException'>
ERROR - 2021-01-22 20:40:14,829 - D:\se\Se_Project\Util\log.py - log.py[:46] - 出现异常，异常信息为：<class 'selenium.common.exceptions.TimeoutException'>
ERROR - 2021-01-22 20:41:02,247 - D:\se\Se_Project\Util\log.py - log.py[:46] - 出现异常，异常信息为：<class 'selenium.common.exceptions.TimeoutException'>
ERROR - 2021-01-22 20:42:18,299 - D:\se\Se_Project\Util\log.py - log.py[:46] - 出现异常，异常信息为：<class 'selenium.common.exceptions.TimeoutException'>
ERROR - 2021-01-22 20:43:50,640 - D:\se\Se_Project\Util\log.py - log.py[:46] - 出现异常，异常信息为：<class 'selenium.common.exceptions.TimeoutException'>
ERROR - 2021-01-22 20:44:39,169 - D:\se\Se_Project\Util\log.py - log.py[:46] - 出现异常，异常信息为：<class 'selenium.common.exceptions.TimeoutException'>
ERROR - 2021-01-22 20:54:03,389 - D:\se\Se_Project\Util\log.py - log.py[:46] - 出现异常，异常信息为：<class 'selenium.common.exceptions.TimeoutException'>
ERROR - 2021-01-22 21:07:03,588 - D:\se\Se_Project\Util\log.py - log.py[:46] - 出现异常，异常信息为：<class 'AttributeError'>
ERROR - 2021-01-22 21:08:03,790 - D:\se\Se_Project\Util\log.py - log.py[:46] - 出现异常，异常信息为：<class 'AttributeError'>
ERROR - 2021-01-22 21:09:32,598 - D:\se\Se_Project\Util\log.py - log.py[:46] - 出现异常，异常信息为：<class 'selenium.common.exceptions.TimeoutException'>
ERROR - 2021-01-22 21:27:01,002 - D:\se\Se_Project\Util\log.py - log.py[:46] - 出现异常，异常信息为：<class 'selenium.common.exceptions.TimeoutException'>
ERROR - 2021-01-22 21:27:47,617 - D:\se\Se_Project\Util\log.py - log.py[:46] - 出现异常，异常信息为：<class 'selenium.common.exceptions.TimeoutException'>
ERROR - 2021-01-22 21:30:34,398 - D:\se\Se_Project\Util\log.py - log.py[:46] - 出现异常，异常信息为：<class 'selenium.common.exceptions.TimeoutException'>
ERROR - 2021-01-22 21:30:59,690 - D:\se\Se_Project\Util\log.py - log.py[:46] - Exception: Don't find Boe, please check config
ERROR - 2021-01-22 21:30:59,690 - D:\se\Se_Project\Util\log.py - log.py[:46] - 出现异常，异常信息为：<class 'Exception'>
ERROR - 2021-01-22 23:14:50,479 - D:\se\Se_Project\Util\log.py - log.py[:46] - 出现异常，异常信息为：<class 'AttributeError'>
ERROR - 2021-01-22 23:15:25,226 - D:\se\Se_Project\Util\log.py - log.py[:46] - 出现异常，异常信息为：<class 'AttributeError'>
ERROR - 2021-01-22 23:21:36,438 - D:\se\Se_Project\Util\log.py - log.py[:46] - Exception: Don't find Boe, please check config
ERROR - 2021-01-22 23:21:36,438 - D:\se\Se_Project\Util\log.py - log.py[:46] - 出现异常，异常信息为：<class 'Exception'>
ERROR - 2021-01-22 23:32:51,415 - D:\se\Se_Project\Util\log.py - log.py[:46] - 出现异常，异常信息为：<class 'selenium.common.exceptions.NoSuchElementException'>
ERROR - 2021-01-22 23:34:06,267 - D:\se\Se_Project\Util\log.py - log.py[:46] - 出现异常，异常信息为：<class 'selenium.common.exceptions.NoSuchElementException'>
ERROR - 2021-01-22 23:35:55,257 - D:\se\Se_Project\Util\log.py - log.py[:46] - 出现异常，异常信息为：<class 'selenium.common.exceptions.StaleElementReferenceException'>
ERROR - 2021-01-22 23:36:46,455 - D:\se\Se_Project\Util\log.py - log.py[:46] - 出现异常，异常信息为：<class 'selenium.common.exceptions.StaleElementReferenceException'>
ERROR - 2021-01-22 23:39:00,513 - D:\se\Se_Project\Util\log.py - log.py[:46] - 出现异常，异常信息为：<class 'selenium.common.exceptions.TimeoutException'>
ERROR - 2021-01-22 23:48:38,604 - D:\se\Se_Project\Util\log.py - log.py[:46] - 出现异常，异常信息为：<class 'selenium.common.exceptions.TimeoutException'>
ERROR - 2021-01-22 23:51:57,115 - D:\se\Se_Project\Util\log.py - log.py[:46] - 出现异常，异常信息为：<class 'selenium.common.exceptions.ElementClickInterceptedException'>
ERROR - 2021-01-22 23:52:32,775 - D:\se\Se_Project\Util\log.py - log.py[:46] - 出现异常，异常信息为：<class 'selenium.common.exceptions.ElementClickInterceptedException'>
ERROR - 2021-01-23 00:07:42,630 - D:\se\Se_Project\Util\log.py - log.py[:46] - Exception: Don't find Boe, please check config
ERROR - 2021-01-23 00:07:42,631 - D:\se\Se_Project\Util\log.py - log.py[:46] - 出现异常，异常信息为：<class 'Exception'>
ERROR - 2021-01-23 00:29:33,387 - D:\se\Se_Project\Util\log.py - log.py[:46] - Exception: Don't find Boe, please check config
ERROR - 2021-01-23 00:29:33,388 - D:\se\Se_Project\Util\log.py - log.py[:46] - 出现异常，异常信息为：<class 'Exception'>
ERROR - 2021-01-23 00:30:09,453 - D:\se\Se_Project\Util\log.py - log.py[:46] - Exception: Don't find Boe, please check config
ERROR - 2021-01-23 00:30:09,454 - D:\se\Se_Project\Util\log.py - log.py[:46] - 出现异常，异常信息为：<class 'Exception'>
ERROR - 2021-01-23 00:30:40,164 - D:\se\Se_Project\Util\log.py - log.py[:46] - Exception: Don't find Boe, please check config
ERROR - 2021-01-23 00:30:40,165 - D:\se\Se_Project\Util\log.py - log.py[:46] - 出现异常，异常信息为：<class 'Exception'>
ERROR - 2021-01-23 00:32:07,045 - D:\se\Se_Project\Util\log.py - log.py[:46] - 出现异常，异常信息为：<class 'selenium.common.exceptions.NoSuchElementException'>
ERROR - 2021-01-23 00:32:40,805 - D:\se\Se_Project\Util\log.py - log.py[:46] - Exception: Don't find Boe, please check config
ERROR - 2021-01-23 00:32:40,805 - D:\se\Se_Project\Util\log.py - log.py[:46] - 出现异常，异常信息为：<class 'Exception'>
ERROR - 2021-01-23 00:36:33,216 - D:\se\Se_Project\Util\log.py - log.py[:46] - 出现异常，异常信息为：<class 'selenium.common.exceptions.TimeoutException'>
ERROR - 2021-01-23 01:07:24,167 - D:\se\Se_Project\Util\log.py - log.py[:46] - Exception: Don't find Boe, please check config
ERROR - 2021-01-23 01:07:24,168 - D:\se\Se_Project\Util\log.py - log.py[:46] - 出现异常，异常信息为：<class 'Exception'>
ERROR - 2021-01-23 01:08:41,120 - D:\se\Se_Project\Util\log.py - log.py[:46] - Exception: Don't find Boe, please check config
ERROR - 2021-01-23 01:08:41,121 - D:\se\Se_Project\Util\log.py - log.py[:46] - 出现异常，异常信息为：<class 'Exception'>
ERROR - 2021-01-23 01:09:37,484 - D:\se\Se_Project\Util\log.py - log.py[:46] - Exception: Don't find Boe, please check config
ERROR - 2021-01-23 01:09:37,486 - D:\se\Se_Project\Util\log.py - log.py[:46] - 出现异常，异常信息为：<class 'Exception'>
ERROR - 2021-01-23 17:01:57,675 - D:\se\Se_Project\Util\log.py - log.py[:46] - Exception: Don't find Boe, please check config
ERROR - 2021-01-23 17:01:57,681 - D:\se\Se_Project\Util\log.py - log.py[:46] - 出现异常，异常信息为：<class 'Exception'>
ERROR - 2021-01-24 15:57:26,307 - D:\se\Se_Project\Util\log.py - log.py[:46] - 业务审批出现异常，异常信息为：<class 'selenium.common.exceptions.TimeoutException'>
ERROR - 2021-01-24 16:11:10,808 - D:\se\Se_Project\Util\log.py - log.py[:46] - Exception: Don't find Boe, please check config
ERROR - 2021-01-24 16:11:10,813 - D:\se\Se_Project\Util\log.py - log.py[:46] - 出现异常，异常信息为：<class 'Exception'>
ERROR - 2021-01-24 17:12:07,970 - D:\se\Se_Project\Util\log.py - log.py[:46] - Exception: Don't find Boe, please check config
ERROR - 2021-01-24 17:12:07,971 - D:\se\Se_Project\Util\log.py - log.py[:46] -  Don't find Boe, Try agent
ERROR - 2021-01-24 18:49:04,988 - D:\se\Se_Project\Util\log.py - log.py[:46] - 没有找到查询结果，--- try again ---
ERROR - 2021-01-24 18:53:28,332 - D:\se\Se_Project\Util\log.py - log.py[:46] - 没有找到查询结果，--- try again ---
ERROR - 2021-01-24 19:30:45,292 - D:\se\Se_Project\Util\log.py - log.py[:46] - Exception: Don't find Boe, please check config
ERROR - 2021-01-24 19:30:45,292 - D:\se\Se_Project\Util\log.py - log.py[:46] -  Don't find Boe, Try again
ERROR - 2021-01-24 19:32:29,126 - D:\se\Se_Project\Util\log.py - log.py[:46] - Exception: Don't find Boe, please check config
ERROR - 2021-01-24 19:32:29,126 - D:\se\Se_Project\Util\log.py - log.py[:46] -  Don't find Boe, Try again
ERROR - 2021-01-24 19:34:21,452 - D:\se\Se_Project\Util\log.py - log.py[:46] - 没有找到查询结果，--- try again ---
ERROR - 2021-01-24 19:45:58,381 - D:\se\Se_Project\Util\log.py - log.py[:46] - 没有找到查询结果，--- try again ---
ERROR - 2021-01-24 19:46:00,664 - D:\se\Se_Project\Util\log.py - log.py[:46] - 没有找到查询结果，--- try again ---
ERROR - 2021-01-24 19:48:40,616 - D:\se\Se_Project\Util\log.py - log.py[:46] - Exception: Don't find Boe, please check config
ERROR - 2021-01-24 19:48:40,616 - D:\se\Se_Project\Util\log.py - log.py[:46] -  Don't find Boe, Try again
ERROR - 2021-01-24 19:49:34,413 - D:\se\Se_Project\Util\log.py - log.py[:46] - 没有找到查询结果，--- try again ---
ERROR - 2021-01-24 19:54:33,778 - D:\se\Se_Project\Util\log.py - log.py[:46] - Exception: Don't find Boe, please check config
ERROR - 2021-01-24 19:54:33,778 - D:\se\Se_Project\Util\log.py - log.py[:46] -  Don't find Boe, Try again
ERROR - 2021-01-24 19:57:27,680 - D:\se\Se_Project\Util\log.py - log.py[:46] - 没有找到查询结果，--- try again ---
ERROR - 2021-01-24 19:58:33,439 - D:\se\Se_Project\Util\log.py - log.py[:46] - 没有找到查询结果，--- try again ---
ERROR - 2021-01-24 20:17:27,277 - D:\se\Se_Project\Util\log.py - log.py[:46] - Exception: Don't find Boe, please check config
ERROR - 2021-01-24 20:17:27,277 - D:\se\Se_Project\Util\log.py - log.py[:46] -  Don't find Boe, Try again
ERROR - 2021-01-24 20:17:27,279 - D:\se\Se_Project\Util\log.py - log.py[:46] - 出现异常，异常信息为：<class 'AttributeError'>
ERROR - 2021-01-24 20:18:27,146 - D:\se\Se_Project\Util\log.py - log.py[:46] - 出现异常，异常信息为：<class 'KeyError'>
ERROR - 2021-01-24 20:23:04,700 - D:\se\Se_Project\Util\log.py - log.py[:46] - 出现异常，异常信息为：<class 'KeyError'>
ERROR - 2021-01-24 20:23:55,295 - D:\se\Se_Project\Util\log.py - log.py[:46] - 出现异常，异常信息为：<class 'KeyError'>
ERROR - 2021-01-24 20:24:48,155 - D:\se\Se_Project\Util\log.py - log.py[:46] - 出现异常，异常信息为：<class 'KeyError'>
ERROR - 2021-01-24 20:29:40,753 - D:\se\Se_Project\Util\log.py - log.py[:46] - 出现异常，异常信息为：<class 'selenium.common.exceptions.TimeoutException'>
ERROR - 2021-01-24 20:33:19,326 - D:\se\Se_Project\Util\log.py - log.py[:46] - 没有找到查询结果，--- try again ---
ERROR - 2021-01-24 20:34:07,118 - D:\se\Se_Project\Util\log.py - log.py[:46] - 没有找到查询结果，--- try again ---
ERROR - 2021-01-24 20:53:45,412 - D:\se\Se_Project\Util\log.py - log.py[:46] - 出现异常，异常信息为：<class 'KeyError'>
ERROR - 2021-01-24 20:54:50,594 - D:\se\Se_Project\Util\log.py - log.py[:46] - 出现异常，异常信息为：<class 'KeyError'>
ERROR - 2021-01-24 20:57:52,501 - D:\se\Se_Project\Util\log.py - log.py[:46] - 出现异常，异常信息为：<class 'selenium.common.exceptions.NoSuchElementException'>
ERROR - 2021-01-24 21:00:17,145 - D:\se\Se_Project\Util\log.py - log.py[:46] - Exception: Don't find Boe, please check config
ERROR - 2021-01-24 21:00:18,145 - D:\se\Se_Project\Util\log.py - log.py[:46] -  Don't find Boe, Try again
ERROR - 2021-01-24 21:01:20,283 - D:\se\Se_Project\Util\log.py - log.py[:46] - 没有找到查询结果，--- try again ---
ERROR - 2021-01-24 21:02:11,591 - D:\se\Se_Project\Util\log.py - log.py[:46] - 没有找到查询结果，--- try again ---
ERROR - 2021-01-24 21:35:44,976 - D:\se\Se_Project\Util\log.py - log.py[:46] - Exception: Don't find Boe, please check config
ERROR - 2021-01-24 21:35:45,976 - D:\se\Se_Project\Util\log.py - log.py[:46] -  Don't find Boe, Try again
ERROR - 2021-01-24 21:40:07,158 - D:\se\Se_Project\Util\log.py - log.py[:46] - 没有找到查询结果，--- try again ---
ERROR - 2021-01-24 21:41:06,446 - D:\se\Se_Project\Util\log.py - log.py[:46] - 没有找到查询结果，--- try again ---
ERROR - 2021-01-24 22:02:40,713 - D:\se\Se_Project\Util\log.py - log.py[:46] - Exception: Don't find Boe, please check config
ERROR - 2021-01-24 22:02:41,714 - D:\se\Se_Project\Util\log.py - log.py[:46] -  Don't find Boe, Try again
ERROR - 2021-01-24 22:02:58,649 - D:\se\Se_Project\Util\log.py - log.py[:46] - 出现异常，异常信息为：<class 'selenium.common.exceptions.TimeoutException'>
ERROR - 2021-01-24 22:15:15,768 - D:\se\Se_Project\Util\log.py - log.py[:46] - 没有找到查询结果，--- try again ---
ERROR - 2021-01-24 22:16:11,452 - D:\se\Se_Project\Util\log.py - log.py[:46] - 没有找到查询结果，--- try again ---
ERROR - 2021-01-24 22:35:12,740 - D:\se\Se_Project\Util\log.py - log.py[:46] - 出现异常，异常信息为：<class 'selenium.common.exceptions.NoSuchElementException'>
ERROR - 2021-01-24 22:40:24,606 - D:\se\Se_Project\Util\log.py - log.py[:46] - 没有找到查询结果，--- try again ---
ERROR - 2021-01-24 22:41:11,026 - D:\se\Se_Project\Util\log.py - log.py[:46] - 没有找到查询结果，--- try again ---
ERROR - 2021-01-24 23:18:19,789 - D:\se\Se_Project\Util\log.py - log.py[:46] - 没有找到查询结果，--- try again ---
ERROR - 2021-01-24 23:19:08,618 - D:\se\Se_Project\Util\log.py - log.py[:46] - 没有找到查询结果，--- try again ---
ERROR - 2021-01-24 23:39:24,417 - D:\se\Se_Project\Util\log.py - log.py[:46] - Exception: Don't find Boe, please check config
ERROR - 2021-01-24 23:39:25,420 - D:\se\Se_Project\Util\log.py - log.py[:46] -  Don't find Boe, Try again
ERROR - 2021-01-24 23:39:25,500 - D:\se\Se_Project\Util\log.py - log.py[:46] - Exception: Don't find Boe, please check config
ERROR - 2021-01-24 23:39:25,504 - D:\se\Se_Project\Util\log.py - log.py[:46] - 出现异常，异常信息为：<class 'Exception'>
ERROR - 2021-01-24 23:40:05,713 - D:\se\Se_Project\Util\log.py - log.py[:46] - Exception: Don't find Boe, please check config
ERROR - 2021-01-24 23:40:07,714 - D:\se\Se_Project\Util\log.py - log.py[:46] -  Don't find Boe, Try again
ERROR - 2021-01-24 23:40:07,810 - D:\se\Se_Project\Util\log.py - log.py[:46] - Exception: Don't find Boe, please check config
ERROR - 2021-01-24 23:40:07,811 - D:\se\Se_Project\Util\log.py - log.py[:46] - 出现异常，异常信息为：<class 'Exception'>
ERROR - 2021-01-24 23:41:05,060 - D:\se\Se_Project\Util\log.py - log.py[:46] - Exception: Don't find Boe, please check config
ERROR - 2021-01-24 23:41:06,061 - D:\se\Se_Project\Util\log.py - log.py[:46] -  Don't find Boe, Try again
ERROR - 2021-01-24 23:41:06,132 - D:\se\Se_Project\Util\log.py - log.py[:46] - Exception: Don't find Boe, please check config
ERROR - 2021-01-24 23:41:06,135 - D:\se\Se_Project\Util\log.py - log.py[:46] - 出现异常，异常信息为：<class 'Exception'>
ERROR - 2021-01-24 23:43:26,511 - D:\se\Se_Project\Util\log.py - log.py[:46] - Exception: Don't find Boe, please check config
ERROR - 2021-01-24 23:43:27,511 - D:\se\Se_Project\Util\log.py - log.py[:46] -  Don't find Boe, Try again
ERROR - 2021-01-24 23:43:27,610 - D:\se\Se_Project\Util\log.py - log.py[:46] - Exception: Don't find Boe, please check config
ERROR - 2021-01-24 23:43:27,612 - D:\se\Se_Project\Util\log.py - log.py[:46] - 出现异常，异常信息为：<class 'Exception'>
ERROR - 2021-01-24 23:45:31,117 - D:\se\Se_Project\Util\log.py - log.py[:46] - Exception: Don't find Boe, please check config
ERROR - 2021-01-24 23:45:32,117 - D:\se\Se_Project\Util\log.py - log.py[:46] -  Don't find Boe, Try again
ERROR - 2021-01-24 23:45:32,189 - D:\se\Se_Project\Util\log.py - log.py[:46] - Exception: Don't find Boe, please check config
ERROR - 2021-01-24 23:45:32,190 - D:\se\Se_Project\Util\log.py - log.py[:46] - 出现异常，异常信息为：<class 'Exception'>
ERROR - 2021-01-24 23:46:20,868 - D:\se\Se_Project\Util\log.py - log.py[:46] - Exception: Don't find Boe, please check config
ERROR - 2021-01-24 23:50:49,827 - D:\se\Se_Project\Util\log.py - log.py[:46] - Exception: Don't find Boe, please check config
ERROR - 2021-01-24 23:50:50,829 - D:\se\Se_Project\Util\log.py - log.py[:46] -  Don't find Boe, Try again
ERROR - 2021-01-24 23:50:50,894 - D:\se\Se_Project\Util\log.py - log.py[:46] - Exception: Don't find Boe, please check config
ERROR - 2021-01-24 23:50:50,895 - D:\se\Se_Project\Util\log.py - log.py[:46] - 出现异常，异常信息为：<class 'Exception'>
ERROR - 2021-01-24 23:52:04,785 - D:\se\Se_Project\Util\log.py - log.py[:46] - Exception: Don't find Boe, please check config
ERROR - 2021-01-24 23:52:05,786 - D:\se\Se_Project\Util\log.py - log.py[:46] -  Don't find Boe, Try again
ERROR - 2021-01-24 23:52:05,861 - D:\se\Se_Project\Util\log.py - log.py[:46] - Exception: Don't find Boe, please check config
ERROR - 2021-01-24 23:52:05,862 - D:\se\Se_Project\Util\log.py - log.py[:46] - 出现异常，异常信息为：<class 'Exception'>
ERROR - 2021-01-24 23:52:59,595 - D:\se\Se_Project\Util\log.py - log.py[:46] - 出现异常，异常信息为：<class 'selenium.common.exceptions.WebDriverException'>
ERROR - 2021-01-24 23:54:02,076 - D:\se\Se_Project\Util\log.py - log.py[:46] - 出现异常，异常信息为：<class 'selenium.common.exceptions.NoSuchElementException'>
ERROR - 2021-01-24 23:56:32,004 - D:\se\Se_Project\Util\log.py - log.py[:46] - 出现异常，异常信息为：<class 'selenium.common.exceptions.ElementNotInteractableException'>
ERROR - 2021-01-24 23:58:08,666 - D:\se\Se_Project\Util\log.py - log.py[:46] - 出现异常，异常信息为：<class 'TypeError'>
ERROR - 2021-01-25 00:00:59,363 - D:\se\Se_Project\Util\log.py - log.py[:46] - 出现异常，异常信息为：<class 'selenium.common.exceptions.TimeoutException'>
ERROR - 2021-01-25 00:01:54,631 - D:\se\Se_Project\Util\log.py - log.py[:46] - Exception: Don't find Boe, please check config
ERROR - 2021-01-25 00:01:55,632 - D:\se\Se_Project\Util\log.py - log.py[:46] -  Don't find Boe, Try again
ERROR - 2021-01-25 00:03:00,050 - D:\se\Se_Project\Util\log.py - log.py[:46] - 没有找到查询结果，--- try again ---
ERROR - 2021-01-25 00:04:02,161 - D:\se\Se_Project\Util\log.py - log.py[:46] - 没有找到查询结果，--- try again ---
ERROR - 2021-01-25 00:05:24,477 - D:\se\Se_Project\Util\log.py - log.py[:46] - Exception: Don't find Boe, please check config
ERROR - 2021-01-25 00:05:25,478 - D:\se\Se_Project\Util\log.py - log.py[:46] -  Don't find Boe, Try again
ERROR - 2021-01-25 00:05:31,262 - D:\se\Se_Project\Util\log.py - log.py[:46] - 出现异常，异常信息为：<class 'selenium.common.exceptions.NoSuchElementException'>
ERROR - 2021-01-25 00:05:41,532 - D:\se\Se_Project\Util\log.py - log.py[:46] - 出现异常，异常信息为：<class 'selenium.common.exceptions.ElementClickInterceptedException'>
ERROR - 2021-01-25 00:06:53,538 - D:\se\Se_Project\Util\log.py - log.py[:46] - Exception: Don't find Boe, please check config
ERROR - 2021-01-25 00:06:54,539 - D:\se\Se_Project\Util\log.py - log.py[:46] -  Don't find Boe, Try again
ERROR - 2021-01-25 00:06:59,989 - D:\se\Se_Project\Util\log.py - log.py[:46] - 出现异常，异常信息为：<class 'selenium.common.exceptions.NoSuchElementException'>
ERROR - 2021-01-25 00:07:11,337 - D:\se\Se_Project\Util\log.py - log.py[:46] - 出现异常，异常信息为：<class 'selenium.common.exceptions.ElementClickInterceptedException'>
ERROR - 2021-01-25 00:08:10,600 - D:\se\Se_Project\Util\log.py - log.py[:46] - 出现异常，异常信息为：<class 'selenium.common.exceptions.NoSuchElementException'>
ERROR - 2021-01-25 00:08:22,190 - D:\se\Se_Project\Util\log.py - log.py[:46] - 出现异常，异常信息为：<class 'selenium.common.exceptions.ElementClickInterceptedException'>
ERROR - 2021-01-25 00:09:14,512 - D:\se\Se_Project\Util\log.py - log.py[:46] - 出现异常，异常信息为：<class 'selenium.common.exceptions.NoSuchElementException'>
ERROR - 2021-01-25 00:09:38,692 - D:\se\Se_Project\Util\log.py - log.py[:46] - 出现异常，异常信息为：<class 'selenium.common.exceptions.TimeoutException'>
ERROR - 2021-01-25 00:14:22,046 - D:\se\Se_Project\Util\log.py - log.py[:46] - 出现异常，异常信息为：<class 'selenium.common.exceptions.NoSuchElementException'>
ERROR - 2021-01-25 00:15:25,911 - D:\se\Se_Project\Util\log.py - log.py[:46] - 没有找到查询结果，--- try again ---
ERROR - 2021-01-25 00:16:26,062 - D:\se\Se_Project\Util\log.py - log.py[:46] - 没有找到查询结果，--- try again ---
ERROR - 2021-01-25 00:26:42,433 - D:\se\Se_Project\Util\log.py - log.py[:46] - Exception: Don't find Boe, please check config
ERROR - 2021-01-25 00:29:29,801 - D:\se\Se_Project\Util\log.py - log.py[:46] - Exception: Don't find Boe, please check config
ERROR - 2021-01-25 00:31:36,732 - D:\se\Se_Project\Util\log.py - log.py[:46] - 出现异常，异常信息为：<class 'selenium.common.exceptions.NoSuchElementException'>
ERROR - 2021-01-25 00:31:52,479 - D:\se\Se_Project\Util\log.py - log.py[:46] - 出现异常，异常信息为：<class 'selenium.common.exceptions.ElementClickInterceptedException'>
ERROR - 2021-01-25 00:33:02,291 - D:\se\Se_Project\Util\log.py - log.py[:46] - 出现异常，异常信息为：<class 'selenium.common.exceptions.NoSuchElementException'>
ERROR - 2021-01-25 00:33:18,271 - D:\se\Se_Project\Util\log.py - log.py[:46] - 出现异常，异常信息为：<class 'selenium.common.exceptions.ElementClickInterceptedException'>
ERROR - 2021-01-25 00:34:15,049 - D:\se\Se_Project\Util\log.py - log.py[:46] - 出现异常，异常信息为：<class 'selenium.common.exceptions.NoSuchElementException'>
ERROR - 2021-01-25 00:34:30,847 - D:\se\Se_Project\Util\log.py - log.py[:46] - 出现异常，异常信息为：<class 'selenium.common.exceptions.ElementClickInterceptedException'>
ERROR - 2021-01-25 00:35:50,706 - D:\se\Se_Project\Util\log.py - log.py[:46] - 出现异常，异常信息为：<class 'selenium.common.exceptions.NoSuchElementException'>
ERROR - 2021-01-25 00:36:07,658 - D:\se\Se_Project\Util\log.py - log.py[:46] - 出现异常，异常信息为：<class 'selenium.common.exceptions.NoSuchElementException'>
ERROR - 2021-01-25 00:36:22,918 - D:\se\Se_Project\Util\log.py - log.py[:46] - 出现异常，异常信息为：<class 'selenium.common.exceptions.ElementClickInterceptedException'>
ERROR - 2021-01-25 00:38:22,847 - D:\se\Se_Project\Util\log.py - log.py[:46] - 出现异常，异常信息为：<class 'selenium.common.exceptions.NoSuchElementException'>
ERROR - 2021-01-25 00:38:40,265 - D:\se\Se_Project\Util\log.py - log.py[:46] - 出现异常，异常信息为：<class 'selenium.common.exceptions.NoSuchElementException'>
ERROR - 2021-01-25 00:46:03,808 - D:\se\Se_Project\Util\log.py - log.py[:46] - 没有找到查询结果，--- try again ---
ERROR - 2021-01-25 00:47:07,143 - D:\se\Se_Project\Util\log.py - log.py[:46] - 没有找到查询结果，--- try again ---
ERROR - 2021-01-25 00:48:53,607 - D:\se\Se_Project\Util\log.py - log.py[:46] - 没有找到查询结果，--- try again ---
ERROR - 2021-01-25 00:49:52,510 - D:\se\Se_Project\Util\log.py - log.py[:46] - 没有找到查询结果，--- try again ---
ERROR - 2021-01-25 00:51:39,945 - D:\se\Se_Project\Util\log.py - log.py[:46] - 没有找到查询结果，--- try again ---
ERROR - 2021-01-25 00:52:47,085 - D:\se\Se_Project\Util\log.py - log.py[:46] - 没有找到查询结果，--- try again ---
ERROR - 2021-01-25 00:54:30,727 - D:\se\Se_Project\Util\log.py - log.py[:46] - 没有找到查询结果，--- try again ---
ERROR - 2021-01-25 00:55:31,722 - D:\se\Se_Project\Util\log.py - log.py[:46] - 没有找到查询结果，--- try again ---
ERROR - 2021-01-25 00:56:09,990 - D:\se\Se_Project\Util\log.py - log.py[:46] - 出现异常，异常信息为：<class 'selenium.common.exceptions.NoSuchElementException'>
ERROR - 2021-01-25 00:57:31,638 - D:\se\Se_Project\Util\log.py - log.py[:46] - 没有找到查询结果，--- try again ---
ERROR - 2021-01-25 00:58:33,541 - D:\se\Se_Project\Util\log.py - log.py[:46] - 没有找到查询结果，--- try again ---
ERROR - 2021-01-25 00:59:17,143 - D:\se\Se_Project\Util\log.py - log.py[:46] - 出现异常，异常信息为：<class 'selenium.common.exceptions.NoSuchElementException'>
ERROR - 2021-01-25 00:59:33,971 - D:\se\Se_Project\Util\log.py - log.py[:46] - 出现异常，异常信息为：<class 'selenium.common.exceptions.NoSuchElementException'>
ERROR - 2021-01-25 01:00:51,453 - D:\se\Se_Project\Util\log.py - log.py[:46] - 没有找到查询结果，--- try again ---
ERROR - 2021-01-25 01:01:55,445 - D:\se\Se_Project\Util\log.py - log.py[:46] - 没有找到查询结果，--- try again ---
ERROR - 2021-01-25 01:02:29,606 - D:\se\Se_Project\Util\log.py - log.py[:46] - Exception: Don't find Boe, please check config
ERROR - 2021-01-25 01:02:30,606 - D:\se\Se_Project\Util\log.py - log.py[:46] -  Don't find Boe, Try again
ERROR - 2021-01-25 01:03:41,186 - D:\se\Se_Project\Util\log.py - log.py[:46] - 没有找到查询结果，--- try again ---
ERROR - 2021-01-25 01:04:50,391 - D:\se\Se_Project\Util\log.py - log.py[:46] - 没有找到查询结果，--- try again ---
ERROR - 2021-01-25 01:05:21,613 - D:\se\Se_Project\Util\log.py - log.py[:46] - Exception: Don't find Boe, please check config
ERROR - 2021-01-25 01:05:22,614 - D:\se\Se_Project\Util\log.py - log.py[:46] -  Don't find Boe, Try again
ERROR - 2021-01-25 01:06:34,880 - D:\se\Se_Project\Util\log.py - log.py[:46] - 没有找到查询结果，--- try again ---
ERROR - 2021-01-25 01:07:34,756 - D:\se\Se_Project\Util\log.py - log.py[:46] - 没有找到查询结果，--- try again ---
ERROR - 2021-01-25 08:53:03,288 - D:\se\Se_Project\Util\log.py - log.py[:46] - Exception: Don't find Boe, please check config
ERROR - 2021-01-25 08:53:04,292 - D:\se\Se_Project\Util\log.py - log.py[:46] -  Don't find Boe, Try again
ERROR - 2021-01-25 08:53:04,378 - D:\se\Se_Project\Util\log.py - log.py[:46] - Exception: Don't find Boe, please check config
ERROR - 2021-01-25 08:53:04,388 - D:\se\Se_Project\Util\log.py - log.py[:46] - 出现异常，异常信息为：<class 'Exception'>
ERROR - 2021-01-25 08:55:10,454 - D:\se\Se_Project\Util\log.py - log.py[:46] - Exception: Don't find Boe, please check config
ERROR - 2021-01-25 08:55:11,455 - D:\se\Se_Project\Util\log.py - log.py[:46] -  Don't find Boe, Try again
ERROR - 2021-01-25 08:55:11,528 - D:\se\Se_Project\Util\log.py - log.py[:46] - Exception: Don't find Boe, please check config
ERROR - 2021-01-25 08:55:11,529 - D:\se\Se_Project\Util\log.py - log.py[:46] - 出现异常，异常信息为：<class 'Exception'>
ERROR - 2021-01-25 09:00:27,136 - D:\se\Se_Project\Util\log.py - log.py[:46] - 没有找到查询结果，--- try again ---
ERROR - 2021-01-25 09:01:01,713 - D:\se\Se_Project\Util\log.py - log.py[:46] - 没有找到查询结果，--- try again ---
ERROR - 2021-01-25 09:11:32,953 - D:\se\Se_Project\Util\log.py - log.py[:46] - 没有找到查询结果，--- try again ---
ERROR - 2021-01-25 09:11:48,926 - D:\se\Se_Project\Util\log.py - log.py[:46] - 没有找到查询结果，--- try again ---
ERROR - 2021-01-25 11:00:14,082 - D:\se\Se_Project\Util\log.py - log.py[:46] - Exception: Don't find Boe, please check config
ERROR - 2021-01-25 11:00:15,083 - D:\se\Se_Project\Util\log.py - log.py[:46] -  Don't find Boe, Try again
ERROR - 2021-01-25 11:00:15,197 - D:\se\Se_Project\Util\log.py - log.py[:46] - Exception: Don't find Boe, please check config
ERROR - 2021-01-25 11:00:15,198 - D:\se\Se_Project\Util\log.py - log.py[:46] - 出现异常，异常信息为：<class 'Exception'>
ERROR - 2021-01-25 11:02:20,158 - D:\se\Se_Project\Util\log.py - log.py[:46] - Exception: Don't find Boe, please check config
ERROR - 2021-01-25 11:02:21,159 - D:\se\Se_Project\Util\log.py - log.py[:46] -  Don't find Boe, Try again
ERROR - 2021-01-25 11:02:21,243 - D:\se\Se_Project\Util\log.py - log.py[:46] - Exception: Don't find Boe, please check config
ERROR - 2021-01-25 11:02:21,244 - D:\se\Se_Project\Util\log.py - log.py[:46] - 出现异常，异常信息为：<class 'Exception'>
ERROR - 2021-01-25 11:03:33,337 - D:\se\Se_Project\Util\log.py - log.py[:46] - Exception: Don't find Boe, please check config
ERROR - 2021-01-25 11:03:34,338 - D:\se\Se_Project\Util\log.py - log.py[:46] -  Don't find Boe, Try again
ERROR - 2021-01-25 11:03:34,429 - D:\se\Se_Project\Util\log.py - log.py[:46] - Exception: Don't find Boe, please check config
ERROR - 2021-01-25 11:03:34,430 - D:\se\Se_Project\Util\log.py - log.py[:46] - 出现异常，异常信息为：<class 'Exception'>
ERROR - 2021-01-25 11:05:06,558 - D:\se\Se_Project\Util\log.py - log.py[:46] - Exception: Don't find Boe, please check config
ERROR - 2021-01-25 11:05:07,559 - D:\se\Se_Project\Util\log.py - log.py[:46] -  Don't find Boe, Try again
ERROR - 2021-01-25 11:05:07,715 - D:\se\Se_Project\Util\log.py - log.py[:46] - Exception: Don't find Boe, please check config
ERROR - 2021-01-25 11:05:07,716 - D:\se\Se_Project\Util\log.py - log.py[:46] - 出现异常，异常信息为：<class 'Exception'>
ERROR - 2021-01-25 11:05:18,481 - D:\se\Se_Project\Util\log.py - log.py[:46] - 出现异常，异常信息为：<class 'urllib3.exceptions.MaxRetryError'>
ERROR - 2021-01-25 11:08:21,787 - D:\se\Se_Project\Util\log.py - log.py[:46] - Exception: Don't find Boe, please check config
ERROR - 2021-01-25 11:08:22,788 - D:\se\Se_Project\Util\log.py - log.py[:46] -  Don't find Boe, Try again
ERROR - 2021-01-25 11:08:22,959 - D:\se\Se_Project\Util\log.py - log.py[:46] - Exception: Don't find Boe, please check config
ERROR - 2021-01-25 11:08:22,961 - D:\se\Se_Project\Util\log.py - log.py[:46] - 出现异常，异常信息为：<class 'Exception'>
ERROR - 2021-01-25 11:08:24,656 - D:\se\Se_Project\Util\log.py - log.py[:46] - 出现异常，异常信息为：<class 'selenium.common.exceptions.ElementClickInterceptedException'>
ERROR - 2021-01-25 11:10:33,101 - D:\se\Se_Project\Util\log.py - log.py[:46] - Exception: Don't find Boe, please check config
ERROR - 2021-01-25 11:10:34,101 - D:\se\Se_Project\Util\log.py - log.py[:46] -  Don't find Boe, Try again
ERROR - 2021-01-25 11:10:34,267 - D:\se\Se_Project\Util\log.py - log.py[:46] - Exception: Don't find Boe, please check config
ERROR - 2021-01-25 11:10:34,268 - D:\se\Se_Project\Util\log.py - log.py[:46] - 出现异常，异常信息为：<class 'Exception'>
ERROR - 2021-01-25 11:12:04,526 - D:\se\Se_Project\Util\log.py - log.py[:46] - 没有找到查询结果，--- try again ---
ERROR - 2021-01-25 11:12:19,166 - D:\se\Se_Project\Util\log.py - log.py[:46] - 没有找到查询结果，--- try again ---
ERROR - 2021-01-25 11:17:06,449 - D:\se\Se_Project\Util\log.py - log.py[:46] - 没有找到查询结果，--- try again ---
ERROR - 2021-01-25 11:23:46,808 - D:\se\Se_Project\Util\log.py - log.py[:46] - 出现异常，异常信息为：<class 'selenium.common.exceptions.ElementClickInterceptedException'>
ERROR - 2021-01-25 11:26:14,200 - D:\se\Se_Project\Util\log.py - log.py[:46] - 没有找到查询结果，--- try again ---
ERROR - 2021-01-25 11:26:16,934 - D:\se\Se_Project\Util\log.py - log.py[:46] - 没有找到查询结果，--- try again ---
ERROR - 2021-01-25 11:26:34,300 - D:\se\Se_Project\Util\log.py - log.py[:46] - 没有找到查询结果，--- try again ---
ERROR - 2021-01-25 11:26:37,691 - D:\se\Se_Project\Util\log.py - log.py[:46] - 没有找到查询结果，--- try again ---
ERROR - 2021-01-25 11:36:58,032 - D:\se\Se_Project\Util\log.py - log.py[:46] - 没有找到查询结果，--- try again ---
ERROR - 2021-01-25 11:40:41,624 - D:\se\Se_Project\Util\log.py - log.py[:46] - 没有找到查询结果，--- try again ---
ERROR - 2021-01-25 11:40:49,359 - D:\se\Se_Project\Util\log.py - log.py[:46] - 没有找到查询结果，--- try again ---
ERROR - 2021-01-25 11:40:51,808 - D:\se\Se_Project\Util\log.py - log.py[:46] - 没有找到查询结果，--- try again ---
ERROR - 2021-01-25 11:41:53,314 - D:\se\Se_Project\Util\log.py - log.py[:46] - 没有找到查询结果，--- try again ---
ERROR - 2021-01-25 11:46:23,582 - D:\se\Se_Project\Util\log.py - log.py[:46] - 出现异常，异常信息为：<class 'selenium.common.exceptions.NoSuchElementException'>
ERROR - 2021-01-25 11:47:49,782 - D:\se\Se_Project\Util\log.py - log.py[:46] - 没有找到查询结果，--- try again ---
ERROR - 2021-01-25 11:48:51,064 - D:\se\Se_Project\Util\log.py - log.py[:46] - 没有找到查询结果，--- try again ---
ERROR - 2021-01-27 14:44:35,895 - D:\se\Se_Project\Util\log.py - log.py[:47] - 出现异常，异常信息为：<class 'selenium.common.exceptions.TimeoutException'>
ERROR - 2021-01-27 14:46:27,740 - D:\se\Se_Project\Util\log.py - log.py[:47] - 出现异常，异常信息为：<class 'selenium.common.exceptions.TimeoutException'>
ERROR - 2021-01-27 14:51:22,588 - D:\se\Se_Project\Util\log.py - log.py[:47] - Exception: Don't find Boe, please check config
ERROR - 2021-01-27 14:51:23,590 - D:\se\Se_Project\Util\log.py - log.py[:47] -  Don't find Boe, Try again
ERROR - 2021-01-27 14:52:08,268 - D:\se\Se_Project\Util\log.py - log.py[:47] - 没有找到查询结果，--- try again ---
ERROR - 2021-01-27 14:52:23,107 - D:\se\Se_Project\Util\log.py - log.py[:47] - 没有找到查询结果，--- try again ---
ERROR - 2021-01-27 14:52:30,522 - D:\se\Se_Project\Util\log.py - log.py[:47] - 出现异常，异常信息为：<class 'selenium.common.exceptions.TimeoutException'>
ERROR - 2021-01-27 14:53:51,586 - D:\se\Se_Project\Util\log.py - log.py[:47] - 没有找到查询结果，--- try again ---
ERROR - 2021-01-27 14:54:23,758 - D:\se\Se_Project\Util\log.py - log.py[:47] - 出现异常，异常信息为：<class 'selenium.common.exceptions.TimeoutException'>
ERROR - 2021-01-27 14:55:45,499 - D:\se\Se_Project\Util\log.py - log.py[:47] - 没有找到查询结果，--- try again ---
ERROR - 2021-01-27 14:56:46,227 - D:\se\Se_Project\Util\log.py - log.py[:47] - 没有找到查询结果，--- try again ---
ERROR - 2021-01-27 14:57:02,566 - D:\se\Se_Project\Util\log.py - log.py[:47] - 出现异常，异常信息为：<class 'selenium.common.exceptions.TimeoutException'>
ERROR - 2021-01-28 11:11:10,361 - D:\se\Se_Project\Util\log.py - log.py[:54] - Exception: Don't find Boe, please check config
ERROR - 2021-01-28 11:11:11,363 - D:\se\Se_Project\Util\log.py - log.py[:54] -  Don't find Boe, Try again
ERROR - 2021-01-28 11:11:26,151 - D:\se\Se_Project\Util\log.py - log.py[:54] - 出现异常，异常信息为：<class 'selenium.common.exceptions.TimeoutException'>
ERROR - 2021-01-28 11:13:18,895 - D:\se\Se_Project\Util\log.py - log.py[:54] - 没有找到查询结果，--- try again ---
ERROR - 2021-01-28 11:13:28,675 - D:\se\Se_Project\Util\log.py - log.py[:54] - 没有找到查询结果，--- try again ---
ERROR - 2021-01-28 11:14:05,930 - D:\se\Se_Project\Util\log.py - log.py[:54] - Exception: Don't find Boe, please check config
ERROR - 2021-01-28 11:14:06,931 - D:\se\Se_Project\Util\log.py - log.py[:54] -  Don't find Boe, Try again
ERROR - 2021-01-28 11:14:54,534 - D:\se\Se_Project\Util\log.py - log.py[:54] - 没有找到查询结果，--- try again ---
ERROR - 2021-01-28 11:15:08,361 - D:\se\Se_Project\Util\log.py - log.py[:54] - 没有找到查询结果，--- try again ---
ERROR - 2021-01-28 17:00:54,563 - D:\se\Se_Project\Util\log.py - log.py[:54] - 没有找到查询结果，--- try again ---
ERROR - 2021-01-28 17:00:57,555 - D:\se\Se_Project\Util\log.py - log.py[:54] - 没有找到查询结果，--- try again ---
ERROR - 2021-01-28 17:01:57,771 - D:\se\Se_Project\Util\log.py - log.py[:54] - 没有找到查询结果，--- try again ---
ERROR - 2021-01-29 14:30:17,889 - D:\se\Se_Project\Util\log.py - log.py[:54] - 没有找到查询结果，--- try again ---
ERROR - 2021-01-29 14:32:23,133 - D:\se\Se_Project\Util\log.py - log.py[:54] - 没有找到查询结果，--- try again ---
ERROR - 2021-01-29 14:47:01,968 - D:\se\Se_Project\Util\log.py - log.py[:54] - 没有找到查询结果，--- try again ---
ERROR - 2021-01-29 14:49:28,651 - D:\se\Se_Project\Util\log.py - log.py[:54] - 没有找到查询结果，--- try again ---
ERROR - 2021-01-29 14:49:44,085 - D:\se\Se_Project\Util\log.py - log.py[:54] - 没有找到查询结果，--- try again ---
ERROR - 2021-01-29 14:50:19,875 - D:\se\Se_Project\Util\log.py - log.py[:54] - 没有找到查询结果，--- try again ---
ERROR - 2021-01-29 14:50:36,575 - D:\se\Se_Project\Util\log.py - log.py[:54] - 没有找到查询结果，--- try again ---
ERROR - 2021-01-29 14:57:09,327 - D:\se\Se_Project\Util\log.py - log.py[:54] - 没有找到查询结果，--- try again ---
ERROR - 2021-01-29 15:08:52,106 - D:\se\Se_Project\Util\log.py - log.py[:54] - 没有找到查询结果，--- try again ---
ERROR - 2021-01-29 15:39:36,143 - D:\se\Se_Project\Util\log.py - log.py[:54] - 没有找到查询结果，--- try again ---
ERROR - 2021-01-29 15:40:32,693 - D:\se\Se_Project\Util\log.py - log.py[:54] - 没有找到查询结果，--- try again ---
ERROR - 2021-01-29 15:43:40,057 - D:\se\Se_Project\Util\log.py - log.py[:54] - 没有找到查询结果，--- try again ---
ERROR - 2021-01-29 15:58:32,847 - D:\se\Se_Project\Util\log.py - log.py[:54] - 没有找到查询结果，--- try again ---
ERROR - 2021-01-29 16:01:00,030 - D:\se\Se_Project\Util\log.py - log.py[:54] - 没有找到查询结果，--- try again ---
ERROR - 2021-01-29 16:06:32,952 - D:\se\Se_Project\Util\log.py - log.py[:54] - 没有找到查询结果，--- try again ---
ERROR - 2021-01-29 16:18:20,680 - D:\se\Se_Project\Util\log.py - log.py[:54] - 没有找到查询结果，--- try again ---
ERROR - 2021-01-29 16:22:23,656 - D:\se\Se_Project\Util\log.py - log.py[:54] - 没有找到查询结果，--- try again ---
ERROR - 2021-01-29 16:22:30,792 - D:\se\Se_Project\Util\log.py - log.py[:54] - 没有找到查询结果，--- try again ---
ERROR - 2021-01-29 16:23:21,787 - D:\se\Se_Project\Util\log.py - log.py[:54] - 没有找到查询结果，--- try again ---
ERROR - 2021-01-29 16:30:32,559 - D:\se\Se_Project\Util\log.py - log.py[:54] - 没有找到查询结果，--- try again ---
ERROR - 2021-01-29 16:31:19,021 - D:\se\Se_Project\Util\log.py - log.py[:54] - 没有找到查询结果，--- try again ---
ERROR - 2021-01-29 16:40:23,783 - D:\se\Se_Project\Util\log.py - log.py[:54] - 没有找到查询结果，--- try again ---
ERROR - 2021-01-29 16:42:20,828 - D:\se\Se_Project\Util\log.py - log.py[:54] - 没有找到查询结果，--- try again ---
ERROR - 2021-01-29 16:47:41,665 - D:\se\Se_Project\Util\log.py - log.py[:54] - 没有找到查询结果，--- try again ---
ERROR - 2021-01-29 16:49:13,083 - D:\se\Se_Project\Util\log.py - log.py[:54] - 没有找到查询结果，--- try again ---
ERROR - 2021-01-29 16:50:00,456 - D:\se\Se_Project\Util\log.py - log.py[:54] - 没有找到查询结果，--- try again ---
ERROR - 2021-01-29 16:50:40,046 - D:\se\Se_Project\Util\log.py - log.py[:54] - 没有找到查询结果，--- try again ---
ERROR - 2021-01-29 16:59:07,700 - D:\se\Se_Project\Util\log.py - log.py[:54] - 没有找到查询结果，--- try again ---
ERROR - 2021-01-29 17:00:08,260 - D:\se\Se_Project\Util\log.py - log.py[:54] - 没有找到查询结果，--- try again ---
ERROR - 2021-01-29 17:07:34,248 - D:\se\Se_Project\Util\log.py - log.py[:54] - 没有找到查询结果，--- try again ---
ERROR - 2021-01-29 17:08:36,149 - D:\se\Se_Project\Util\log.py - log.py[:54] - 没有找到查询结果，--- try again ---
ERROR - 2021-02-03 09:18:37,961 - D:\se\Se_Project\Util\log.py - log.py[:54] - 没有找到查询结果，--- try again ---
ERROR - 2021-02-03 09:21:45,203 - D:\se\Se_Project\Util\log.py - log.py[:54] - 没有找到查询结果，--- try again ---
ERROR - 2021-02-03 11:33:19,568 - D:\se\Se_Project\Util\log.py - log.py[:54] - 没有找到查询结果，--- try again ---
ERROR - 2021-02-03 11:33:26,980 - D:\se\Se_Project\Util\log.py - log.py[:54] - 没有找到查询结果，--- try again ---
ERROR - 2021-02-03 11:34:27,538 - D:\se\Se_Project\Util\log.py - log.py[:54] - 没有找到查询结果，--- try again ---
ERROR - 2021-02-03 11:47:48,063 - D:\se\Se_Project\Util\log.py - log.py[:54] - 没有找到查询结果，--- try again ---
ERROR - 2021-02-03 11:49:14,996 - D:\se\Se_Project\Util\log.py - log.py[:54] - 没有找到查询结果，--- try again ---
ERROR - 2021-02-03 11:50:17,380 - D:\se\Se_Project\Util\log.py - log.py[:54] - 没有找到查询结果，--- try again ---
ERROR - 2021-02-03 11:52:22,413 - D:\se\Se_Project\Util\log.py - log.py[:54] - 没有找到查询结果，--- try again ---
ERROR - 2021-02-03 11:53:21,616 - D:\se\Se_Project\Util\log.py - log.py[:54] - 没有找到查询结果，--- try again ---
ERROR - 2021-02-03 14:43:18,987 - D:\se\Se_Project\Util\log.py - log.py[:54] - 没有找到查询结果，--- try again ---
ERROR - 2021-02-03 14:44:08,019 - D:\se\Se_Project\Util\log.py - log.py[:54] - 没有找到查询结果，--- try again ---
ERROR - 2021-02-04 13:37:55,380 - D:\Pycharm\Se_Project\Util\log.py - log.py[:54] - 没有找到查询结果，--- try again ---
ERROR - 2021-02-04 13:39:49,957 - D:\Pycharm\Se_Project\Util\log.py - log.py[:54] - 没有找到查询结果，--- try again ---
ERROR - 2021-02-04 13:40:36,704 - D:\Pycharm\Se_Project\Util\log.py - log.py[:54] - 没有找到查询结果，--- try again ---
ERROR - 2021-02-04 13:42:21,435 - D:\Pycharm\Se_Project\Util\log.py - log.py[:54] - boeNum do not exist
ERROR - 2021-02-04 13:42:21,436 - D:\Pycharm\Se_Project\Util\log.py - log.py[:54] - 业务审批出现异常，异常信息为：<class 'Exception'>
ERROR - 2021-02-04 13:42:35,260 - D:\Pycharm\Se_Project\Util\log.py - log.py[:54] - 没有找到查询结果，--- try again ---
ERROR - 2021-02-04 13:42:39,589 - D:\Pycharm\Se_Project\Util\log.py - log.py[:54] - 没有找到查询结果，--- try again ---
ERROR - 2021-02-04 13:44:48,186 - D:\Pycharm\Se_Project\Util\log.py - log.py[:54] - 没有找到查询结果，--- try again ---
ERROR - 2021-02-04 13:47:16,699 - D:\Pycharm\Se_Project\Util\log.py - log.py[:54] - boeNum do not exist
ERROR - 2021-02-04 13:47:16,699 - D:\Pycharm\Se_Project\Util\log.py - log.py[:54] - 业务审批出现异常，异常信息为：<class 'Exception'>
ERROR - 2021-02-04 13:47:29,176 - D:\Pycharm\Se_Project\Util\log.py - log.py[:54] - 没有找到查询结果，--- try again ---
ERROR - 2021-02-04 13:47:33,255 - D:\Pycharm\Se_Project\Util\log.py - log.py[:54] - 没有找到查询结果，--- try again ---
ERROR - 2021-02-04 13:48:57,614 - D:\Pycharm\Se_Project\Util\log.py - log.py[:54] - 没有找到查询结果，--- try again ---
ERROR - 2021-02-04 13:49:07,521 - D:\Pycharm\Se_Project\Util\log.py - log.py[:54] - com.bstek.urule.RuleException: Node[1] not exist.
ERROR - 2021-02-18 13:54:05,397 - D:\se\Se_Project\Util\log.py - log.py[:54] - 没有找到查询结果，--- try again ---
ERROR - 2021-02-18 14:06:40,545 - D:\se\Se_Project\Util\log.py - log.py[:54] - 没有找到查询结果，--- try again ---
ERROR - 2021-02-18 14:07:02,386 - D:\se\Se_Project\Util\log.py - log.py[:54] - 没有找到查询结果，--- try again ---
ERROR - 2021-02-18 14:09:38,821 - D:\se\Se_Project\Util\log.py - log.py[:54] - 没有找到查询结果，--- try again ---
ERROR - 2021-02-18 14:11:17,378 - D:\se\Se_Project\Util\log.py - log.py[:54] - 没有找到查询结果，--- try again ---
ERROR - 2021-02-18 14:17:08,876 - D:\se\Se_Project\Util\log.py - log.py[:54] - 没有找到查询结果，--- try again ---
ERROR - 2021-02-18 14:20:30,650 - D:\se\Se_Project\Util\log.py - log.py[:54] - 没有找到查询结果，--- try again ---
ERROR - 2021-02-18 14:21:06,934 - D:\se\Se_Project\Util\log.py - log.py[:54] - 没有找到查询结果，--- try again ---
ERROR - 2021-03-01 14:58:20,998 - D:\se\Se_Project\Util\log.py - log.py[:54] - 没有找到查询结果，--- try again ---
ERROR - 2021-03-01 14:59:06,655 - D:\se\Se_Project\Util\log.py - log.py[:54] - 没有找到查询结果，--- try again ---
ERROR - 2021-03-01 15:14:19,786 - D:\se\Se_Project\Util\log.py - log.py[:54] - 没有找到查询结果，--- try again ---
ERROR - 2021-03-01 15:15:09,279 - D:\se\Se_Project\Util\log.py - log.py[:54] - 没有找到查询结果，--- try again ---
ERROR - 2021-03-04 10:23:21,291 - D:\se\Se_Project\Util\log.py - log.py[:54] - 出现异常，异常信息为：<class 'selenium.common.exceptions.NoSuchElementException'>
ERROR - 2021-03-04 10:24:28,041 - D:\se\Se_Project\Util\log.py - log.py[:54] - 出现异常，异常信息为：<class 'selenium.common.exceptions.NoSuchElementException'>
ERROR - 2021-03-04 10:24:51,412 - D:\se\Se_Project\Util\log.py - log.py[:54] - 出现异常，异常信息为：<class 'selenium.common.exceptions.NoSuchElementException'>
ERROR - 2021-03-04 10:25:16,017 - D:\se\Se_Project\Util\log.py - log.py[:54] - 出现异常，异常信息为：<class 'selenium.common.exceptions.NoSuchElementException'>
ERROR - 2021-03-04 10:30:08,129 - D:\se\Se_Project\Util\log.py - log.py[:54] - 出现异常，异常信息为：<class 'selenium.common.exceptions.TimeoutException'>
ERROR - 2021-03-04 10:30:56,816 - D:\se\Se_Project\Util\log.py - log.py[:54] - 出现异常，异常信息为：<class 'selenium.common.exceptions.TimeoutException'>
ERROR - 2021-03-04 10:31:46,718 - D:\se\Se_Project\Util\log.py - log.py[:54] - 出现异常，异常信息为：<class 'selenium.common.exceptions.TimeoutException'>
ERROR - 2021-03-04 10:40:41,500 - D:\se\Se_Project\Util\log.py - log.py[:54] - 没有找到查询结果，--- try again ---
ERROR - 2021-03-04 10:41:41,940 - D:\se\Se_Project\Util\log.py - log.py[:54] - 没有找到查询结果，--- try again ---
ERROR - 2021-03-04 10:43:00,982 - D:\se\Se_Project\Util\log.py - log.py[:54] - 没有找到查询结果，--- try again ---
ERROR - 2021-03-04 10:44:01,340 - D:\se\Se_Project\Util\log.py - log.py[:54] - 没有找到查询结果，--- try again ---
ERROR - 2021-03-04 10:45:23,463 - D:\se\Se_Project\Util\log.py - log.py[:54] - 没有找到查询结果，--- try again ---
ERROR - 2021-03-04 10:46:26,450 - D:\se\Se_Project\Util\log.py - log.py[:54] - 没有找到查询结果，--- try again ---
ERROR - 2021-03-04 11:02:12,078 - D:\se\Se_Project\Util\log.py - log.py[:54] - 出现异常，异常信息为：<class 'selenium.common.exceptions.NoSuchElementException'>
ERROR - 2021-03-04 11:35:14,367 - D:\se\Se_Project\Util\log.py - log.py[:54] - 出现异常，异常信息为：<class 'selenium.common.exceptions.NoSuchElementException'>
ERROR - 2021-03-04 13:58:19,705 - D:\se\Se_Project\Util\log.py - log.py[:54] - 没有找到查询结果，--- try again ---
ERROR - 2021-03-04 13:58:28,316 - D:\se\Se_Project\Util\log.py - log.py[:54] - 单据XY-BX2103040085需要生成凭证，请刷新凭证后重试
ERROR - 2021-03-04 14:03:28,344 - D:\se\Se_Project\Util\log.py - log.py[:54] - 没有找到查询结果，--- try again ---
ERROR - 2021-03-04 14:03:36,874 - D:\se\Se_Project\Util\log.py - log.py[:54] - 发票号码50112611查验失败，是否确认审批通过？
ERROR - 2021-03-04 14:08:43,107 - D:\se\Se_Project\Util\log.py - log.py[:54] - 没有找到查询结果，--- try again ---
ERROR - 2021-03-04 14:09:42,918 - D:\se\Se_Project\Util\log.py - log.py[:54] - 没有找到查询结果，--- try again ---
ERROR - 2021-03-04 14:19:55,250 - D:\se\Se_Project\Util\log.py - log.py[:54] - 出现异常，异常信息为：<class 'selenium.common.exceptions.TimeoutException'>
ERROR - 2021-03-04 14:30:06,131 - D:\se\Se_Project\Util\log.py - log.py[:54] - 出现异常，异常信息为：<class 'selenium.common.exceptions.ElementClickInterceptedException'>
ERROR - 2021-03-04 14:31:14,375 - D:\se\Se_Project\Util\log.py - log.py[:54] - 业务审批出现异常，异常信息为：<class 'selenium.common.exceptions.TimeoutException'>
ERROR - 2021-03-04 15:08:39,758 - D:\se\Se_Project\Util\log.py - log.py[:54] - Exception: Don't find Boe, please check config
ERROR - 2021-03-04 15:08:40,761 - D:\se\Se_Project\Util\log.py - log.py[:54] -  Don't find Boe, Try again
ERROR - 2021-03-04 15:09:02,391 - D:\se\Se_Project\Util\log.py - log.py[:54] - 出现异常，异常信息为：<class 'selenium.common.exceptions.ElementClickInterceptedException'>
ERROR - 2021-03-04 15:09:56,058 - D:\se\Se_Project\Util\log.py - log.py[:54] - 出现异常，异常信息为：<class 'selenium.common.exceptions.TimeoutException'>
ERROR - 2021-03-04 15:11:21,678 - D:\se\Se_Project\Util\log.py - log.py[:54] - 出现异常，异常信息为：<class 'selenium.common.exceptions.TimeoutException'>
ERROR - 2021-03-04 15:15:33,859 - D:\se\Se_Project\Util\log.py - log.py[:54] - 出现异常，异常信息为：<class 'selenium.common.exceptions.StaleElementReferenceException'>
ERROR - 2021-03-04 15:24:20,754 - D:\se\Se_Project\Util\log.py - log.py[:54] - 出现异常，异常信息为：<class 'selenium.common.exceptions.ElementClickInterceptedException'>
ERROR - 2021-03-04 15:36:43,556 - D:\se\Se_Project\Util\log.py - log.py[:54] - 出现异常，异常信息为：<class 'selenium.common.exceptions.ElementClickInterceptedException'>
ERROR - 2021-03-04 15:41:40,761 - D:\se\Se_Project\Util\log.py - log.py[:54] - 出现异常，异常信息为：<class 'selenium.common.exceptions.TimeoutException'>
ERROR - 2021-03-04 15:51:02,742 - D:\se\Se_Project\Util\log.py - log.py[:54] - 出现异常，异常信息为：<class 'selenium.common.exceptions.NoSuchElementException'>
ERROR - 2021-03-04 15:51:55,104 - D:\se\Se_Project\Util\log.py - log.py[:54] - 没有找到查询结果，--- try again ---
ERROR - 2021-03-04 15:55:57,484 - D:\se\Se_Project\Util\log.py - log.py[:54] - 没有找到查询结果，--- try again ---
ERROR - 2021-03-04 15:59:02,782 - D:\se\Se_Project\Util\log.py - log.py[:54] - 出现异常，异常信息为：<class 'selenium.common.exceptions.NoSuchElementException'>
ERROR - 2021-03-04 15:59:53,500 - D:\se\Se_Project\Util\log.py - log.py[:54] - 没有找到查询结果，--- try again ---
ERROR - 2021-03-04 16:09:36,180 - D:\se\Se_Project\Util\log.py - log.py[:54] - 出现异常，异常信息为：<class 'selenium.common.exceptions.ElementClickInterceptedException'>
ERROR - 2021-03-04 16:38:27,202 - D:\se\Se_Project\Util\log.py - log.py[:54] - 没有找到查询结果，--- try again ---
ERROR - 2021-03-04 16:48:56,178 - D:\se\Se_Project\Util\log.py - log.py[:54] - 没有找到查询结果，--- try again ---
ERROR - 2021-03-04 16:49:58,536 - D:\se\Se_Project\Util\log.py - log.py[:54] - 没有找到查询结果，--- try again ---
ERROR - 2021-03-04 16:59:17,214 - D:\se\Se_Project\Util\log.py - log.py[:54] - 出现异常，异常信息为：<class 'selenium.common.exceptions.StaleElementReferenceException'>
ERROR - 2021-03-04 17:01:44,600 - D:\se\Se_Project\Util\log.py - log.py[:54] - 出现异常，异常信息为：<class 'selenium.common.exceptions.TimeoutException'>
ERROR - 2021-03-04 17:03:56,578 - D:\se\Se_Project\Util\log.py - log.py[:54] - 出现异常，异常信息为：<class 'selenium.common.exceptions.TimeoutException'>
ERROR - 2021-03-04 17:13:36,730 - D:\se\Se_Project\Util\log.py - log.py[:54] - 没有找到查询结果，--- try again ---
ERROR - 2021-03-04 17:14:36,061 - D:\se\Se_Project\Util\log.py - log.py[:54] - 没有找到查询结果，--- try again ---
ERROR - 2021-03-04 17:18:25,313 - D:\se\Se_Project\Util\log.py - log.py[:54] - 出现异常，异常信息为：<class 'selenium.common.exceptions.NoSuchWindowException'>
ERROR - 2021-03-04 17:27:59,678 - D:\se\Se_Project\Util\log.py - log.py[:54] - 没有找到查询结果，--- try again ---
ERROR - 2021-03-04 17:32:04,189 - D:\se\Se_Project\Util\log.py - log.py[:54] - 没有找到查询结果，--- try again ---
ERROR - 2021-03-04 17:32:09,052 - D:\se\Se_Project\Util\log.py - log.py[:54] - 没有找到查询结果，--- try again ---
ERROR - 2021-03-04 17:34:55,542 - D:\se\Se_Project\Util\log.py - log.py[:54] - 没有找到查询结果，--- try again ---
ERROR - 2021-03-04 17:35:55,915 - D:\se\Se_Project\Util\log.py - log.py[:54] - 没有找到查询结果，--- try again ---
ERROR - 2021-03-04 19:08:54,670 - D:\se\Se_Project\Util\log.py - log.py[:54] - 没有找到查询结果，--- try again ---
ERROR - 2021-03-04 19:13:55,320 - D:\se\Se_Project\Util\log.py - log.py[:54] - 没有找到查询结果，--- try again ---
ERROR - 2021-03-04 19:14:05,501 - D:\se\Se_Project\Util\log.py - log.py[:54] - 保存失败
ERROR - 2021-03-04 19:15:49,187 - D:\se\Se_Project\Util\log.py - log.py[:54] - 没有找到查询结果，--- try again ---
ERROR - 2021-03-04 19:20:51,661 - D:\se\Se_Project\Util\log.py - log.py[:54] - 出现异常，异常信息为：<class 'IndexError'>
ERROR - 2021-03-04 19:22:35,107 - D:\se\Se_Project\Util\log.py - log.py[:54] - 没有找到查询结果，--- try again ---
ERROR - 2021-03-04 19:22:52,796 - D:\se\Se_Project\Util\log.py - log.py[:54] - 单据XY-BX2103040175需要生成凭证，请刷新凭证后重试
ERROR - 2021-03-04 19:26:53,516 - D:\se\Se_Project\Util\log.py - log.py[:54] - 没有找到查询结果，--- try again ---
ERROR - 2021-03-04 19:27:40,981 - D:\se\Se_Project\Util\log.py - log.py[:54] - 没有找到查询结果，--- try again ---
ERROR - 2021-03-04 19:54:19,344 - D:\se\Se_Project\Util\log.py - log.py[:54] - 没有找到查询结果，--- try again ---
ERROR - 2021-03-04 19:55:20,272 - D:\se\Se_Project\Util\log.py - log.py[:54] - 没有找到查询结果，--- try again ---
ERROR - 2021-03-04 20:02:45,667 - D:\se\Se_Project\Util\log.py - log.py[:54] - 没有找到查询结果，--- try again ---
ERROR - 2021-03-04 20:13:43,416 - D:\se\Se_Project\Util\log.py - log.py[:54] - 出现异常，异常信息为：<class 'selenium.common.exceptions.NoSuchElementException'>
ERROR - 2021-03-04 20:14:45,172 - D:\se\Se_Project\Util\log.py - log.py[:54] - 业务审批出现异常，异常信息为：<class 'selenium.common.exceptions.TimeoutException'>
ERROR - 2021-03-04 20:15:03,246 - D:\se\Se_Project\Util\log.py - log.py[:54] - 没有找到查询结果，--- try again ---
ERROR - 2021-03-04 20:17:23,412 - D:\se\Se_Project\Util\log.py - log.py[:54] - 没有找到查询结果，--- try again ---
ERROR - 2021-03-04 20:25:05,357 - D:\se\Se_Project\Util\log.py - log.py[:54] - 没有找到查询结果，--- try again ---
ERROR - 2021-03-04 20:25:09,616 - D:\se\Se_Project\Util\log.py - log.py[:54] - 没有找到查询结果，--- try again ---
ERROR - 2021-03-04 20:26:25,275 - D:\se\Se_Project\Util\log.py - log.py[:54] - 没有找到查询结果，--- try again ---
ERROR - 2021-03-04 20:27:25,604 - D:\se\Se_Project\Util\log.py - log.py[:54] - 没有找到查询结果，--- try again ---
ERROR - 2021-03-05 08:44:22,819 - D:\se\Se_Project\Util\log.py - log.py[:54] - 没有找到查询结果，--- try again ---
ERROR - 2021-03-05 08:45:57,541 - D:\se\Se_Project\Util\log.py - log.py[:54] - 没有找到查询结果，--- try again ---
ERROR - 2021-03-05 08:47:41,860 - D:\se\Se_Project\Util\log.py - log.py[:54] - 没有找到查询结果，--- try again ---
ERROR - 2021-03-05 09:08:05,405 - D:\se\Se_Project\Util\log.py - log.py[:54] - 没有找到查询结果，--- try again ---
ERROR - 2021-03-05 09:12:22,382 - D:\se\Se_Project\Util\log.py - log.py[:54] - 没有找到查询结果，--- try again ---
ERROR - 2021-03-05 09:13:22,253 - D:\se\Se_Project\Util\log.py - log.py[:54] - 没有找到查询结果，--- try again ---
ERROR - 2021-03-05 09:50:07,810 - D:\se\Se_Project\Util\log.py - log.py[:54] - 出现异常，异常信息为：<class 'selenium.common.exceptions.NoSuchElementException'>
ERROR - 2021-03-05 09:51:20,184 - D:\se\Se_Project\Util\log.py - log.py[:54] - 没有找到查询结果，--- try again ---
ERROR - 2021-03-05 09:51:28,160 - D:\se\Se_Project\Util\log.py - log.py[:54] - 单据XY-BX2103050015需要生成凭证，请刷新凭证后重试
ERROR - 2021-03-05 09:57:02,500 - D:\se\Se_Project\Util\log.py - log.py[:54] - 业务审批出现异常，异常信息为：<class 'selenium.common.exceptions.TimeoutException'>
ERROR - 2021-03-05 09:58:14,135 - D:\se\Se_Project\Util\log.py - log.py[:54] - 没有找到查询结果，--- try again ---
ERROR - 2021-03-05 10:15:05,291 - D:\se\Se_Project\Util\log.py - log.py[:54] - 出现异常，异常信息为：<class 'selenium.common.exceptions.TimeoutException'>
ERROR - 2021-03-05 10:15:53,554 - D:\se\Se_Project\Util\log.py - log.py[:54] - 出现异常，异常信息为：<class 'selenium.common.exceptions.TimeoutException'>
ERROR - 2021-03-05 10:16:35,429 - D:\se\Se_Project\Util\log.py - log.py[:54] - 出现异常，异常信息为：<class 'selenium.common.exceptions.TimeoutException'>
ERROR - 2021-03-05 10:17:39,078 - D:\se\Se_Project\Util\log.py - log.py[:54] - 没有找到查询结果，--- try again ---
ERROR - 2021-03-05 10:18:14,661 - D:\se\Se_Project\Util\log.py - log.py[:54] - 没有找到查询结果，--- try again ---
ERROR - 2021-03-05 10:30:06,703 - D:\se\Se_Project\Util\log.py - log.py[:54] - 业务审批出现异常，异常信息为：<class 'selenium.common.exceptions.NoSuchWindowException'>
ERROR - 2021-03-05 10:31:47,443 - D:\se\Se_Project\Util\log.py - log.py[:54] - 出现异常，异常信息为：<class 'AttributeError'>
ERROR - 2021-03-05 10:59:51,479 - D:\se\Se_Project\Util\log.py - log.py[:54] - 没有找到查询结果，--- try again ---
ERROR - 2021-03-05 11:01:08,711 - D:\se\Se_Project\Util\log.py - log.py[:54] - 没有找到查询结果，--- try again ---
ERROR - 2021-03-05 11:02:09,680 - D:\se\Se_Project\Util\log.py - log.py[:54] - 没有找到查询结果，--- try again ---
ERROR - 2021-03-05 11:10:07,661 - D:\se\Se_Project\Util\log.py - log.py[:54] - 没有找到查询结果，--- try again ---
ERROR - 2021-03-05 11:10:15,126 - D:\se\Se_Project\Util\log.py - log.py[:54] - 没有找到查询结果，--- try again ---
ERROR - 2021-03-05 11:11:19,920 - D:\se\Se_Project\Util\log.py - log.py[:54] - 没有找到查询结果，--- try again ---
ERROR - 2021-03-05 11:15:32,408 - D:\se\Se_Project\Util\log.py - log.py[:54] - 没有找到查询结果，--- try again ---
ERROR - 2021-03-05 11:16:31,976 - D:\se\Se_Project\Util\log.py - log.py[:54] - 没有找到查询结果，--- try again ---
ERROR - 2021-03-05 11:40:32,313 - D:\se\Se_Project\Util\log.py - log.py[:54] - 没有找到查询结果，--- try again ---
ERROR - 2021-03-05 11:40:41,542 - D:\se\Se_Project\Util\log.py - log.py[:54] - 单据XY-BX2103050077需要生成凭证，请刷新凭证后重试
ERROR - 2021-03-05 11:44:09,899 - D:\se\Se_Project\Util\log.py - log.py[:54] - 没有找到查询结果，--- try again ---
ERROR - 2021-03-05 11:45:15,498 - D:\se\Se_Project\Util\log.py - log.py[:54] - 没有找到查询结果，--- try again ---
ERROR - 2021-03-05 13:49:49,926 - D:\se\Se_Project\Util\log.py - log.py[:54] - 没有找到查询结果，--- try again ---
ERROR - 2021-03-05 14:00:25,105 - D:\se\Se_Project\Util\log.py - log.py[:54] - 没有找到查询结果，--- try again ---
ERROR - 2021-03-05 14:03:49,597 - D:\se\Se_Project\Util\log.py - log.py[:54] - 没有找到查询结果，--- try again ---
ERROR - 2021-03-05 14:04:50,281 - D:\se\Se_Project\Util\log.py - log.py[:54] - 没有找到查询结果，--- try again ---
ERROR - 2021-03-05 14:11:05,334 - D:\se\Se_Project\Util\log.py - log.py[:54] - 没有找到查询结果，--- try again ---
ERROR - 2021-03-05 14:12:06,650 - D:\se\Se_Project\Util\log.py - log.py[:54] - 没有找到查询结果，--- try again ---
ERROR - 2021-03-05 15:13:20,814 - D:\se\Se_Project\Util\log.py - log.py[:54] - 没有找到查询结果，--- try again ---
ERROR - 2021-03-05 15:13:28,177 - D:\se\Se_Project\Util\log.py - log.py[:54] - 单据XY-BX2103050130需要生成凭证，请刷新凭证后重试
ERROR - 2021-03-05 15:20:45,129 - D:\se\Se_Project\Util\log.py - log.py[:54] - 业务审批出现异常，异常信息为：<class 'selenium.common.exceptions.NoSuchWindowException'>
ERROR - 2021-03-05 17:21:15,796 - D:\se\Se_Project\Util\log.py - log.py[:54] - 出现异常，异常信息为：<class 'selenium.common.exceptions.TimeoutException'>
ERROR - 2021-03-05 17:22:39,486 - D:\se\Se_Project\Util\log.py - log.py[:54] - 出现异常，异常信息为：<class 'selenium.common.exceptions.TimeoutException'>
ERROR - 2021-03-05 17:23:35,539 - D:\se\Se_Project\Util\log.py - log.py[:54] - 出现异常，异常信息为：<class 'selenium.common.exceptions.TimeoutException'>
ERROR - 2021-03-05 17:24:29,638 - D:\se\Se_Project\Util\log.py - log.py[:54] - 出现异常，异常信息为：<class 'selenium.common.exceptions.NoSuchElementException'>
ERROR - 2021-03-05 17:32:47,834 - D:\se\Se_Project\Util\log.py - log.py[:54] - 业务审批出现异常，异常信息为：<class 'selenium.common.exceptions.TimeoutException'>
ERROR - 2021-03-05 17:33:12,249 - D:\se\Se_Project\Util\log.py - log.py[:54] - 出现异常，异常信息为：<class 'selenium.common.exceptions.TimeoutException'>
ERROR - 2021-03-05 17:34:57,801 - D:\se\Se_Project\Util\log.py - log.py[:54] - 出现异常，异常信息为：<class 'selenium.common.exceptions.TimeoutException'>
ERROR - 2021-03-05 17:36:02,857 - D:\se\Se_Project\Util\log.py - log.py[:54] - 出现异常，异常信息为：<class 'selenium.common.exceptions.TimeoutException'>
ERROR - 2021-03-05 18:49:52,077 - D:\se\Se_Project\Util\log.py - log.py[:54] - 没有找到查询结果，--- try again ---
ERROR - 2021-03-05 18:50:00,658 - D:\se\Se_Project\Util\log.py - log.py[:54] - 没有找到查询结果，--- try again ---
ERROR - 2021-03-05 18:50:27,357 - D:\se\Se_Project\Util\log.py - log.py[:54] - Exception: Don't find Boe, please check config
ERROR - 2021-03-05 18:50:27,358 - D:\se\Se_Project\Util\log.py - log.py[:54] -  Don't find Boe, Try again
ERROR - 2021-03-05 18:50:28,358 - D:\se\Se_Project\Util\log.py - log.py[:54] - 出现异常，异常信息为：<class 'AttributeError'>
ERROR - 2021-03-05 18:51:45,689 - D:\se\Se_Project\Util\log.py - log.py[:54] - 没有找到查询结果，--- try again ---
ERROR - 2021-03-05 18:52:48,118 - D:\se\Se_Project\Util\log.py - log.py[:54] - 没有找到查询结果，--- try again ---
ERROR - 2021-03-05 18:54:26,939 - D:\se\Se_Project\Util\log.py - log.py[:54] - 没有找到查询结果，--- try again ---
ERROR - 2021-03-05 18:55:27,223 - D:\se\Se_Project\Util\log.py - log.py[:54] - 没有找到查询结果，--- try again ---
ERROR - 2021-03-05 18:56:47,514 - D:\se\Se_Project\Util\log.py - log.py[:54] - 没有找到查询结果，--- try again ---
ERROR - 2021-03-05 18:56:56,551 - D:\se\Se_Project\Util\log.py - log.py[:54] - 没有找到查询结果，--- try again ---
ERROR - 2021-03-05 18:58:00,220 - D:\se\Se_Project\Util\log.py - log.py[:54] - 没有找到查询结果，--- try again ---
ERROR - 2021-03-05 18:59:22,143 - D:\se\Se_Project\Util\log.py - log.py[:54] - 没有找到查询结果，--- try again ---
ERROR - 2021-03-05 19:00:26,255 - D:\se\Se_Project\Util\log.py - log.py[:54] - 没有找到查询结果，--- try again ---
ERROR - 2021-03-05 19:01:31,133 - D:\se\Se_Project\Util\log.py - log.py[:54] - 出现异常，异常信息为：<class 'selenium.common.exceptions.NoSuchElementException'>
ERROR - 2021-03-05 19:02:21,794 - D:\se\Se_Project\Util\log.py - log.py[:54] - 出现异常，异常信息为：<class 'selenium.common.exceptions.NoSuchElementException'>
ERROR - 2021-03-05 19:04:28,486 - D:\se\Se_Project\Util\log.py - log.py[:54] - Exception: Don't find Boe, please check config
ERROR - 2021-03-05 19:04:29,486 - D:\se\Se_Project\Util\log.py - log.py[:54] -  Don't find Boe, Try again
ERROR - 2021-03-05 19:04:43,679 - D:\se\Se_Project\Util\log.py - log.py[:54] - 出现异常，异常信息为：<class 'selenium.common.exceptions.NoSuchElementException'>
ERROR - 2021-03-05 19:05:52,043 - D:\se\Se_Project\Util\log.py - log.py[:54] - Exception: Don't find Boe, please check config
ERROR - 2021-03-05 19:05:53,043 - D:\se\Se_Project\Util\log.py - log.py[:54] -  Don't find Boe, Try again
ERROR - 2021-03-05 19:06:53,584 - D:\se\Se_Project\Util\log.py - log.py[:54] - 没有找到查询结果，--- try again ---
ERROR - 2021-03-05 19:08:54,244 - D:\se\Se_Project\Util\log.py - log.py[:54] - 没有找到查询结果，--- try again ---
ERROR - 2021-03-05 19:09:02,391 - D:\se\Se_Project\Util\log.py - log.py[:54] - 没有找到查询结果，--- try again ---
ERROR - 2021-03-05 19:10:05,974 - D:\se\Se_Project\Util\log.py - log.py[:54] - 没有找到查询结果，--- try again ---
ERROR - 2021-03-05 19:10:29,537 - D:\se\Se_Project\Util\log.py - log.py[:54] - Exception: Don't find Boe, please check config
ERROR - 2021-03-05 19:10:30,538 - D:\se\Se_Project\Util\log.py - log.py[:54] -  Don't find Boe, Try again
ERROR - 2021-03-05 19:11:29,614 - D:\se\Se_Project\Util\log.py - log.py[:54] - 没有找到查询结果，--- try again ---
ERROR - 2021-03-05 19:11:37,971 - D:\se\Se_Project\Util\log.py - log.py[:54] - 没有找到查询结果，--- try again ---
ERROR - 2021-03-05 19:12:38,801 - D:\se\Se_Project\Util\log.py - log.py[:54] - 没有找到查询结果，--- try again ---
ERROR - 2021-03-05 19:13:47,069 - D:\se\Se_Project\Util\log.py - log.py[:54] - 出现异常，异常信息为：<class 'selenium.common.exceptions.TimeoutException'>
ERROR - 2021-03-05 19:21:05,495 - D:\se\Se_Project\Util\log.py - log.py[:54] - 没有找到查询结果，--- try again ---
ERROR - 2021-03-05 19:22:11,512 - D:\se\Se_Project\Util\log.py - log.py[:54] - 没有找到查询结果，--- try again ---
ERROR - 2021-03-05 19:22:35,215 - D:\se\Se_Project\Util\log.py - log.py[:54] - Exception: Don't find Boe, please check config
ERROR - 2021-03-05 19:22:36,216 - D:\se\Se_Project\Util\log.py - log.py[:54] -  Don't find Boe, Try again
ERROR - 2021-03-05 19:22:47,275 - D:\se\Se_Project\Util\log.py - log.py[:54] - 出现异常，异常信息为：<class 'selenium.common.exceptions.NoSuchElementException'>
ERROR - 2021-03-05 19:26:11,364 - D:\se\Se_Project\Util\log.py - log.py[:54] - 出现异常，异常信息为：<class 'selenium.common.exceptions.TimeoutException'>
ERROR - 2021-03-05 19:27:51,906 - D:\se\Se_Project\Util\log.py - log.py[:54] - Exception: Don't find Boe, please check config
ERROR - 2021-03-05 19:27:52,907 - D:\se\Se_Project\Util\log.py - log.py[:54] -  Don't find Boe, Try again
ERROR - 2021-03-05 19:31:07,797 - D:\se\Se_Project\Util\log.py - log.py[:54] - Exception: Don't find Boe, please check config
ERROR - 2021-03-05 19:31:08,797 - D:\se\Se_Project\Util\log.py - log.py[:54] -  Don't find Boe, Try again
ERROR - 2021-03-05 19:39:28,337 - D:\se\Se_Project\Util\log.py - log.py[:54] - 没有找到查询结果，--- try again ---
ERROR - 2021-03-05 19:39:54,618 - D:\se\Se_Project\Util\log.py - log.py[:54] - Exception: Don't find Boe, please check config
ERROR - 2021-03-05 19:39:55,620 - D:\se\Se_Project\Util\log.py - log.py[:54] -  Don't find Boe, Try again
ERROR - 2021-03-05 19:40:03,095 - D:\se\Se_Project\Util\log.py - log.py[:54] - 出现异常，异常信息为：<class 'selenium.common.exceptions.NoSuchElementException'>
ERROR - 2021-03-05 19:40:30,117 - D:\se\Se_Project\Util\log.py - log.py[:54] - Exception: Don't find Boe, please check config
ERROR - 2021-03-05 19:40:31,118 - D:\se\Se_Project\Util\log.py - log.py[:54] -  Don't find Boe, Try again
ERROR - 2021-03-05 19:41:21,277 - D:\se\Se_Project\Util\log.py - log.py[:54] - 没有找到查询结果，--- try again ---
ERROR - 2021-03-05 19:42:23,185 - D:\se\Se_Project\Util\log.py - log.py[:54] - 没有找到查询结果，--- try again ---
ERROR - 2021-03-05 19:42:50,593 - D:\se\Se_Project\Util\log.py - log.py[:54] - Exception: Don't find Boe, please check config
ERROR - 2021-03-05 19:42:51,593 - D:\se\Se_Project\Util\log.py - log.py[:54] -  Don't find Boe, Try again
ERROR - 2021-03-05 19:43:13,155 - D:\se\Se_Project\Util\log.py - log.py[:54] - 出现异常，异常信息为：<class 'selenium.common.exceptions.TimeoutException'>
ERROR - 2021-03-05 19:47:27,911 - D:\se\Se_Project\Util\log.py - log.py[:54] - 业务审批出现异常，异常信息为：<class 'selenium.common.exceptions.NoSuchWindowException'>
ERROR - 2021-03-05 19:54:45,611 - D:\se\Se_Project\Util\log.py - log.py[:54] - Exception: Don't find Boe, please check config
ERROR - 2021-03-05 19:54:46,612 - D:\se\Se_Project\Util\log.py - log.py[:54] -  Don't find Boe, Try again
ERROR - 2021-03-05 19:56:54,199 - D:\se\Se_Project\Util\log.py - log.py[:54] - Exception: Don't find Boe, please check config
ERROR - 2021-03-05 19:56:55,199 - D:\se\Se_Project\Util\log.py - log.py[:54] -  Don't find Boe, Try again
ERROR - 2021-03-05 19:58:29,575 - D:\se\Se_Project\Util\log.py - log.py[:54] - 出现异常，异常信息为：<class 'selenium.common.exceptions.WebDriverException'>
ERROR - 2021-03-05 19:59:54,062 - D:\se\Se_Project\Util\log.py - log.py[:54] - 业务审批出现异常，异常信息为：<class 'AttributeError'>
ERROR - 2021-03-05 20:01:48,067 - D:\se\Se_Project\Util\log.py - log.py[:54] - 没有找到查询结果，--- try again ---
ERROR - 2021-03-05 20:02:19,414 - D:\se\Se_Project\Util\log.py - log.py[:54] - 出现异常，异常信息为：<class 'selenium.common.exceptions.NoSuchWindowException'>
ERROR - 2021-03-05 20:02:39,116 - D:\se\Se_Project\Util\log.py - log.py[:54] - Exception: Don't find Boe, please check config
ERROR - 2021-03-05 20:02:40,116 - D:\se\Se_Project\Util\log.py - log.py[:54] -  Don't find Boe, Try again
ERROR - 2021-03-05 20:03:30,050 - D:\se\Se_Project\Util\log.py - log.py[:54] - 没有找到查询结果，--- try again ---
ERROR - 2021-03-05 20:04:32,085 - D:\se\Se_Project\Util\log.py - log.py[:54] - 没有找到查询结果，--- try again ---
ERROR - 2021-03-05 20:05:46,374 - D:\se\Se_Project\Util\log.py - log.py[:54] - 没有找到查询结果，--- try again ---
ERROR - 2021-03-05 20:05:55,272 - D:\se\Se_Project\Util\log.py - log.py[:54] - 没有找到查询结果，--- try again ---
ERROR - 2021-03-05 20:06:56,946 - D:\se\Se_Project\Util\log.py - log.py[:54] - 没有找到查询结果，--- try again ---
ERROR - 2021-03-05 22:57:35,793 - D:\se\Se_Project\Util\log.py - log.py[:54] - 出现异常，异常信息为：<class 'selenium.common.exceptions.NoSuchWindowException'>
ERROR - 2021-03-05 23:18:30,684 - D:\se\Se_Project\Util\log.py - log.py[:54] - 没有找到查询结果，--- try again ---
ERROR - 2021-03-05 23:19:03,171 - D:\se\Se_Project\Util\log.py - log.py[:54] - 出现异常，异常信息为：<class 'selenium.common.exceptions.NoSuchElementException'>
ERROR - 2021-03-05 23:20:24,962 - D:\se\Se_Project\Util\log.py - log.py[:54] - 没有找到查询结果，--- try again ---
ERROR - 2021-03-05 23:38:28,251 - D:\se\Se_Project\Util\log.py - log.py[:54] - 没有找到查询结果，--- try again ---
ERROR - 2021-03-05 23:38:57,158 - D:\se\Se_Project\Util\log.py - log.py[:54] - 出现异常，异常信息为：<class 'selenium.common.exceptions.NoSuchElementException'>
ERROR - 2021-03-05 23:40:11,398 - D:\se\Se_Project\Util\log.py - log.py[:54] - 没有找到查询结果，--- try again ---
ERROR - 2021-03-05 23:41:14,079 - D:\se\Se_Project\Util\log.py - log.py[:54] - 没有找到查询结果，--- try again ---
ERROR - 2021-03-05 23:41:58,926 - D:\se\Se_Project\Util\log.py - log.py[:54] - 出现异常，异常信息为：<class 'selenium.common.exceptions.ElementNotInteractableException'>
ERROR - 2021-03-05 23:43:25,075 - D:\se\Se_Project\Util\log.py - log.py[:54] - 没有找到查询结果，--- try again ---
ERROR - 2021-03-05 23:43:33,690 - D:\se\Se_Project\Util\log.py - log.py[:54] - 没有找到查询结果，--- try again ---
ERROR - 2021-03-05 23:47:29,394 - D:\se\Se_Project\Util\log.py - log.py[:54] - 没有找到查询结果，--- try again ---
ERROR - 2021-03-05 23:48:30,678 - D:\se\Se_Project\Util\log.py - log.py[:54] - 没有找到查询结果，--- try again ---
ERROR - 2021-03-05 23:50:46,317 - D:\se\Se_Project\Util\log.py - log.py[:54] - 出现异常，异常信息为：<class 'selenium.common.exceptions.StaleElementReferenceException'>
ERROR - 2021-03-05 23:54:30,742 - D:\se\Se_Project\Util\log.py - log.py[:54] - 没有找到查询结果，--- try again ---
ERROR - 2021-03-05 23:54:39,881 - D:\se\Se_Project\Util\log.py - log.py[:54] - 没有找到查询结果，--- try again ---
ERROR - 2021-03-05 23:54:54,689 - D:\se\Se_Project\Util\log.py - log.py[:54] - 开票金额必须与票据金额相等
ERROR - 2021-03-06 01:55:16,864 - D:\se\Se_Project\Util\log.py - log.py[:54] - 出现异常，异常信息为：<class 'selenium.common.exceptions.NoSuchElementException'>
ERROR - 2021-03-06 01:56:44,808 - D:\se\Se_Project\Util\log.py - log.py[:54] - 没有找到查询结果，--- try again ---
ERROR - 2021-03-06 01:57:01,378 - D:\se\Se_Project\Util\log.py - log.py[:54] - 保存失败
ERROR - 2021-03-06 01:59:18,012 - D:\se\Se_Project\Util\log.py - log.py[:54] - 没有找到查询结果，--- try again ---
ERROR - 2021-03-06 02:00:09,398 - D:\se\Se_Project\Util\log.py - log.py[:54] - 没有找到查询结果，--- try again ---
ERROR - 2021-03-06 02:20:16,634 - D:\se\Se_Project\Util\log.py - log.py[:54] - 出现异常，异常信息为：<class 'selenium.common.exceptions.NoSuchElementException'>
ERROR - 2021-03-06 02:21:31,937 - D:\se\Se_Project\Util\log.py - log.py[:54] - 出现异常，异常信息为：<class 'selenium.common.exceptions.NoSuchElementException'>
ERROR - 2021-03-06 02:22:56,772 - D:\se\Se_Project\Util\log.py - log.py[:54] - 没有找到查询结果，--- try again ---
ERROR - 2021-03-06 02:23:49,214 - D:\se\Se_Project\Util\log.py - log.py[:54] - 出现异常，异常信息为：<class 'selenium.common.exceptions.TimeoutException'>
ERROR - 2021-03-06 02:25:18,123 - D:\se\Se_Project\Util\log.py - log.py[:54] - 没有找到查询结果，--- try again ---
ERROR - 2021-03-06 02:26:13,860 - D:\se\Se_Project\Util\log.py - log.py[:54] - 没有找到查询结果，--- try again ---
ERROR - 2021-03-06 02:27:47,823 - D:\se\Se_Project\Util\log.py - log.py[:54] - 没有找到查询结果，--- try again ---
ERROR - 2021-03-06 02:28:49,404 - D:\se\Se_Project\Util\log.py - log.py[:54] - 没有找到查询结果，--- try again ---
ERROR - 2021-03-06 13:12:36,239 - D:\se\Se_Project\Util\log.py - log.py[:54] - 没有找到查询结果，--- try again ---
ERROR - 2021-03-06 13:13:40,326 - D:\se\Se_Project\Util\log.py - log.py[:54] - 没有找到查询结果，--- try again ---
ERROR - 2021-03-06 13:16:59,559 - D:\se\Se_Project\Util\log.py - log.py[:54] - 出现异常，异常信息为：<class 'selenium.common.exceptions.TimeoutException'>
ERROR - 2021-03-06 13:19:08,421 - D:\se\Se_Project\Util\log.py - log.py[:54] - 没有找到查询结果，--- try again ---
ERROR - 2021-03-06 13:20:09,014 - D:\se\Se_Project\Util\log.py - log.py[:54] - 没有找到查询结果，--- try again ---
ERROR - 2021-03-06 13:33:26,154 - D:\se\Se_Project\Util\log.py - log.py[:54] - 没有找到查询结果，--- try again ---
ERROR - 2021-03-06 13:34:21,381 - D:\se\Se_Project\Util\log.py - log.py[:54] - 没有找到查询结果，--- try again ---
ERROR - 2021-03-06 13:35:18,230 - D:\se\Se_Project\Util\log.py - log.py[:54] - 业务审批出现异常，异常信息为：<class 'selenium.common.exceptions.TimeoutException'>
ERROR - 2021-03-06 13:35:37,533 - D:\se\Se_Project\Util\log.py - log.py[:54] - 没有找到查询结果，--- try again ---
ERROR - 2021-03-06 13:35:42,715 - D:\se\Se_Project\Util\log.py - log.py[:54] - 没有找到查询结果，--- try again ---
ERROR - 2021-03-06 13:36:42,920 - D:\se\Se_Project\Util\log.py - log.py[:54] - 出现异常，异常信息为：<class 'selenium.common.exceptions.ElementClickInterceptedException'>
ERROR - 2021-03-06 13:37:57,036 - D:\se\Se_Project\Util\log.py - log.py[:54] - 没有找到查询结果，--- try again ---
ERROR - 2021-03-06 13:39:00,059 - D:\se\Se_Project\Util\log.py - log.py[:54] - 没有找到查询结果，--- try again ---
ERROR - 2021-03-06 13:40:11,450 - D:\se\Se_Project\Util\log.py - log.py[:54] - 没有找到查询结果，--- try again ---
ERROR - 2021-03-06 13:41:12,762 - D:\se\Se_Project\Util\log.py - log.py[:54] - 没有找到查询结果，--- try again ---
ERROR - 2021-03-06 13:45:54,412 - D:\se\Se_Project\Util\log.py - log.py[:54] - 没有找到查询结果，--- try again ---
ERROR - 2021-03-06 13:46:53,962 - D:\se\Se_Project\Util\log.py - log.py[:54] - 没有找到查询结果，--- try again ---
ERROR - 2021-03-06 13:48:06,790 - D:\se\Se_Project\Util\log.py - log.py[:54] - 没有找到查询结果，--- try again ---
ERROR - 2021-03-06 13:49:06,565 - D:\se\Se_Project\Util\log.py - log.py[:54] - 没有找到查询结果，--- try again ---
ERROR - 2021-03-06 13:54:20,629 - D:\se\Se_Project\Util\log.py - log.py[:54] - 没有找到查询结果，--- try again ---
ERROR - 2021-03-06 13:55:23,542 - D:\se\Se_Project\Util\log.py - log.py[:54] - 没有找到查询结果，--- try again ---
ERROR - 2021-03-06 13:59:10,625 - D:\se\Se_Project\Util\log.py - log.py[:54] - 没有找到查询结果，--- try again ---
ERROR - 2021-03-06 14:00:08,270 - D:\se\Se_Project\Util\log.py - log.py[:54] - 没有找到查询结果，--- try again ---
ERROR - 2021-03-06 14:06:28,510 - D:\se\Se_Project\Util\log.py - log.py[:54] - 没有找到查询结果，--- try again ---
ERROR - 2021-03-06 14:07:20,289 - D:\se\Se_Project\Util\log.py - log.py[:54] - 没有找到查询结果，--- try again ---
ERROR - 2021-03-06 14:35:50,614 - D:\se\Se_Project\Util\log.py - log.py[:54] - 没有找到查询结果，--- try again ---
ERROR - 2021-03-06 14:36:03,707 - D:\se\Se_Project\Util\log.py - log.py[:54] - 单据LMJT-BX2103060188需要生成凭证，请刷新凭证后重试
ERROR - 2021-03-06 14:42:59,997 - D:\se\Se_Project\Util\log.py - log.py[:54] - 没有找到查询结果，--- try again ---
ERROR - 2021-03-06 14:49:47,412 - D:\se\Se_Project\Util\log.py - log.py[:54] - 没有找到查询结果，--- try again ---
ERROR - 2021-03-06 14:50:47,331 - D:\se\Se_Project\Util\log.py - log.py[:54] - 没有找到查询结果，--- try again ---
ERROR - 2021-03-06 15:09:52,025 - D:\se\Se_Project\Util\log.py - log.py[:54] - 没有找到查询结果，--- try again ---
ERROR - 2021-03-06 15:10:58,115 - D:\se\Se_Project\Util\log.py - log.py[:54] - 没有找到查询结果，--- try again ---
ERROR - 2021-03-06 15:16:41,550 - D:\se\Se_Project\Util\log.py - log.py[:54] - 没有找到查询结果，--- try again ---
ERROR - 2021-03-06 15:17:41,910 - D:\se\Se_Project\Util\log.py - log.py[:54] - 没有找到查询结果，--- try again ---
ERROR - 2021-03-06 15:19:40,805 - D:\se\Se_Project\Util\log.py - log.py[:54] - 没有找到查询结果，--- try again ---
ERROR - 2021-03-06 15:20:42,112 - D:\se\Se_Project\Util\log.py - log.py[:54] - 没有找到查询结果，--- try again ---
ERROR - 2021-03-06 15:22:04,884 - D:\se\Se_Project\Util\log.py - log.py[:54] - 没有找到查询结果，--- try again ---
ERROR - 2021-03-06 15:23:04,120 - D:\se\Se_Project\Util\log.py - log.py[:54] - 没有找到查询结果，--- try again ---
ERROR - 2021-03-06 15:27:33,716 - D:\se\Se_Project\Util\log.py - log.py[:54] - 没有找到查询结果，--- try again ---
ERROR - 2021-03-06 15:27:42,431 - D:\se\Se_Project\Util\log.py - log.py[:54] - 没有找到查询结果，--- try again ---
ERROR - 2021-03-06 15:28:46,422 - D:\se\Se_Project\Util\log.py - log.py[:54] - 没有找到查询结果，--- try again ---
ERROR - 2021-03-06 15:30:17,089 - D:\se\Se_Project\Util\log.py - log.py[:54] - 没有找到查询结果，--- try again ---
ERROR - 2021-03-06 15:31:12,573 - D:\se\Se_Project\Util\log.py - log.py[:54] - 没有找到查询结果，--- try again ---
ERROR - 2021-03-06 15:31:53,124 - D:\se\Se_Project\Util\log.py - log.py[:54] - 出现异常，异常信息为：<class 'selenium.common.exceptions.NoSuchElementException'>
ERROR - 2021-03-06 15:33:44,778 - D:\se\Se_Project\Util\log.py - log.py[:54] - 没有找到查询结果，--- try again ---
ERROR - 2021-03-06 15:34:46,116 - D:\se\Se_Project\Util\log.py - log.py[:54] - 没有找到查询结果，--- try again ---
ERROR - 2021-03-06 15:35:53,393 - D:\se\Se_Project\Util\log.py - log.py[:54] - 出现异常，异常信息为：<class 'selenium.common.exceptions.TimeoutException'>
ERROR - 2021-03-06 15:36:21,137 - D:\se\Se_Project\Util\log.py - log.py[:54] - Exception: Don't find Boe, please check config
ERROR - 2021-03-06 15:36:22,138 - D:\se\Se_Project\Util\log.py - log.py[:54] -  Don't find Boe, Try again
ERROR - 2021-03-06 15:36:23,197 - D:\se\Se_Project\Util\log.py - log.py[:54] - Exception: Don't find Boe, please check config
ERROR - 2021-03-06 15:36:23,198 - D:\se\Se_Project\Util\log.py - log.py[:54] - 出现异常，异常信息为：<class 'Exception'>
ERROR - 2021-03-06 15:38:04,801 - D:\se\Se_Project\Util\log.py - log.py[:54] - 没有找到查询结果，--- try again ---
ERROR - 2021-03-06 15:38:56,284 - D:\se\Se_Project\Util\log.py - log.py[:54] - 没有找到查询结果，--- try again ---
ERROR - 2021-03-06 15:39:26,520 - D:\se\Se_Project\Util\log.py - log.py[:54] - 出现异常，异常信息为：<class 'selenium.common.exceptions.NoSuchElementException'>
ERROR - 2021-03-06 15:44:41,523 - D:\se\Se_Project\Util\log.py - log.py[:54] - 没有找到查询结果，--- try again ---
ERROR - 2021-03-06 15:45:29,579 - D:\se\Se_Project\Util\log.py - log.py[:54] - 出现异常，异常信息为：<class 'selenium.common.exceptions.NoSuchElementException'>
ERROR - 2021-03-06 15:47:23,726 - D:\se\Se_Project\Util\log.py - log.py[:54] - 没有找到查询结果，--- try again ---
ERROR - 2021-03-06 15:48:07,945 - D:\se\Se_Project\Util\log.py - log.py[:54] - 没有找到查询结果，--- try again ---
ERROR - 2021-03-06 15:50:19,250 - D:\se\Se_Project\Util\log.py - log.py[:54] - 没有找到查询结果，--- try again ---
ERROR - 2021-03-06 15:51:07,967 - D:\se\Se_Project\Util\log.py - log.py[:54] - 没有找到查询结果，--- try again ---
ERROR - 2021-03-06 15:52:06,896 - D:\se\Se_Project\Util\log.py - log.py[:54] - 出现异常，异常信息为：<class 'selenium.common.exceptions.TimeoutException'>
ERROR - 2021-03-06 15:53:45,583 - D:\se\Se_Project\Util\log.py - log.py[:54] - 没有找到查询结果，--- try again ---
ERROR - 2021-03-06 15:53:54,923 - D:\se\Se_Project\Util\log.py - log.py[:54] - 没有找到查询结果，--- try again ---
ERROR - 2021-03-06 15:54:55,444 - D:\se\Se_Project\Util\log.py - log.py[:54] - 没有找到查询结果，--- try again ---
ERROR - 2021-03-06 15:56:47,350 - D:\se\Se_Project\Util\log.py - log.py[:54] - 没有找到查询结果，--- try again ---
ERROR - 2021-03-06 15:57:47,778 - D:\se\Se_Project\Util\log.py - log.py[:54] - 没有找到查询结果，--- try again ---
ERROR - 2021-03-06 16:00:15,108 - D:\se\Se_Project\Util\log.py - log.py[:54] - 没有找到查询结果，--- try again ---
ERROR - 2021-03-06 16:01:13,601 - D:\se\Se_Project\Util\log.py - log.py[:54] - 没有找到查询结果，--- try again ---
ERROR - 2021-03-06 16:02:51,082 - D:\se\Se_Project\Util\log.py - log.py[:54] - 没有找到查询结果，--- try again ---
ERROR - 2021-03-06 16:03:52,646 - D:\se\Se_Project\Util\log.py - log.py[:54] - 没有找到查询结果，--- try again ---
ERROR - 2021-03-06 16:06:48,820 - D:\se\Se_Project\Util\log.py - log.py[:54] - 没有找到查询结果，--- try again ---
ERROR - 2021-03-06 16:07:51,630 - D:\se\Se_Project\Util\log.py - log.py[:54] - 没有找到查询结果，--- try again ---
ERROR - 2021-03-06 16:09:31,297 - D:\se\Se_Project\Util\log.py - log.py[:54] - 没有找到查询结果，--- try again ---
ERROR - 2021-03-06 16:10:34,419 - D:\se\Se_Project\Util\log.py - log.py[:54] - 没有找到查询结果，--- try again ---
ERROR - 2021-03-06 16:14:41,485 - D:\se\Se_Project\Util\log.py - log.py[:54] - 没有找到查询结果，--- try again ---
ERROR - 2021-03-06 16:15:42,455 - D:\se\Se_Project\Util\log.py - log.py[:54] - 没有找到查询结果，--- try again ---
ERROR - 2021-03-06 16:59:04,686 - D:\se\Se_Project\Util\log.py - log.py[:54] - 没有找到查询结果，--- try again ---
ERROR - 2021-03-06 17:02:13,221 - D:\se\Se_Project\Util\log.py - log.py[:54] - Exception: Don't find Boe, please check config
ERROR - 2021-03-06 17:02:14,222 - D:\se\Se_Project\Util\log.py - log.py[:54] -  Don't find Boe, Try again
ERROR - 2021-03-06 17:02:15,243 - D:\se\Se_Project\Util\log.py - log.py[:54] - Exception: Don't find Boe, please check config
ERROR - 2021-03-06 17:02:15,245 - D:\se\Se_Project\Util\log.py - log.py[:54] - 出现异常，异常信息为：<class 'Exception'>
ERROR - 2021-03-06 17:12:28,383 - D:\se\Se_Project\Util\log.py - log.py[:54] - 没有找到查询结果，--- try again ---
ERROR - 2021-03-06 17:13:42,879 - D:\se\Se_Project\Util\log.py - log.py[:54] - boeNum do not exist
ERROR - 2021-03-06 17:13:42,880 - D:\se\Se_Project\Util\log.py - log.py[:54] - 业务审批出现异常，异常信息为：<class 'Exception'>
ERROR - 2021-03-06 17:17:06,831 - D:\se\Se_Project\Util\log.py - log.py[:54] - 没有找到查询结果，--- try again ---
ERROR - 2021-03-06 17:18:09,525 - D:\se\Se_Project\Util\log.py - log.py[:54] - 没有找到查询结果，--- try again ---
ERROR - 2021-03-06 17:20:11,632 - D:\se\Se_Project\Util\log.py - log.py[:54] - 没有找到查询结果，--- try again ---
ERROR - 2021-03-06 17:21:23,768 - D:\se\Se_Project\Util\log.py - log.py[:54] - Exception: Don't find Boe, please check config
ERROR - 2021-03-06 17:21:24,769 - D:\se\Se_Project\Util\log.py - log.py[:54] -  Don't find Boe, Try again
ERROR - 2021-03-06 17:21:25,775 - D:\se\Se_Project\Util\log.py - log.py[:54] - Exception: Don't find Boe, please check config
ERROR - 2021-03-06 17:21:25,776 - D:\se\Se_Project\Util\log.py - log.py[:54] - 出现异常，异常信息为：<class 'Exception'>
ERROR - 2021-03-06 17:30:36,986 - D:\se\Se_Project\Util\log.py - log.py[:54] - 没有找到查询结果，--- try again ---
ERROR - 2021-03-06 17:31:41,670 - D:\se\Se_Project\Util\log.py - log.py[:54] - 没有找到查询结果，--- try again ---
ERROR - 2021-03-06 17:32:05,436 - D:\se\Se_Project\Util\log.py - log.py[:54] - Exception: Don't find Boe, please check config
ERROR - 2021-03-06 17:32:05,436 - D:\se\Se_Project\Util\log.py - log.py[:54] -  Don't find Boe, Try again
ERROR - 2021-03-06 17:32:06,438 - D:\se\Se_Project\Util\log.py - log.py[:54] - 出现异常，异常信息为：<class 'AttributeError'>
ERROR - 2021-03-06 17:34:05,536 - D:\se\Se_Project\Util\log.py - log.py[:54] - 没有找到查询结果，--- try again ---
ERROR - 2021-03-06 17:35:07,870 - D:\se\Se_Project\Util\log.py - log.py[:54] - 没有找到查询结果，--- try again ---
ERROR - 2021-03-06 17:36:26,878 - D:\se\Se_Project\Util\log.py - log.py[:54] - 没有找到查询结果，--- try again ---
ERROR - 2021-03-06 17:39:02,721 - D:\se\Se_Project\Util\log.py - log.py[:54] - 出现异常，异常信息为：<class 'selenium.common.exceptions.TimeoutException'>
ERROR - 2021-03-06 17:40:21,588 - D:\se\Se_Project\Util\log.py - log.py[:54] - 没有找到查询结果，--- try again ---
ERROR - 2021-03-06 17:41:25,162 - D:\se\Se_Project\Util\log.py - log.py[:54] - 没有找到查询结果，--- try again ---
ERROR - 2021-03-06 17:42:41,525 - D:\se\Se_Project\Util\log.py - log.py[:54] - 没有找到查询结果，--- try again ---
ERROR - 2021-03-06 17:42:49,838 - D:\se\Se_Project\Util\log.py - log.py[:54] - 没有找到查询结果，--- try again ---
ERROR - 2021-03-06 17:43:52,065 - D:\se\Se_Project\Util\log.py - log.py[:54] - 没有找到查询结果，--- try again ---
ERROR - 2021-03-06 17:45:15,370 - D:\se\Se_Project\Util\log.py - log.py[:54] - 没有找到查询结果，--- try again ---
ERROR - 2021-03-06 17:46:11,804 - D:\se\Se_Project\Util\log.py - log.py[:54] - 没有找到查询结果，--- try again ---
ERROR - 2021-03-06 17:47:05,990 - D:\se\Se_Project\Util\log.py - log.py[:54] - 出现异常，异常信息为：<class 'selenium.common.exceptions.TimeoutException'>
ERROR - 2021-03-06 17:48:42,933 - D:\se\Se_Project\Util\log.py - log.py[:54] - 没有找到查询结果，--- try again ---
ERROR - 2021-03-06 17:50:03,362 - D:\se\Se_Project\Util\log.py - log.py[:54] - 没有找到查询结果，--- try again ---
ERROR - 2021-03-06 17:50:30,485 - D:\se\Se_Project\Util\log.py - log.py[:54] - 出现异常，异常信息为：<class 'selenium.common.exceptions.NoSuchElementException'>
ERROR - 2021-03-06 17:55:53,823 - D:\se\Se_Project\Util\log.py - log.py[:54] - 没有找到查询结果，--- try again ---
ERROR - 2021-03-06 17:56:29,557 - D:\se\Se_Project\Util\log.py - log.py[:54] - 出现异常，异常信息为：<class 'selenium.common.exceptions.NoSuchWindowException'>
ERROR - 2021-03-06 17:58:10,712 - D:\se\Se_Project\Util\log.py - log.py[:54] - 没有找到查询结果，--- try again ---
ERROR - 2021-03-06 17:59:12,618 - D:\se\Se_Project\Util\log.py - log.py[:54] - 没有找到查询结果，--- try again ---
ERROR - 2021-03-06 18:00:26,488 - D:\se\Se_Project\Util\log.py - log.py[:54] - 没有找到查询结果，--- try again ---
ERROR - 2021-03-06 18:00:35,376 - D:\se\Se_Project\Util\log.py - log.py[:54] - 没有找到查询结果，--- try again ---
ERROR - 2021-03-06 18:01:37,840 - D:\se\Se_Project\Util\log.py - log.py[:54] - 没有找到查询结果，--- try again ---
ERROR - 2021-03-06 18:02:58,415 - D:\se\Se_Project\Util\log.py - log.py[:54] - 没有找到查询结果，--- try again ---
ERROR - 2021-03-06 18:04:00,759 - D:\se\Se_Project\Util\log.py - log.py[:54] - 没有找到查询结果，--- try again ---
ERROR - 2021-03-06 18:05:24,846 - D:\se\Se_Project\Util\log.py - log.py[:54] - 没有找到查询结果，--- try again ---
ERROR - 2021-03-06 18:06:27,995 - D:\se\Se_Project\Util\log.py - log.py[:54] - 没有找到查询结果，--- try again ---
ERROR - 2021-03-06 18:07:22,629 - D:\se\Se_Project\Util\log.py - log.py[:54] - 出现异常，异常信息为：<class 'selenium.common.exceptions.TimeoutException'>
ERROR - 2021-03-06 18:08:54,699 - D:\se\Se_Project\Util\log.py - log.py[:54] - 没有找到查询结果，--- try again ---
ERROR - 2021-03-06 18:10:21,773 - D:\se\Se_Project\Util\log.py - log.py[:54] - 出现异常，异常信息为：<class 'selenium.common.exceptions.NoSuchElementException'>
ERROR - 2021-03-06 18:14:42,611 - D:\se\Se_Project\Util\log.py - log.py[:54] - 没有找到查询结果，--- try again ---
ERROR - 2021-03-06 18:15:43,500 - D:\se\Se_Project\Util\log.py - log.py[:54] - 没有找到查询结果，--- try again ---
ERROR - 2021-03-06 18:16:58,288 - D:\se\Se_Project\Util\log.py - log.py[:54] - 没有找到查询结果，--- try again ---
ERROR - 2021-03-06 18:18:01,289 - D:\se\Se_Project\Util\log.py - log.py[:54] - 没有找到查询结果，--- try again ---
ERROR - 2021-03-06 18:19:14,971 - D:\se\Se_Project\Util\log.py - log.py[:54] - 没有找到查询结果，--- try again ---
ERROR - 2021-03-06 18:20:08,707 - D:\se\Se_Project\Util\log.py - log.py[:54] - 没有找到查询结果，--- try again ---
ERROR - 2021-03-06 18:21:17,959 - D:\se\Se_Project\Util\log.py - log.py[:54] - 没有找到查询结果，--- try again ---
ERROR - 2021-03-06 18:21:26,438 - D:\se\Se_Project\Util\log.py - log.py[:54] - 没有找到查询结果，--- try again ---
ERROR - 2021-03-06 18:22:28,496 - D:\se\Se_Project\Util\log.py - log.py[:54] - 没有找到查询结果，--- try again ---
ERROR - 2021-03-06 18:23:38,022 - D:\se\Se_Project\Util\log.py - log.py[:54] - 没有找到查询结果，--- try again ---
ERROR - 2021-03-06 18:23:46,414 - D:\se\Se_Project\Util\log.py - log.py[:54] - 没有找到查询结果，--- try again ---
ERROR - 2021-03-06 18:25:08,296 - D:\se\Se_Project\Util\log.py - log.py[:54] - 出现异常，异常信息为：<class 'selenium.common.exceptions.NoSuchElementException'>
ERROR - 2021-03-06 18:25:46,416 - D:\se\Se_Project\Util\log.py - log.py[:54] - 出现异常，异常信息为：<class 'selenium.common.exceptions.TimeoutException'>
ERROR - 2021-03-06 18:27:00,478 - D:\se\Se_Project\Util\log.py - log.py[:54] - 没有找到查询结果，--- try again ---
ERROR - 2021-03-06 18:28:02,606 - D:\se\Se_Project\Util\log.py - log.py[:54] - 没有找到查询结果，--- try again ---
ERROR - 2021-03-06 18:29:23,216 - D:\se\Se_Project\Util\log.py - log.py[:54] - 没有找到查询结果，--- try again ---
ERROR - 2021-03-06 18:29:31,506 - D:\se\Se_Project\Util\log.py - log.py[:54] - 没有找到查询结果，--- try again ---
ERROR - 2021-03-06 18:30:35,880 - D:\se\Se_Project\Util\log.py - log.py[:54] - 没有找到查询结果，--- try again ---
ERROR - 2021-03-06 18:31:46,930 - D:\se\Se_Project\Util\log.py - log.py[:54] - 没有找到查询结果，--- try again ---
ERROR - 2021-03-06 18:32:51,188 - D:\se\Se_Project\Util\log.py - log.py[:54] - 没有找到查询结果，--- try again ---
ERROR - 2021-03-06 18:34:40,052 - D:\se\Se_Project\Util\log.py - log.py[:54] - 没有找到查询结果，--- try again ---
ERROR - 2021-03-06 18:35:44,332 - D:\se\Se_Project\Util\log.py - log.py[:54] - 没有找到查询结果，--- try again ---
ERROR - 2021-03-06 18:36:52,082 - D:\se\Se_Project\Util\log.py - log.py[:54] - 没有找到查询结果，--- try again ---
ERROR - 2021-03-06 18:37:01,017 - D:\se\Se_Project\Util\log.py - log.py[:54] - 没有找到查询结果，--- try again ---
ERROR - 2021-03-06 18:38:05,173 - D:\se\Se_Project\Util\log.py - log.py[:54] - 没有找到查询结果，--- try again ---
ERROR - 2021-03-06 18:39:09,500 - D:\se\Se_Project\Util\log.py - log.py[:54] - 没有找到查询结果，--- try again ---
ERROR - 2021-03-06 18:42:05,542 - D:\se\Se_Project\Util\log.py - log.py[:54] - Exception: Don't find Boe, please check config
ERROR - 2021-03-06 18:42:06,542 - D:\se\Se_Project\Util\log.py - log.py[:54] -  Don't find Boe, Try again
ERROR - 2021-03-06 18:42:07,602 - D:\se\Se_Project\Util\log.py - log.py[:54] - Exception: Don't find Boe, please check config
ERROR - 2021-03-06 18:42:07,603 - D:\se\Se_Project\Util\log.py - log.py[:54] - 出现异常，异常信息为：<class 'Exception'>
ERROR - 2021-03-06 18:43:18,612 - D:\se\Se_Project\Util\log.py - log.py[:54] - 没有找到查询结果，--- try again ---
ERROR - 2021-03-06 18:44:22,905 - D:\se\Se_Project\Util\log.py - log.py[:54] - 没有找到查询结果，--- try again ---
ERROR - 2021-03-06 18:44:31,251 - D:\se\Se_Project\Util\log.py - log.py[:54] - 没有找到查询结果，--- try again ---
ERROR - 2021-03-06 18:45:36,937 - D:\se\Se_Project\Util\log.py - log.py[:54] - 没有找到查询结果，--- try again ---
ERROR - 2021-03-06 18:46:06,835 - D:\se\Se_Project\Util\log.py - log.py[:54] - 出现异常，异常信息为：<class 'selenium.common.exceptions.TimeoutException'>
ERROR - 2021-03-06 18:46:33,135 - D:\se\Se_Project\Util\log.py - log.py[:54] - 出现异常，异常信息为：<class 'selenium.common.exceptions.TimeoutException'>
ERROR - 2021-03-06 18:47:49,188 - D:\se\Se_Project\Util\log.py - log.py[:54] - 没有找到查询结果，--- try again ---
ERROR - 2021-03-06 18:47:57,716 - D:\se\Se_Project\Util\log.py - log.py[:54] - 没有找到查询结果，--- try again ---
ERROR - 2021-03-06 18:48:54,827 - D:\se\Se_Project\Util\log.py - log.py[:54] - 出现异常，异常信息为：<class 'selenium.common.exceptions.ElementClickInterceptedException'>
ERROR - 2021-03-06 18:49:39,830 - D:\se\Se_Project\Util\log.py - log.py[:54] - 出现异常，异常信息为：<class 'selenium.common.exceptions.ElementClickInterceptedException'>
ERROR - 2021-03-06 18:50:52,507 - D:\se\Se_Project\Util\log.py - log.py[:54] - 没有找到查询结果，--- try again ---
ERROR - 2021-03-06 18:51:38,230 - D:\se\Se_Project\Util\log.py - log.py[:54] - 没有找到查询结果，--- try again ---
ERROR - 2021-03-06 18:51:57,979 - D:\se\Se_Project\Util\log.py - log.py[:54] - 出现异常，异常信息为：<class 'selenium.common.exceptions.NoSuchElementException'>
ERROR - 2021-03-06 18:55:30,331 - D:\se\Se_Project\Util\log.py - log.py[:54] - 没有找到查询结果，--- try again ---
ERROR - 2021-03-06 18:56:33,071 - D:\se\Se_Project\Util\log.py - log.py[:54] - 没有找到查询结果，--- try again ---
ERROR - 2021-03-06 18:57:52,185 - D:\se\Se_Project\Util\log.py - log.py[:54] - 没有找到查询结果，--- try again ---
ERROR - 2021-03-06 18:58:54,873 - D:\se\Se_Project\Util\log.py - log.py[:54] - 没有找到查询结果，--- try again ---
ERROR - 2021-03-06 18:59:44,139 - D:\se\Se_Project\Util\log.py - log.py[:54] - 出现异常，异常信息为：<class 'selenium.common.exceptions.TimeoutException'>
ERROR - 2021-03-06 19:00:04,483 - D:\se\Se_Project\Util\log.py - log.py[:54] - Exception: Don't find Boe, please check config
ERROR - 2021-03-06 19:00:05,485 - D:\se\Se_Project\Util\log.py - log.py[:54] -  Don't find Boe, Try again
ERROR - 2021-03-06 19:00:06,490 - D:\se\Se_Project\Util\log.py - log.py[:54] - Exception: Don't find Boe, please check config
ERROR - 2021-03-06 19:00:06,491 - D:\se\Se_Project\Util\log.py - log.py[:54] - 出现异常，异常信息为：<class 'Exception'>
ERROR - 2021-03-06 19:00:26,649 - D:\se\Se_Project\Util\log.py - log.py[:54] - Exception: Don't find Boe, please check config
ERROR - 2021-03-06 19:00:27,649 - D:\se\Se_Project\Util\log.py - log.py[:54] -  Don't find Boe, Try again
ERROR - 2021-03-06 19:00:28,694 - D:\se\Se_Project\Util\log.py - log.py[:54] - Exception: Don't find Boe, please check config
ERROR - 2021-03-06 19:00:28,695 - D:\se\Se_Project\Util\log.py - log.py[:54] - 出现异常，异常信息为：<class 'Exception'>
ERROR - 2021-03-06 19:04:35,794 - D:\se\Se_Project\Util\log.py - log.py[:54] - 没有找到查询结果，--- try again ---
ERROR - 2021-03-06 19:05:39,277 - D:\se\Se_Project\Util\log.py - log.py[:54] - 没有找到查询结果，--- try again ---
ERROR - 2021-03-06 19:06:56,694 - D:\se\Se_Project\Util\log.py - log.py[:54] - 没有找到查询结果，--- try again ---
ERROR - 2021-03-06 19:07:58,756 - D:\se\Se_Project\Util\log.py - log.py[:54] - 没有找到查询结果，--- try again ---
ERROR - 2021-03-06 19:09:17,352 - D:\se\Se_Project\Util\log.py - log.py[:54] - 没有找到查询结果，--- try again ---
ERROR - 2021-03-06 19:10:09,561 - D:\se\Se_Project\Util\log.py - log.py[:54] - 没有找到查询结果，--- try again ---
ERROR - 2021-03-06 19:11:30,694 - D:\se\Se_Project\Util\log.py - log.py[:54] - 没有找到查询结果，--- try again ---
ERROR - 2021-03-06 19:12:32,065 - D:\se\Se_Project\Util\log.py - log.py[:54] - 没有找到查询结果，--- try again ---
ERROR - 2021-03-06 19:13:16,437 - D:\se\Se_Project\Util\log.py - log.py[:54] - 出现异常，异常信息为：<class 'selenium.common.exceptions.ElementClickInterceptedException'>
ERROR - 2021-03-06 19:14:01,709 - D:\se\Se_Project\Util\log.py - log.py[:54] - 出现异常，异常信息为：<class 'selenium.common.exceptions.ElementClickInterceptedException'>
ERROR - 2021-03-06 19:15:11,863 - D:\se\Se_Project\Util\log.py - log.py[:54] - 没有找到查询结果，--- try again ---
ERROR - 2021-03-06 19:16:10,448 - D:\se\Se_Project\Util\log.py - log.py[:54] - 没有找到查询结果，--- try again ---
ERROR - 2021-03-06 19:16:45,133 - D:\se\Se_Project\Util\log.py - log.py[:54] - 出现异常，异常信息为：<class 'selenium.common.exceptions.NoSuchElementException'>
ERROR - 2021-03-06 19:21:42,676 - D:\se\Se_Project\Util\log.py - log.py[:54] - 没有找到查询结果，--- try again ---
ERROR - 2021-03-06 19:23:03,209 - D:\se\Se_Project\Util\log.py - log.py[:54] - 没有找到查询结果，--- try again ---
ERROR - 2021-03-06 19:24:04,600 - D:\se\Se_Project\Util\log.py - log.py[:54] - 没有找到查询结果，--- try again ---
ERROR - 2021-03-06 19:25:15,470 - D:\se\Se_Project\Util\log.py - log.py[:54] - 没有找到查询结果，--- try again ---
ERROR - 2021-03-06 19:26:10,689 - D:\se\Se_Project\Util\log.py - log.py[:54] - 没有找到查询结果，--- try again ---
ERROR - 2021-03-06 19:27:23,759 - D:\se\Se_Project\Util\log.py - log.py[:54] - 没有找到查询结果，--- try again ---
ERROR - 2021-03-06 19:28:26,979 - D:\se\Se_Project\Util\log.py - log.py[:54] - 没有找到查询结果，--- try again ---
ERROR - 2021-03-06 19:29:40,288 - D:\se\Se_Project\Util\log.py - log.py[:54] - 没有找到查询结果，--- try again ---
ERROR - 2021-03-06 19:30:43,575 - D:\se\Se_Project\Util\log.py - log.py[:54] - 没有找到查询结果，--- try again ---
ERROR - 2021-03-06 19:31:52,095 - D:\se\Se_Project\Util\log.py - log.py[:54] - 没有找到查询结果，--- try again ---
ERROR - 2021-03-06 19:32:00,667 - D:\se\Se_Project\Util\log.py - log.py[:54] - 没有找到查询结果，--- try again ---
ERROR - 2021-03-06 19:33:06,682 - D:\se\Se_Project\Util\log.py - log.py[:54] - 没有找到查询结果，--- try again ---
ERROR - 2021-03-06 19:34:22,943 - D:\se\Se_Project\Util\log.py - log.py[:54] - 没有找到查询结果，--- try again ---
ERROR - 2021-03-06 19:35:10,062 - D:\se\Se_Project\Util\log.py - log.py[:54] - 没有找到查询结果，--- try again ---
ERROR - 2021-03-06 19:36:45,817 - D:\se\Se_Project\Util\log.py - log.py[:54] - 没有找到查询结果，--- try again ---
ERROR - 2021-03-06 19:37:47,812 - D:\se\Se_Project\Util\log.py - log.py[:54] - 没有找到查询结果，--- try again ---
ERROR - 2021-03-06 19:39:59,376 - D:\se\Se_Project\Util\log.py - log.py[:54] - 没有找到查询结果，--- try again ---
ERROR - 2021-03-06 19:42:16,652 - D:\se\Se_Project\Util\log.py - log.py[:54] - 没有找到查询结果，--- try again ---
ERROR - 2021-03-06 19:43:15,217 - D:\se\Se_Project\Util\log.py - log.py[:54] - 没有找到查询结果，--- try again ---
ERROR - 2021-03-06 19:44:40,261 - D:\se\Se_Project\Util\log.py - log.py[:54] - 没有找到查询结果，--- try again ---
ERROR - 2021-03-06 19:45:44,170 - D:\se\Se_Project\Util\log.py - log.py[:54] - 没有找到查询结果，--- try again ---
ERROR - 2021-03-06 19:47:19,584 - D:\se\Se_Project\Util\log.py - log.py[:54] - 没有找到查询结果，--- try again ---
ERROR - 2021-03-06 19:48:17,588 - D:\se\Se_Project\Util\log.py - log.py[:54] - 没有找到查询结果，--- try again ---
ERROR - 2021-03-06 19:49:38,411 - D:\se\Se_Project\Util\log.py - log.py[:54] - 没有找到查询结果，--- try again ---
ERROR - 2021-03-06 19:50:40,723 - D:\se\Se_Project\Util\log.py - log.py[:54] - 没有找到查询结果，--- try again ---
ERROR - 2021-03-06 20:29:52,107 - D:\se\Se_Project\Util\log.py - log.py[:54] - 出现异常，异常信息为：<class 'Exception'>
ERROR - 2021-03-06 20:33:18,913 - D:\se\Se_Project\Util\log.py - log.py[:54] - 没有找到查询结果，--- try again ---
ERROR - 2021-03-06 20:34:11,472 - D:\se\Se_Project\Util\log.py - log.py[:54] - 没有找到查询结果，--- try again ---
ERROR - 2021-03-06 20:35:45,634 - D:\se\Se_Project\Util\log.py - log.py[:54] - 没有找到查询结果，--- try again ---
ERROR - 2021-03-06 20:36:27,933 - D:\se\Se_Project\Util\log.py - log.py[:54] - 没有找到查询结果，--- try again ---
ERROR - 2021-03-06 20:42:04,564 - D:\se\Se_Project\Util\log.py - log.py[:54] - 没有找到查询结果，--- try again ---
ERROR - 2021-03-06 20:43:17,739 - D:\se\Se_Project\Util\log.py - log.py[:54] - 没有找到查询结果，--- try again ---
ERROR - 2021-03-06 20:44:37,052 - D:\se\Se_Project\Util\log.py - log.py[:54] - 没有找到查询结果，--- try again ---
ERROR - 2021-03-06 20:45:39,616 - D:\se\Se_Project\Util\log.py - log.py[:54] - 没有找到查询结果，--- try again ---
ERROR - 2021-03-06 20:46:09,616 - D:\se\Se_Project\Util\log.py - log.py[:54] - 出现异常，异常信息为：<class 'selenium.common.exceptions.TimeoutException'>
ERROR - 2021-03-06 20:54:58,486 - D:\se\Se_Project\Util\log.py - log.py[:54] - 没有找到查询结果，--- try again ---
ERROR - 2021-03-06 20:55:30,654 - D:\se\Se_Project\Util\log.py - log.py[:54] - 出现异常，异常信息为：<class 'selenium.common.exceptions.TimeoutException'>
ERROR - 2021-03-06 20:56:44,142 - D:\se\Se_Project\Util\log.py - log.py[:54] - 没有找到查询结果，--- try again ---
ERROR - 2021-03-06 20:57:49,524 - D:\se\Se_Project\Util\log.py - log.py[:54] - 没有找到查询结果，--- try again ---
ERROR - 2021-03-06 20:59:14,758 - D:\se\Se_Project\Util\log.py - log.py[:54] - 没有找到查询结果，--- try again ---
ERROR - 2021-03-06 21:00:09,949 - D:\se\Se_Project\Util\log.py - log.py[:54] - 没有找到查询结果，--- try again ---
ERROR - 2021-03-06 21:02:10,087 - D:\se\Se_Project\Util\log.py - log.py[:54] - 没有找到查询结果，--- try again ---
ERROR - 2021-03-06 21:03:14,726 - D:\se\Se_Project\Util\log.py - log.py[:54] - 没有找到查询结果，--- try again ---
ERROR - 2021-03-06 21:04:41,571 - D:\se\Se_Project\Util\log.py - log.py[:54] - 没有找到查询结果，--- try again ---
ERROR - 2021-03-06 21:05:44,021 - D:\se\Se_Project\Util\log.py - log.py[:54] - 没有找到查询结果，--- try again ---
ERROR - 2021-03-06 21:06:15,105 - D:\se\Se_Project\Util\log.py - log.py[:54] - 出现异常，异常信息为：<class 'selenium.common.exceptions.NoSuchElementException'>
ERROR - 2021-03-06 21:07:36,588 - D:\se\Se_Project\Util\log.py - log.py[:54] - 没有找到查询结果，--- try again ---
ERROR - 2021-03-06 21:08:38,222 - D:\se\Se_Project\Util\log.py - log.py[:54] - 没有找到查询结果，--- try again ---
ERROR - 2021-03-06 21:09:33,487 - D:\se\Se_Project\Util\log.py - log.py[:54] - 出现异常，异常信息为：<class 'selenium.common.exceptions.TimeoutException'>
ERROR - 2021-03-06 21:10:03,275 - D:\se\Se_Project\Util\log.py - log.py[:54] - 出现异常，异常信息为：<class 'selenium.common.exceptions.ElementClickInterceptedException'>
ERROR - 2021-03-06 21:11:15,556 - D:\se\Se_Project\Util\log.py - log.py[:54] - 没有找到查询结果，--- try again ---
ERROR - 2021-03-06 21:12:09,686 - D:\se\Se_Project\Util\log.py - log.py[:54] - 没有找到查询结果，--- try again ---
ERROR - 2021-03-06 21:13:23,308 - D:\se\Se_Project\Util\log.py - log.py[:54] - 没有找到查询结果，--- try again ---
ERROR - 2021-03-06 21:14:32,021 - D:\se\Se_Project\Util\log.py - log.py[:54] - 没有找到查询结果，--- try again ---
ERROR - 2021-03-06 21:18:54,948 - D:\se\Se_Project\Util\log.py - log.py[:54] - 没有找到查询结果，--- try again ---
ERROR - 2021-03-06 21:19:59,960 - D:\se\Se_Project\Util\log.py - log.py[:54] - 没有找到查询结果，--- try again ---
ERROR - 2021-03-06 21:21:18,043 - D:\se\Se_Project\Util\log.py - log.py[:54] - 没有找到查询结果，--- try again ---
ERROR - 2021-03-06 21:23:19,568 - D:\se\Se_Project\Util\log.py - log.py[:54] - 没有找到查询结果，--- try again ---
ERROR - 2021-03-06 21:24:16,213 - D:\se\Se_Project\Util\log.py - log.py[:54] - 没有找到查询结果，--- try again ---
ERROR - 2021-03-06 21:25:35,383 - D:\se\Se_Project\Util\log.py - log.py[:54] - 没有找到查询结果，--- try again ---
ERROR - 2021-03-06 21:25:44,940 - D:\se\Se_Project\Util\log.py - log.py[:54] - 没有找到查询结果，--- try again ---
ERROR - 2021-03-06 21:26:50,573 - D:\se\Se_Project\Util\log.py - log.py[:54] - 没有找到查询结果，--- try again ---
ERROR - 2021-03-06 21:28:12,126 - D:\se\Se_Project\Util\log.py - log.py[:54] - 没有找到查询结果，--- try again ---
ERROR - 2021-03-06 21:29:12,142 - D:\se\Se_Project\Util\log.py - log.py[:54] - 没有找到查询结果，--- try again ---
ERROR - 2021-03-06 21:30:34,660 - D:\se\Se_Project\Util\log.py - log.py[:54] - 没有找到查询结果，--- try again ---
ERROR - 2021-03-06 21:31:40,345 - D:\se\Se_Project\Util\log.py - log.py[:54] - 没有找到查询结果，--- try again ---
ERROR - 2021-03-06 21:33:00,319 - D:\se\Se_Project\Util\log.py - log.py[:54] - 没有找到查询结果，--- try again ---
ERROR - 2021-03-06 21:34:07,000 - D:\se\Se_Project\Util\log.py - log.py[:54] - 没有找到查询结果，--- try again ---
ERROR - 2021-03-06 21:36:22,942 - D:\se\Se_Project\Util\log.py - log.py[:54] - 没有找到查询结果，--- try again ---
ERROR - 2021-03-06 21:37:19,911 - D:\se\Se_Project\Util\log.py - log.py[:54] - 没有找到查询结果，--- try again ---
ERROR - 2021-03-06 21:38:41,457 - D:\se\Se_Project\Util\log.py - log.py[:54] - 没有找到查询结果，--- try again ---
ERROR - 2021-03-06 21:38:54,542 - D:\se\Se_Project\Util\log.py - log.py[:54] - 没有找到查询结果，--- try again ---
ERROR - 2021-03-06 21:41:49,649 - D:\se\Se_Project\Util\log.py - log.py[:54] - 没有找到查询结果，--- try again ---
ERROR - 2021-03-06 21:42:55,074 - D:\se\Se_Project\Util\log.py - log.py[:54] - 没有找到查询结果，--- try again ---
ERROR - 2021-03-06 21:44:25,314 - D:\se\Se_Project\Util\log.py - log.py[:54] - 没有找到查询结果，--- try again ---
ERROR - 2021-03-06 21:45:11,694 - D:\se\Se_Project\Util\log.py - log.py[:54] - 没有找到查询结果，--- try again ---
ERROR - 2021-03-06 21:47:24,173 - D:\se\Se_Project\Util\log.py - log.py[:54] - 没有找到查询结果，--- try again ---
ERROR - 2021-03-06 21:48:14,739 - D:\se\Se_Project\Util\log.py - log.py[:54] - 没有找到查询结果，--- try again ---
ERROR - 2021-03-06 23:22:27,930 - D:\se\Se_Project\Util\log.py - log.py[:54] - Exception: Don't find Boe, please check config
ERROR - 2021-03-06 23:22:28,932 - D:\se\Se_Project\Util\log.py - log.py[:54] -  Don't find Boe, Try again
ERROR - 2021-03-06 23:22:29,938 - D:\se\Se_Project\Util\log.py - log.py[:54] - Exception: Don't find Boe, please check config
ERROR - 2021-03-06 23:22:29,939 - D:\se\Se_Project\Util\log.py - log.py[:54] - 出现异常，异常信息为：<class 'Exception'>
ERROR - 2021-03-06 23:24:15,925 - D:\se\Se_Project\Util\log.py - log.py[:54] - 业务审批出现异常，异常信息为：<class 'selenium.common.exceptions.TimeoutException'>
ERROR - 2021-03-06 23:24:31,768 - D:\se\Se_Project\Util\log.py - log.py[:54] - 没有找到查询结果，--- try again ---
ERROR - 2021-03-06 23:24:36,558 - D:\se\Se_Project\Util\log.py - log.py[:54] - 没有找到查询结果，--- try again ---
ERROR - 2021-03-06 23:25:15,556 - D:\se\Se_Project\Util\log.py - log.py[:54] - 业务审批出现异常，异常信息为：<class 'selenium.common.exceptions.NoSuchWindowException'>
ERROR - 2021-03-06 23:26:25,351 - D:\se\Se_Project\Util\log.py - log.py[:54] - 没有找到查询结果，--- try again ---
ERROR - 2021-03-06 23:27:39,354 - D:\se\Se_Project\Util\log.py - log.py[:54] - 没有找到查询结果，--- try again ---
ERROR - 2021-03-06 23:27:47,411 - D:\se\Se_Project\Util\log.py - log.py[:54] - 没有找到查询结果，--- try again ---
ERROR - 2021-03-06 23:28:28,076 - D:\se\Se_Project\Util\log.py - log.py[:54] - 没有找到查询结果，--- try again ---
ERROR - 2021-03-06 23:29:09,724 - D:\se\Se_Project\Util\log.py - log.py[:54] - 业务审批出现异常，异常信息为：<class 'urllib3.exceptions.ProtocolError'>
ERROR - 2021-03-06 23:34:17,334 - D:\se\Se_Project\Util\log.py - log.py[:54] - 没有找到查询结果，--- try again ---
ERROR - 2021-03-06 23:35:09,805 - D:\se\Se_Project\Util\log.py - log.py[:54] - 没有找到查询结果，--- try again ---
ERROR - 2021-03-06 23:36:25,396 - D:\se\Se_Project\Util\log.py - log.py[:54] - 没有找到查询结果，--- try again ---
ERROR - 2021-03-06 23:37:32,318 - D:\se\Se_Project\Util\log.py - log.py[:54] - 没有找到查询结果，--- try again ---
ERROR - 2021-03-06 23:38:42,298 - D:\se\Se_Project\Util\log.py - log.py[:54] - 没有找到查询结果，--- try again ---
ERROR - 2021-03-06 23:38:49,793 - D:\se\Se_Project\Util\log.py - log.py[:54] - 没有找到查询结果，--- try again ---
ERROR - 2021-03-06 23:39:52,119 - D:\se\Se_Project\Util\log.py - log.py[:54] - 没有找到查询结果，--- try again ---
ERROR - 2021-03-06 23:40:23,846 - D:\se\Se_Project\Util\log.py - log.py[:54] - Exception: Don't find Boe, please check config
ERROR - 2021-03-06 23:40:24,846 - D:\se\Se_Project\Util\log.py - log.py[:54] -  Don't find Boe, Try again
ERROR - 2021-03-06 23:41:09,667 - D:\se\Se_Project\Util\log.py - log.py[:54] - 没有找到查询结果，--- try again ---
ERROR - 2021-03-06 23:42:13,120 - D:\se\Se_Project\Util\log.py - log.py[:54] - 没有找到查询结果，--- try again ---
ERROR - 2021-03-06 23:43:28,395 - D:\se\Se_Project\Util\log.py - log.py[:54] - 没有找到查询结果，--- try again ---
ERROR - 2021-03-06 23:44:29,103 - D:\se\Se_Project\Util\log.py - log.py[:54] - 没有找到查询结果，--- try again ---
ERROR - 2021-03-06 23:45:44,537 - D:\se\Se_Project\Util\log.py - log.py[:54] - 没有找到查询结果，--- try again ---
ERROR - 2021-03-06 23:45:52,565 - D:\se\Se_Project\Util\log.py - log.py[:54] - 没有找到查询结果，--- try again ---
ERROR - 2021-03-06 23:46:58,374 - D:\se\Se_Project\Util\log.py - log.py[:54] - 没有找到查询结果，--- try again ---
ERROR - 2021-03-06 23:48:22,349 - D:\se\Se_Project\Util\log.py - log.py[:54] - 没有找到查询结果，--- try again ---
ERROR - 2021-03-06 23:49:27,662 - D:\se\Se_Project\Util\log.py - log.py[:54] - 没有找到查询结果，--- try again ---
ERROR - 2021-03-06 23:49:56,181 - D:\se\Se_Project\Util\log.py - log.py[:54] - 出现异常，异常信息为：<class 'selenium.common.exceptions.TimeoutException'>
ERROR - 2021-03-06 23:51:58,693 - D:\se\Se_Project\Util\log.py - log.py[:54] - 没有找到查询结果，--- try again ---
ERROR - 2021-03-06 23:53:11,133 - D:\se\Se_Project\Util\log.py - log.py[:54] - 没有找到查询结果，--- try again ---
ERROR - 2021-03-06 23:54:09,031 - D:\se\Se_Project\Util\log.py - log.py[:54] - 没有找到查询结果，--- try again ---
ERROR - 2021-03-06 23:55:01,438 - D:\se\Se_Project\Util\log.py - log.py[:54] - boeNum do not exist
ERROR - 2021-03-06 23:55:01,440 - D:\se\Se_Project\Util\log.py - log.py[:54] - 业务审批出现异常，异常信息为：<class 'Exception'>
ERROR - 2021-03-06 23:55:18,161 - D:\se\Se_Project\Util\log.py - log.py[:54] - 没有找到查询结果，--- try again ---
ERROR - 2021-03-06 23:55:22,800 - D:\se\Se_Project\Util\log.py - log.py[:54] - 没有找到查询结果，--- try again ---
ERROR - 2021-03-06 23:58:48,003 - D:\se\Se_Project\Util\log.py - log.py[:54] - 出现异常，异常信息为：<class 'selenium.common.exceptions.NoSuchElementException'>
ERROR - 2021-03-06 23:59:49,786 - D:\se\Se_Project\Util\log.py - log.py[:54] - 没有找到查询结果，--- try again ---
ERROR - 2021-03-06 23:59:57,350 - D:\se\Se_Project\Util\log.py - log.py[:54] - 没有找到查询结果，--- try again ---
ERROR - 2021-03-07 00:00:48,727 - D:\se\Se_Project\Util\log.py - log.py[:54] - 出现异常，异常信息为：<class 'selenium.common.exceptions.TimeoutException'>
ERROR - 2021-03-07 00:01:58,108 - D:\se\Se_Project\Util\log.py - log.py[:54] - 没有找到查询结果，--- try again ---
ERROR - 2021-03-07 00:02:06,225 - D:\se\Se_Project\Util\log.py - log.py[:54] - 没有找到查询结果，--- try again ---
ERROR - 2021-03-07 00:03:11,478 - D:\se\Se_Project\Util\log.py - log.py[:54] - 没有找到查询结果，--- try again ---
ERROR - 2021-03-07 00:04:17,393 - D:\se\Se_Project\Util\log.py - log.py[:54] - 没有找到查询结果，--- try again ---
ERROR - 2021-03-07 00:04:25,755 - D:\se\Se_Project\Util\log.py - log.py[:54] - 没有找到查询结果，--- try again ---
ERROR - 2021-03-07 00:05:34,237 - D:\se\Se_Project\Util\log.py - log.py[:54] - 没有找到查询结果，--- try again ---
ERROR - 2021-03-07 00:06:42,101 - D:\se\Se_Project\Util\log.py - log.py[:54] - 没有找到查询结果，--- try again ---
ERROR - 2021-03-07 00:07:46,912 - D:\se\Se_Project\Util\log.py - log.py[:54] - 没有找到查询结果，--- try again ---
ERROR - 2021-03-07 00:08:55,099 - D:\se\Se_Project\Util\log.py - log.py[:54] - 没有找到查询结果，--- try again ---
ERROR - 2021-03-07 00:09:59,054 - D:\se\Se_Project\Util\log.py - log.py[:54] - 没有找到查询结果，--- try again ---
ERROR - 2021-03-07 00:11:15,957 - D:\se\Se_Project\Util\log.py - log.py[:54] - 没有找到查询结果，--- try again ---
ERROR - 2021-03-07 00:12:12,838 - D:\se\Se_Project\Util\log.py - log.py[:54] - 没有找到查询结果，--- try again ---
ERROR - 2021-03-07 00:13:25,391 - D:\se\Se_Project\Util\log.py - log.py[:54] - 没有找到查询结果，--- try again ---
ERROR - 2021-03-07 00:14:29,199 - D:\se\Se_Project\Util\log.py - log.py[:54] - 没有找到查询结果，--- try again ---
ERROR - 2021-03-07 00:16:31,011 - D:\se\Se_Project\Util\log.py - log.py[:54] - 没有找到查询结果，--- try again ---
ERROR - 2021-03-07 00:17:59,783 - D:\se\Se_Project\Util\log.py - log.py[:54] - 没有找到查询结果，--- try again ---
ERROR - 2021-03-07 00:19:00,759 - D:\se\Se_Project\Util\log.py - log.py[:54] - 没有找到查询结果，--- try again ---
ERROR - 2021-03-07 00:20:07,391 - D:\se\Se_Project\Util\log.py - log.py[:54] - 没有找到查询结果，--- try again ---
ERROR - 2021-03-07 00:21:10,763 - D:\se\Se_Project\Util\log.py - log.py[:54] - 没有找到查询结果，--- try again ---
ERROR - 2021-03-07 00:22:18,066 - D:\se\Se_Project\Util\log.py - log.py[:54] - 没有找到查询结果，--- try again ---
ERROR - 2021-03-07 00:22:25,947 - D:\se\Se_Project\Util\log.py - log.py[:54] - 没有找到查询结果，--- try again ---
ERROR - 2021-03-07 00:23:32,581 - D:\se\Se_Project\Util\log.py - log.py[:54] - 没有找到查询结果，--- try again ---
ERROR - 2021-03-07 10:05:12,912 - D:\se\Se_Project\Util\log.py - log.py[:54] - Exception: Don't find Boe, please check config
ERROR - 2021-03-07 10:05:13,913 - D:\se\Se_Project\Util\log.py - log.py[:54] -  Don't find Boe, Try again
ERROR - 2021-03-07 10:05:14,939 - D:\se\Se_Project\Util\log.py - log.py[:54] - Exception: Don't find Boe, please check config
ERROR - 2021-03-07 10:05:14,940 - D:\se\Se_Project\Util\log.py - log.py[:54] - 出现异常，异常信息为：<class 'Exception'>
ERROR - 2021-03-07 10:06:39,292 - D:\se\Se_Project\Util\log.py - log.py[:54] - 业务审批出现异常，异常信息为：<class 'selenium.common.exceptions.TimeoutException'>
ERROR - 2021-03-07 10:06:57,963 - D:\se\Se_Project\Util\log.py - log.py[:54] - 没有找到查询结果，--- try again ---
ERROR - 2021-03-07 10:07:03,207 - D:\se\Se_Project\Util\log.py - log.py[:54] - 没有找到查询结果，--- try again ---
ERROR - 2021-03-07 10:08:16,848 - D:\se\Se_Project\Util\log.py - log.py[:54] - 没有找到查询结果，--- try again ---
ERROR - 2021-03-07 10:21:09,943 - D:\se\Se_Project\Util\log.py - log.py[:54] - Exception: Don't find Boe, please check config
ERROR - 2021-03-07 10:21:10,944 - D:\se\Se_Project\Util\log.py - log.py[:54] -  Don't find Boe, Try again
ERROR - 2021-03-07 10:21:11,981 - D:\se\Se_Project\Util\log.py - log.py[:54] - Exception: Don't find Boe, please check config
ERROR - 2021-03-07 10:21:11,984 - D:\se\Se_Project\Util\log.py - log.py[:54] - 出现异常，异常信息为：<class 'Exception'>
ERROR - 2021-03-07 10:23:16,386 - D:\se\Se_Project\Util\log.py - log.py[:54] - 没有找到查询结果，--- try again ---
ERROR - 2021-03-07 10:25:59,201 - D:\se\Se_Project\Util\log.py - log.py[:54] - Exception: Don't find Boe, please check config
ERROR - 2021-03-07 10:26:00,201 - D:\se\Se_Project\Util\log.py - log.py[:54] -  Don't find Boe, Try again
ERROR - 2021-03-07 10:26:01,207 - D:\se\Se_Project\Util\log.py - log.py[:54] - Exception: Don't find Boe, please check config
ERROR - 2021-03-07 10:26:01,208 - D:\se\Se_Project\Util\log.py - log.py[:54] - 出现异常，异常信息为：<class 'Exception'>
ERROR - 2021-03-07 10:27:19,150 - D:\se\Se_Project\Util\log.py - log.py[:54] - 没有找到查询结果，--- try again ---
ERROR - 2021-03-07 10:28:11,157 - D:\se\Se_Project\Util\log.py - log.py[:54] - 没有找到查询结果，--- try again ---
ERROR - 2021-03-07 10:29:31,872 - D:\se\Se_Project\Util\log.py - log.py[:54] - 没有找到查询结果，--- try again ---
ERROR - 2021-03-07 10:30:38,602 - D:\se\Se_Project\Util\log.py - log.py[:54] - 没有找到查询结果，--- try again ---
ERROR - 2021-03-07 10:31:02,646 - D:\se\Se_Project\Util\log.py - log.py[:54] - Exception: Don't find Boe, please check config
ERROR - 2021-03-07 10:31:03,647 - D:\se\Se_Project\Util\log.py - log.py[:54] -  Don't find Boe, Try again
ERROR - 2021-03-07 10:31:04,657 - D:\se\Se_Project\Util\log.py - log.py[:54] - Exception: Don't find Boe, please check config
ERROR - 2021-03-07 10:31:04,657 - D:\se\Se_Project\Util\log.py - log.py[:54] - 出现异常，异常信息为：<class 'Exception'>
ERROR - 2021-03-07 10:31:55,265 - D:\se\Se_Project\Util\log.py - log.py[:54] - 出现异常，异常信息为：<class 'selenium.common.exceptions.TimeoutException'>
ERROR - 2021-03-07 10:33:37,862 - D:\se\Se_Project\Util\log.py - log.py[:54] - 没有找到查询结果，--- try again ---
ERROR - 2021-03-07 10:33:46,442 - D:\se\Se_Project\Util\log.py - log.py[:54] - 没有找到查询结果，--- try again ---
ERROR - 2021-03-07 10:34:15,732 - D:\se\Se_Project\Util\log.py - log.py[:54] - Exception: Don't find Boe, please check config
ERROR - 2021-03-07 10:34:16,753 - D:\se\Se_Project\Util\log.py - log.py[:54] -  Don't find Boe, Try again
ERROR - 2021-03-07 10:34:17,858 - D:\se\Se_Project\Util\log.py - log.py[:54] - Exception: Don't find Boe, please check config
ERROR - 2021-03-07 10:34:17,859 - D:\se\Se_Project\Util\log.py - log.py[:54] - 出现异常，异常信息为：<class 'Exception'>
ERROR - 2021-03-07 10:34:37,661 - D:\se\Se_Project\Util\log.py - log.py[:54] - Exception: Don't find Boe, please check config
ERROR - 2021-03-07 10:34:38,661 - D:\se\Se_Project\Util\log.py - log.py[:54] -  Don't find Boe, Try again
ERROR - 2021-03-07 10:34:39,691 - D:\se\Se_Project\Util\log.py - log.py[:54] - Exception: Don't find Boe, please check config
ERROR - 2021-03-07 10:34:39,692 - D:\se\Se_Project\Util\log.py - log.py[:54] - 出现异常，异常信息为：<class 'Exception'>
ERROR - 2021-03-07 10:38:52,579 - D:\se\Se_Project\Util\log.py - log.py[:54] - 没有找到查询结果，--- try again ---
ERROR - 2021-03-07 10:40:12,287 - D:\se\Se_Project\Util\log.py - log.py[:54] - 没有找到查询结果，--- try again ---
ERROR - 2021-03-07 10:41:24,532 - D:\se\Se_Project\Util\log.py - log.py[:54] - 没有找到查询结果，--- try again ---
ERROR - 2021-03-07 10:42:29,394 - D:\se\Se_Project\Util\log.py - log.py[:54] - 没有找到查询结果，--- try again ---
ERROR - 2021-03-07 10:43:54,488 - D:\se\Se_Project\Util\log.py - log.py[:54] - 没有找到查询结果，--- try again ---
ERROR - 2021-03-07 10:44:56,048 - D:\se\Se_Project\Util\log.py - log.py[:54] - 没有找到查询结果，--- try again ---
ERROR - 2021-03-07 10:45:39,593 - D:\se\Se_Project\Util\log.py - log.py[:54] - 出现异常，异常信息为：<class 'selenium.common.exceptions.TimeoutException'>
ERROR - 2021-03-07 10:46:49,492 - D:\se\Se_Project\Util\log.py - log.py[:54] - 没有找到查询结果，--- try again ---
ERROR - 2021-03-07 10:47:54,106 - D:\se\Se_Project\Util\log.py - log.py[:54] - 没有找到查询结果，--- try again ---
ERROR - 2021-03-07 10:49:07,995 - D:\se\Se_Project\Util\log.py - log.py[:54] - 没有找到查询结果，--- try again ---
ERROR - 2021-03-07 10:50:10,602 - D:\se\Se_Project\Util\log.py - log.py[:54] - 没有找到查询结果，--- try again ---
ERROR - 2021-03-07 10:51:39,028 - D:\se\Se_Project\Util\log.py - log.py[:54] - 没有找到查询结果，--- try again ---
ERROR - 2021-03-07 10:52:48,589 - D:\se\Se_Project\Util\log.py - log.py[:54] - 没有找到查询结果，--- try again ---
ERROR - 2021-03-07 10:54:01,548 - D:\se\Se_Project\Util\log.py - log.py[:54] - 没有找到查询结果，--- try again ---
ERROR - 2021-03-07 10:56:09,252 - D:\se\Se_Project\Util\log.py - log.py[:54] - 没有找到查询结果，--- try again ---
ERROR - 2021-03-07 10:57:12,116 - D:\se\Se_Project\Util\log.py - log.py[:54] - 没有找到查询结果，--- try again ---
ERROR - 2021-03-07 10:58:20,668 - D:\se\Se_Project\Util\log.py - log.py[:54] - 没有找到查询结果，--- try again ---
ERROR - 2021-03-07 10:58:29,134 - D:\se\Se_Project\Util\log.py - log.py[:54] - 没有找到查询结果，--- try again ---
ERROR - 2021-03-07 10:59:34,013 - D:\se\Se_Project\Util\log.py - log.py[:54] - 没有找到查询结果，--- try again ---
ERROR - 2021-03-08 09:40:20,932 - D:\se\Se_Project\Util\log.py - log.py[:54] - Exception: Don't find Boe, please check config
ERROR - 2021-03-08 09:40:21,936 - D:\se\Se_Project\Util\log.py - log.py[:54] -  Don't find Boe, Try again
ERROR - 2021-03-08 09:40:22,982 - D:\se\Se_Project\Util\log.py - log.py[:54] - Exception: Don't find Boe, please check config
ERROR - 2021-03-08 09:40:22,986 - D:\se\Se_Project\Util\log.py - log.py[:54] - 出现异常，异常信息为：<class 'Exception'>
ERROR - 2021-03-08 09:44:38,468 - D:\se\Se_Project\Util\log.py - log.py[:54] - Exception: Don't find Boe, please check config
ERROR - 2021-03-08 09:44:41,469 - D:\se\Se_Project\Util\log.py - log.py[:54] -  Don't find Boe, Try again
ERROR - 2021-03-08 09:44:42,492 - D:\se\Se_Project\Util\log.py - log.py[:54] - Exception: Don't find Boe, please check config
ERROR - 2021-03-08 09:44:42,494 - D:\se\Se_Project\Util\log.py - log.py[:54] - 出现异常，异常信息为：<class 'Exception'>
ERROR - 2021-03-08 09:46:54,086 - D:\se\Se_Project\Util\log.py - log.py[:54] - Exception: Don't find Boe, please check config
ERROR - 2021-03-08 09:46:59,089 - D:\se\Se_Project\Util\log.py - log.py[:54] -  Don't find Boe, Try again
ERROR - 2021-03-08 09:47:00,110 - D:\se\Se_Project\Util\log.py - log.py[:54] - Exception: Don't find Boe, please check config
ERROR - 2021-03-08 09:47:00,112 - D:\se\Se_Project\Util\log.py - log.py[:54] - 出现异常，异常信息为：<class 'Exception'>
ERROR - 2021-03-08 09:51:47,966 - D:\se\Se_Project\Util\log.py - log.py[:54] - 没有找到查询结果，--- try again ---
ERROR - 2021-03-08 09:52:00,152 - D:\se\Se_Project\Util\log.py - log.py[:54] - 没有找到查询结果，--- try again ---
ERROR - 2021-03-08 09:52:31,095 - D:\se\Se_Project\Util\log.py - log.py[:54] - 没有找到查询结果，--- try again ---
ERROR - 2021-03-08 09:52:57,827 - D:\se\Se_Project\Util\log.py - log.py[:54] - Exception: Don't find Boe, please check config
ERROR - 2021-03-08 09:53:00,854 - D:\se\Se_Project\Util\log.py - log.py[:54] -  Don't find Boe, Try again
ERROR - 2021-03-08 09:53:01,957 - D:\se\Se_Project\Util\log.py - log.py[:54] - Exception: Don't find Boe, please check config
ERROR - 2021-03-08 09:53:01,960 - D:\se\Se_Project\Util\log.py - log.py[:54] - 出现异常，异常信息为：<class 'Exception'>
ERROR - 2021-03-08 10:53:57,324 - D:\se\Se_Project\Util\log.py - log.py[:54] - 没有找到查询结果，--- try again ---
ERROR - 2021-03-08 10:55:01,542 - D:\se\Se_Project\Util\log.py - log.py[:54] - 没有找到查询结果，--- try again ---
ERROR - 2021-03-08 10:55:58,287 - D:\se\Se_Project\Util\log.py - log.py[:54] - 出现异常，异常信息为：<class 'selenium.common.exceptions.NoSuchElementException'>
ERROR - 2021-03-08 11:00:47,219 - D:\se\Se_Project\Util\log.py - log.py[:54] - 没有找到查询结果，--- try again ---
ERROR - 2021-03-08 11:01:49,862 - D:\se\Se_Project\Util\log.py - log.py[:54] - 没有找到查询结果，--- try again ---
ERROR - 2021-03-08 11:02:49,014 - D:\se\Se_Project\Util\log.py - log.py[:54] - 出现异常，异常信息为：<class 'selenium.common.exceptions.NoSuchElementException'>
ERROR - 2021-03-08 11:06:45,083 - D:\se\Se_Project\Util\log.py - log.py[:54] - 没有找到查询结果，--- try again ---
ERROR - 2021-03-08 11:06:56,029 - D:\se\Se_Project\Util\log.py - log.py[:54] - 没有找到查询结果，--- try again ---
ERROR - 2021-03-08 12:23:41,011 - D:\se\Se_Project\Util\log.py - log.py[:54] - 没有找到查询结果，--- try again ---
ERROR - 2021-03-08 12:24:35,038 - D:\se\Se_Project\Util\log.py - log.py[:54] - Exception: Don't find Boe, please check config
ERROR - 2021-03-08 12:24:38,039 - D:\se\Se_Project\Util\log.py - log.py[:54] -  Don't find Boe, Try again
ERROR - 2021-03-08 12:24:39,064 - D:\se\Se_Project\Util\log.py - log.py[:54] - Exception: Don't find Boe, please check config
ERROR - 2021-03-08 12:24:39,066 - D:\se\Se_Project\Util\log.py - log.py[:54] - 出现异常，异常信息为：<class 'Exception'>
ERROR - 2021-03-08 12:25:48,105 - D:\se\Se_Project\Util\log.py - log.py[:54] - 出现异常，异常信息为：<class 'selenium.common.exceptions.NoSuchWindowException'>
ERROR - 2021-03-08 12:26:12,809 - D:\se\Se_Project\Util\log.py - log.py[:54] - Exception: Don't find Boe, please check config
ERROR - 2021-03-08 12:26:15,810 - D:\se\Se_Project\Util\log.py - log.py[:54] -  Don't find Boe, Try again
ERROR - 2021-03-08 12:26:15,905 - D:\se\Se_Project\Util\log.py - log.py[:54] - Exception: Don't find Boe, please check config
ERROR - 2021-03-08 12:26:15,906 - D:\se\Se_Project\Util\log.py - log.py[:54] - 出现异常，异常信息为：<class 'Exception'>
ERROR - 2021-03-08 12:28:26,487 - D:\se\Se_Project\Util\log.py - log.py[:54] - 没有找到查询结果，--- try again ---
ERROR - 2021-03-08 12:29:25,629 - D:\se\Se_Project\Util\log.py - log.py[:54] - 没有找到查询结果，--- try again ---
ERROR - 2021-03-08 12:31:52,742 - D:\se\Se_Project\Util\log.py - log.py[:54] - 没有找到查询结果，--- try again ---
ERROR - 2021-03-08 12:32:57,095 - D:\se\Se_Project\Util\log.py - log.py[:54] - 没有找到查询结果，--- try again ---
ERROR - 2021-03-08 12:36:38,143 - D:\se\Se_Project\Util\log.py - log.py[:54] - 业务审批出现异常，异常信息为：<class 'Exception'>
ERROR - 2021-03-08 12:37:21,615 - D:\se\Se_Project\Util\log.py - log.py[:54] - 没有找到查询结果，--- try again ---
ERROR - 2021-03-08 12:37:33,092 - D:\se\Se_Project\Util\log.py - log.py[:54] - 没有找到查询结果，--- try again ---
ERROR - 2021-03-08 12:38:28,909 - D:\se\Se_Project\Util\log.py - log.py[:54] - 出现异常，异常信息为：<class 'selenium.common.exceptions.NoSuchElementException'>
ERROR - 2021-03-08 12:43:41,848 - D:\se\Se_Project\Util\log.py - log.py[:54] - 没有找到查询结果，--- try again ---
ERROR - 2021-03-08 12:44:44,930 - D:\se\Se_Project\Util\log.py - log.py[:54] - 没有找到查询结果，--- try again ---
ERROR - 2021-03-08 12:47:19,917 - D:\se\Se_Project\Util\log.py - log.py[:54] - 没有找到查询结果，--- try again ---
ERROR - 2021-03-08 12:47:59,851 - D:\se\Se_Project\Util\log.py - log.py[:54] - 没有找到查询结果，--- try again ---
ERROR - 2021-03-08 12:54:02,694 - D:\se\Se_Project\Util\log.py - log.py[:54] - 没有找到查询结果，--- try again ---
ERROR - 2021-03-08 12:55:03,360 - D:\se\Se_Project\Util\log.py - log.py[:54] - 没有找到查询结果，--- try again ---
ERROR - 2021-03-08 12:57:47,141 - D:\se\Se_Project\Util\log.py - log.py[:54] - 没有找到查询结果，--- try again ---
ERROR - 2021-03-08 12:58:02,078 - D:\se\Se_Project\Util\log.py - log.py[:54] - 没有找到查询结果，--- try again ---
ERROR - 2021-03-08 12:59:11,862 - D:\se\Se_Project\Util\log.py - log.py[:54] - 没有找到查询结果，--- try again ---
ERROR - 2021-03-08 13:01:36,116 - D:\se\Se_Project\Util\log.py - log.py[:54] - 没有找到查询结果，--- try again ---
ERROR - 2021-03-08 13:02:14,866 - D:\se\Se_Project\Util\log.py - log.py[:54] - 没有找到查询结果，--- try again ---
ERROR - 2021-03-08 13:04:43,900 - D:\se\Se_Project\Util\log.py - log.py[:54] - 没有找到查询结果，--- try again ---
ERROR - 2021-03-08 13:04:58,734 - D:\se\Se_Project\Util\log.py - log.py[:54] - 没有找到查询结果，--- try again ---
ERROR - 2021-03-08 13:06:09,849 - D:\se\Se_Project\Util\log.py - log.py[:54] - 没有找到查询结果，--- try again ---
ERROR - 2021-03-08 13:06:43,916 - D:\se\Se_Project\Util\log.py - log.py[:54] - Exception: Don't find Boe, please check config
ERROR - 2021-03-08 13:06:46,916 - D:\se\Se_Project\Util\log.py - log.py[:54] -  Don't find Boe, Try again
ERROR - 2021-03-08 13:07:25,566 - D:\se\Se_Project\Util\log.py - log.py[:54] - 出现异常，异常信息为：<class 'selenium.common.exceptions.TimeoutException'>
ERROR - 2021-03-08 13:09:36,647 - D:\se\Se_Project\Util\log.py - log.py[:54] - 没有找到查询结果，--- try again ---
ERROR - 2021-03-08 13:09:51,418 - D:\se\Se_Project\Util\log.py - log.py[:54] - 没有找到查询结果，--- try again ---
ERROR - 2021-03-08 13:10:33,397 - D:\se\Se_Project\Util\log.py - log.py[:54] - Exception: Don't find Boe, please check config
ERROR - 2021-03-08 13:10:36,398 - D:\se\Se_Project\Util\log.py - log.py[:54] -  Don't find Boe, Try again
ERROR - 2021-03-08 13:11:17,141 - D:\se\Se_Project\Util\log.py - log.py[:54] - 业务审批出现异常，异常信息为：<class 'selenium.common.exceptions.TimeoutException'>
ERROR - 2021-03-08 13:11:43,863 - D:\se\Se_Project\Util\log.py - log.py[:54] - 没有找到查询结果，--- try again ---
ERROR - 2021-03-08 13:11:54,792 - D:\se\Se_Project\Util\log.py - log.py[:54] - 没有找到查询结果，--- try again ---
ERROR - 2021-03-08 13:12:21,374 - D:\se\Se_Project\Util\log.py - log.py[:54] - 出现异常，异常信息为：<class 'selenium.common.exceptions.NoSuchElementException'>
ERROR - 2021-03-08 13:18:46,263 - D:\se\Se_Project\Util\log.py - log.py[:54] - 没有找到查询结果，--- try again ---
ERROR - 2021-03-08 13:19:30,292 - D:\se\Se_Project\Util\log.py - log.py[:54] - 出现异常，异常信息为：<class 'selenium.common.exceptions.NoSuchElementException'>
ERROR - 2021-03-08 13:21:18,592 - D:\se\Se_Project\Util\log.py - log.py[:54] - 没有找到查询结果，--- try again ---
ERROR - 2021-03-08 13:22:15,729 - D:\se\Se_Project\Util\log.py - log.py[:54] - 没有找到查询结果，--- try again ---
ERROR - 2021-03-08 13:22:57,071 - D:\se\Se_Project\Util\log.py - log.py[:54] - 出现异常，异常信息为：<class 'selenium.common.exceptions.ElementClickInterceptedException'>
ERROR - 2021-03-08 13:23:44,237 - D:\se\Se_Project\Util\log.py - log.py[:54] - 出现异常，异常信息为：<class 'selenium.common.exceptions.TimeoutException'>
ERROR - 2021-03-08 13:25:33,376 - D:\se\Se_Project\Util\log.py - log.py[:54] - 没有找到查询结果，--- try again ---
ERROR - 2021-03-08 13:26:21,361 - D:\se\Se_Project\Util\log.py - log.py[:54] - 没有找到查询结果，--- try again ---
ERROR - 2021-03-08 13:28:04,709 - D:\se\Se_Project\Util\log.py - log.py[:54] - 没有找到查询结果，--- try again ---
ERROR - 2021-03-08 13:29:21,274 - D:\se\Se_Project\Util\log.py - log.py[:54] - 没有找到查询结果，--- try again ---
ERROR - 2021-03-08 13:31:12,253 - D:\se\Se_Project\Util\log.py - log.py[:54] - 没有找到查询结果，--- try again ---
ERROR - 2021-03-08 13:39:29,043 - D:\se\Se_Project\Util\log.py - log.py[:54] - 业务审批出现异常，异常信息为：<class 'selenium.common.exceptions.TimeoutException'>
ERROR - 2021-03-08 13:40:10,413 - D:\se\Se_Project\Util\log.py - log.py[:54] - 没有找到查询结果，--- try again ---
ERROR - 2021-03-08 13:42:32,320 - D:\se\Se_Project\Util\log.py - log.py[:54] - 没有找到查询结果，--- try again ---
ERROR - 2021-03-08 13:43:29,423 - D:\se\Se_Project\Util\log.py - log.py[:54] - 没有找到查询结果，--- try again ---
ERROR - 2021-03-08 13:45:20,691 - D:\se\Se_Project\Util\log.py - log.py[:54] - 没有找到查询结果，--- try again ---
ERROR - 2021-03-08 13:46:25,754 - D:\se\Se_Project\Util\log.py - log.py[:54] - 没有找到查询结果，--- try again ---
ERROR - 2021-03-08 13:48:10,809 - D:\se\Se_Project\Util\log.py - log.py[:54] - 没有找到查询结果，--- try again ---
ERROR - 2021-03-08 13:49:15,870 - D:\se\Se_Project\Util\log.py - log.py[:54] - 没有找到查询结果，--- try again ---
ERROR - 2021-03-08 13:51:08,480 - D:\se\Se_Project\Util\log.py - log.py[:54] - 没有找到查询结果，--- try again ---
ERROR - 2021-03-08 13:52:27,148 - D:\se\Se_Project\Util\log.py - log.py[:54] - 没有找到查询结果，--- try again ---
ERROR - 2021-03-08 13:54:24,627 - D:\se\Se_Project\Util\log.py - log.py[:54] - 没有找到查询结果，--- try again ---
ERROR - 2021-03-08 13:55:11,430 - D:\se\Se_Project\Util\log.py - log.py[:54] - 没有找到查询结果，--- try again ---
ERROR - 2021-03-08 13:57:30,347 - D:\se\Se_Project\Util\log.py - log.py[:54] - 没有找到查询结果，--- try again ---
ERROR - 2021-03-08 13:59:10,457 - D:\se\Se_Project\Util\log.py - log.py[:54] - 没有找到查询结果，--- try again ---
ERROR - 2021-03-08 14:00:12,544 - D:\se\Se_Project\Util\log.py - log.py[:54] - 没有找到查询结果，--- try again ---
ERROR - 2021-03-08 14:01:58,307 - D:\se\Se_Project\Util\log.py - log.py[:54] - 没有找到查询结果，--- try again ---
ERROR - 2021-03-08 14:03:03,359 - D:\se\Se_Project\Util\log.py - log.py[:54] - 没有找到查询结果，--- try again ---
ERROR - 2021-03-08 14:09:42,884 - D:\se\Se_Project\Util\log.py - log.py[:54] - 没有找到查询结果，--- try again ---
ERROR - 2021-03-08 14:10:00,293 - D:\se\Se_Project\Util\log.py - log.py[:54] - 没有找到查询结果，--- try again ---
ERROR - 2021-03-08 14:11:03,021 - D:\se\Se_Project\Util\log.py - log.py[:54] - 没有找到查询结果，--- try again ---
ERROR - 2021-03-08 14:12:48,737 - D:\se\Se_Project\Util\log.py - log.py[:54] - 没有找到查询结果，--- try again ---
ERROR - 2021-03-08 14:13:53,652 - D:\se\Se_Project\Util\log.py - log.py[:54] - 没有找到查询结果，--- try again ---
ERROR - 2021-03-08 14:16:33,409 - D:\se\Se_Project\Util\log.py - log.py[:54] - 没有找到查询结果，--- try again ---
ERROR - 2021-03-08 14:17:17,564 - D:\se\Se_Project\Util\log.py - log.py[:54] - 没有找到查询结果，--- try again ---
ERROR - 2021-03-08 14:19:02,969 - D:\se\Se_Project\Util\log.py - log.py[:54] - 没有找到查询结果，--- try again ---
ERROR - 2021-03-08 14:20:08,284 - D:\se\Se_Project\Util\log.py - log.py[:54] - 没有找到查询结果，--- try again ---
ERROR - 2021-03-08 14:21:39,875 - D:\se\Se_Project\Util\log.py - log.py[:54] - 没有找到查询结果，--- try again ---
ERROR - 2021-03-08 14:21:56,595 - D:\se\Se_Project\Util\log.py - log.py[:54] - 没有找到查询结果，--- try again ---
ERROR - 2021-03-08 14:23:04,202 - D:\se\Se_Project\Util\log.py - log.py[:54] - 没有找到查询结果，--- try again ---
ERROR - 2021-03-08 14:24:45,300 - D:\se\Se_Project\Util\log.py - log.py[:54] - 没有找到查询结果，--- try again ---
ERROR - 2021-03-08 14:25:52,859 - D:\se\Se_Project\Util\log.py - log.py[:54] - 没有找到查询结果，--- try again ---
ERROR - 2021-03-08 14:27:28,814 - D:\se\Se_Project\Util\log.py - log.py[:54] - 没有找到查询结果，--- try again ---
ERROR - 2021-03-08 14:28:13,296 - D:\se\Se_Project\Util\log.py - log.py[:54] - 没有找到查询结果，--- try again ---
ERROR - 2021-03-08 14:30:05,314 - D:\se\Se_Project\Util\log.py - log.py[:54] - 没有找到查询结果，--- try again ---
ERROR - 2021-03-08 14:31:20,729 - D:\se\Se_Project\Util\log.py - log.py[:54] - 没有找到查询结果，--- try again ---
ERROR - 2021-03-08 14:32:55,110 - D:\se\Se_Project\Util\log.py - log.py[:54] - 没有找到查询结果，--- try again ---
ERROR - 2021-03-08 14:33:12,006 - D:\se\Se_Project\Util\log.py - log.py[:54] - 没有找到查询结果，--- try again ---
ERROR - 2021-03-08 14:34:29,302 - D:\se\Se_Project\Util\log.py - log.py[:54] - 没有找到查询结果，--- try again ---
ERROR - 2021-03-08 14:35:56,949 - D:\se\Se_Project\Util\log.py - log.py[:54] - 没有找到查询结果，--- try again ---
ERROR - 2021-03-08 14:36:14,329 - D:\se\Se_Project\Util\log.py - log.py[:54] - 没有找到查询结果，--- try again ---
ERROR - 2021-03-08 14:37:29,541 - D:\se\Se_Project\Util\log.py - log.py[:54] - 没有找到查询结果，--- try again ---
ERROR - 2021-03-08 14:39:47,666 - D:\se\Se_Project\Util\log.py - log.py[:54] - 业务审批出现异常，异常信息为：<class 'selenium.common.exceptions.TimeoutException'>
ERROR - 2021-03-08 14:40:18,209 - D:\se\Se_Project\Util\log.py - log.py[:54] - 没有找到查询结果，--- try again ---
ERROR - 2021-03-08 14:40:46,080 - D:\se\Se_Project\Util\log.py - log.py[:54] - 没有找到查询结果，--- try again ---
ERROR - 2021-03-08 14:42:49,037 - D:\se\Se_Project\Util\log.py - log.py[:54] - 没有找到查询结果，--- try again ---
ERROR - 2021-03-08 14:43:53,222 - D:\se\Se_Project\Util\log.py - log.py[:54] - 没有找到查询结果，--- try again ---
ERROR - 2021-03-08 14:46:05,352 - D:\se\Se_Project\Util\log.py - log.py[:54] - 没有找到查询结果，--- try again ---
ERROR - 2021-03-08 14:47:04,065 - D:\se\Se_Project\Util\log.py - log.py[:54] - 没有找到查询结果，--- try again ---
ERROR - 2021-03-08 14:48:36,145 - D:\se\Se_Project\Util\log.py - log.py[:54] - 没有找到查询结果，--- try again ---
ERROR - 2021-03-08 14:48:53,941 - D:\se\Se_Project\Util\log.py - log.py[:54] - 没有找到查询结果，--- try again ---
ERROR - 2021-03-08 14:49:58,549 - D:\se\Se_Project\Util\log.py - log.py[:54] - 没有找到查询结果，--- try again ---
ERROR - 2021-03-08 15:10:29,647 - D:\se\Se_Project\Util\log.py - log.py[:54] - 没有找到查询结果，--- try again ---
ERROR - 2021-03-08 15:10:42,472 - D:\se\Se_Project\Util\log.py - log.py[:54] - 没有找到查询结果，--- try again ---
ERROR - 2021-03-08 15:11:39,542 - D:\se\Se_Project\Util\log.py - log.py[:54] - 出现异常，异常信息为：<class 'selenium.common.exceptions.TimeoutException'>
ERROR - 2021-03-08 15:20:08,898 - D:\se\Se_Project\Util\log.py - log.py[:54] - 业务审批出现异常，异常信息为：<class 'selenium.common.exceptions.TimeoutException'>
ERROR - 2021-03-08 15:20:34,723 - D:\se\Se_Project\Util\log.py - log.py[:54] - 没有找到查询结果，--- try again ---
ERROR - 2021-03-08 15:20:47,566 - D:\se\Se_Project\Util\log.py - log.py[:54] - 没有找到查询结果，--- try again ---
ERROR - 2021-03-08 15:52:33,846 - D:\se\Se_Project\Util\log.py - log.py[:54] - 出现异常，异常信息为：<class 'selenium.common.exceptions.TimeoutException'>
ERROR - 2021-03-08 15:59:15,530 - D:\se\Se_Project\Util\log.py - log.py[:54] - 出现异常，异常信息为：<class 'selenium.common.exceptions.TimeoutException'>
ERROR - 2021-03-08 16:02:43,585 - D:\se\Se_Project\Util\log.py - log.py[:54] - Exception: Don't find Boe, please check config
ERROR - 2021-03-08 16:02:46,588 - D:\se\Se_Project\Util\log.py - log.py[:54] -  Don't find Boe, Try again
ERROR - 2021-03-08 16:13:55,425 - D:\se\Se_Project\Util\log.py - log.py[:54] - 出现异常，异常信息为：<class 'selenium.common.exceptions.NoSuchElementException'>
ERROR - 2021-03-08 16:38:25,501 - D:\se\Se_Project\Util\log.py - log.py[:54] - 没有找到查询结果，--- try again ---
ERROR - 2021-03-08 16:41:28,878 - D:\se\Se_Project\Util\log.py - log.py[:54] - 没有找到查询结果，--- try again ---
ERROR - 2021-03-08 16:46:43,512 - D:\se\Se_Project\Util\log.py - log.py[:54] - 没有找到查询结果，--- try again ---
ERROR - 2021-03-08 17:13:58,071 - D:\se\Se_Project\Util\log.py - log.py[:54] - 出现异常，异常信息为：<class 'selenium.common.exceptions.ElementClickInterceptedException'>
ERROR - 2021-03-08 17:14:28,880 - D:\se\Se_Project\Util\log.py - log.py[:54] - 出现异常，异常信息为：<class 'selenium.common.exceptions.TimeoutException'>
ERROR - 2021-03-08 17:15:03,338 - D:\se\Se_Project\Util\log.py - log.py[:54] - 出现异常，异常信息为：<class 'selenium.common.exceptions.NoSuchElementException'>
ERROR - 2021-03-08 17:23:55,431 - D:\se\Se_Project\Util\log.py - log.py[:54] - 没有找到查询结果，--- try again ---
ERROR - 2021-03-08 17:57:51,160 - D:\se\Se_Project\Util\log.py - log.py[:54] - 没有找到查询结果，--- try again ---
ERROR - 2021-03-08 18:50:28,901 - D:\se\Se_Project\Util\log.py - log.py[:54] - 出现异常，异常信息为：<class 'selenium.common.exceptions.TimeoutException'>
ERROR - 2021-03-08 19:04:36,705 - D:\se\Se_Project\Util\log.py - log.py[:54] - 没有找到查询结果，--- try again ---
ERROR - 2021-03-08 19:04:49,796 - D:\se\Se_Project\Util\log.py - log.py[:54] - 没有找到查询结果，--- try again ---
ERROR - 2021-03-08 19:11:28,148 - D:\se\Se_Project\Util\log.py - log.py[:54] - 没有找到查询结果，--- try again ---
ERROR - 2021-03-08 19:11:41,875 - D:\se\Se_Project\Util\log.py - log.py[:54] - 没有找到查询结果，--- try again ---
ERROR - 2021-03-08 19:13:40,413 - D:\se\Se_Project\Util\log.py - log.py[:54] - 出现异常，异常信息为：<class 'selenium.common.exceptions.TimeoutException'>
ERROR - 2021-03-08 20:48:03,029 - D:\se\Se_Project\Util\log.py - log.py[:54] - 出现异常，异常信息为：<class 'selenium.common.exceptions.TimeoutException'>
ERROR - 2021-03-08 20:51:45,636 - D:\se\Se_Project\Util\log.py - log.py[:54] - Exception: Don't find Boe, please check config
ERROR - 2021-03-08 20:51:48,638 - D:\se\Se_Project\Util\log.py - log.py[:54] -  Don't find Boe, Try again
ERROR - 2021-03-08 21:12:54,558 - D:\se\Se_Project\Util\log.py - log.py[:54] - 出现异常，异常信息为：<class 'selenium.common.exceptions.TimeoutException'>
ERROR - 2021-03-15 10:45:52,217 - D:\Pycharm\Se_Project\Util\log.py - log.py[:54] - 出现异常，异常信息为：<class 'AttributeError'>
ERROR - 2021-03-15 10:49:30,010 - D:\Pycharm\Se_Project\Util\log.py - log.py[:54] - 出现异常，异常信息为：<class 'selenium.common.exceptions.NoSuchElementException'>
ERROR - 2021-03-15 10:50:03,142 - D:\Pycharm\Se_Project\Util\log.py - log.py[:54] - 出现异常，异常信息为：<class 'selenium.common.exceptions.NoSuchElementException'>
ERROR - 2021-03-15 10:50:33,182 - D:\Pycharm\Se_Project\Util\log.py - log.py[:54] - 出现异常，异常信息为：<class 'selenium.common.exceptions.NoSuchElementException'>
ERROR - 2021-03-15 10:51:03,669 - D:\Pycharm\Se_Project\Util\log.py - log.py[:54] - 出现异常，异常信息为：<class 'selenium.common.exceptions.NoSuchElementException'>
ERROR - 2021-03-15 10:51:33,304 - D:\Pycharm\Se_Project\Util\log.py - log.py[:54] - 出现异常，异常信息为：<class 'selenium.common.exceptions.NoSuchElementException'>
ERROR - 2021-03-15 10:52:15,423 - D:\Pycharm\Se_Project\Util\log.py - log.py[:54] - 出现异常，异常信息为：<class 'selenium.common.exceptions.TimeoutException'>
ERROR - 2021-03-15 10:52:45,782 - D:\Pycharm\Se_Project\Util\log.py - log.py[:54] - 出现异常，异常信息为：<class 'selenium.common.exceptions.NoSuchElementException'>
ERROR - 2021-03-15 10:54:11,257 - D:\Pycharm\Se_Project\Util\log.py - log.py[:54] - 出现异常，异常信息为：<class 'selenium.common.exceptions.NoSuchElementException'>
ERROR - 2021-03-15 10:54:42,333 - D:\Pycharm\Se_Project\Util\log.py - log.py[:54] - 出现异常，异常信息为：<class 'selenium.common.exceptions.NoSuchElementException'>
ERROR - 2021-03-15 10:55:08,133 - D:\Pycharm\Se_Project\Util\log.py - log.py[:54] - 出现异常，异常信息为：<class 'selenium.common.exceptions.NoSuchElementException'>
ERROR - 2021-03-15 10:55:33,877 - D:\Pycharm\Se_Project\Util\log.py - log.py[:54] - 出现异常，异常信息为：<class 'selenium.common.exceptions.NoSuchElementException'>
ERROR - 2021-03-15 10:56:01,414 - D:\Pycharm\Se_Project\Util\log.py - log.py[:54] - 出现异常，异常信息为：<class 'selenium.common.exceptions.NoSuchElementException'>
ERROR - 2021-03-15 10:56:42,566 - D:\Pycharm\Se_Project\Util\log.py - log.py[:54] - 出现异常，异常信息为：<class 'selenium.common.exceptions.TimeoutException'>
ERROR - 2021-03-15 10:57:12,313 - D:\Pycharm\Se_Project\Util\log.py - log.py[:54] - 出现异常，异常信息为：<class 'selenium.common.exceptions.NoSuchElementException'>
ERROR - 2021-03-15 11:00:41,083 - D:\Pycharm\Se_Project\Util\log.py - log.py[:54] - 出现异常，异常信息为：<class 'selenium.common.exceptions.TimeoutException'>
ERROR - 2021-03-15 11:01:10,761 - D:\Pycharm\Se_Project\Util\log.py - log.py[:54] - 出现异常，异常信息为：<class 'selenium.common.exceptions.NoSuchElementException'>
ERROR - 2021-03-15 11:02:19,842 - D:\Pycharm\Se_Project\Util\log.py - log.py[:54] - 出现异常，异常信息为：<class 'selenium.common.exceptions.NoSuchElementException'>
ERROR - 2021-03-15 11:02:52,773 - D:\Pycharm\Se_Project\Util\log.py - log.py[:54] - 出现异常，异常信息为：<class 'selenium.common.exceptions.NoSuchElementException'>
ERROR - 2021-03-15 11:03:25,734 - D:\Pycharm\Se_Project\Util\log.py - log.py[:54] - 出现异常，异常信息为：<class 'selenium.common.exceptions.NoSuchElementException'>
ERROR - 2021-03-15 11:03:56,860 - D:\Pycharm\Se_Project\Util\log.py - log.py[:54] - 出现异常，异常信息为：<class 'selenium.common.exceptions.NoSuchElementException'>
ERROR - 2021-03-15 15:37:33,793 - D:\Pycharm\Se_Project\Util\log.py - log.py[:54] - 出现异常，异常信息为：<class 'selenium.common.exceptions.ElementNotInteractableException'>
ERROR - 2021-03-15 15:38:23,554 - D:\Pycharm\Se_Project\Util\log.py - log.py[:54] - 出现异常，异常信息为：<class 'selenium.common.exceptions.NoSuchElementException'>
ERROR - 2021-03-15 15:47:31,333 - D:\Pycharm\Se_Project\Util\log.py - log.py[:54] - 出现异常，异常信息为：<class 'selenium.common.exceptions.ElementNotInteractableException'>
ERROR - 2021-03-15 16:30:18,557 - D:\Pycharm\Se_Project\Util\log.py - log.py[:54] - 没有找到查询结果，--- try again ---
ERROR - 2021-03-15 16:32:42,126 - D:\Pycharm\Se_Project\Util\log.py - log.py[:54] - 没有找到查询结果，--- try again ---
ERROR - 2021-03-15 16:35:13,597 - D:\Pycharm\Se_Project\Util\log.py - log.py[:54] - 没有找到查询结果，--- try again ---
ERROR - 2021-03-15 16:35:40,834 - D:\Pycharm\Se_Project\Util\log.py - log.py[:54] - No available service
